[2024-12-03 16:26:17,817][flwr][WARNING] - DEPRECATED FEATURE: flwr.simulation.start_simulation() is deprecated.
	Instead, use the `flwr run` CLI command to start a local simulation in your Flower app, as shown for example below:

		$ flwr new  # Create a new Flower app from a template

		$ flwr run  # Run the Flower app in Simulation Mode

	Using `start_simulation()` is deprecated.

            This is a deprecated feature. It will be removed
            entirely in future versions of Flower.
        
[2024-12-03 16:26:17,821][flwr][INFO] - Starting Flower simulation, config: num_rounds=10, no round_timeout
[2024-12-03 16:26:31,436][flwr][INFO] - Flower VCE: Ray initialized with resources: {'accelerator_type:G': 1.0, 'node:__internal_head__': 1.0, 'CPU': 8.0, 'object_store_memory': 1644874137.0, 'node:127.0.0.1': 1.0, 'memory': 3289748276.0, 'GPU': 1.0}
[2024-12-03 16:26:31,438][flwr][INFO] - Optimize your simulation with Flower VCE: https://flower.ai/docs/framework/how-to-run-simulations.html
[2024-12-03 16:26:31,439][flwr][INFO] - Flower VCE: Resources for each Virtual Client: {'num_cpus': 2, 'num_gpus': 0.5}
[2024-12-03 16:26:31,469][flwr][INFO] - Flower VCE: Creating VirtualClientEngineActorPool with 2 actors
[2024-12-03 16:26:31,470][flwr][INFO] - [INIT]
[2024-12-03 16:26:31,471][flwr][INFO] - Requesting initial parameters from one random client
[2024-12-03 16:26:44,548][flwr][WARNING] - Failed to receive initial parameters from the client. Empty initial parameters will be used.
[2024-12-03 16:26:44,548][flwr][INFO] - Starting evaluation of initial global parameters
[2024-12-03 16:26:56,651][flwr][INFO] - initial parameters (loss, other metrics): 0.14922158420085907, {'mae': 0.3440554141998291}
[2024-12-03 16:26:56,652][flwr][INFO] - 
[2024-12-03 16:26:56,653][flwr][INFO] - [ROUND 1]
[2024-12-03 16:26:56,654][flwr][INFO] - configure_fit: strategy sampled 8 clients (out of 12)
[2024-12-03 16:27:00,365][flwr][ERROR] - Traceback (most recent call last):
  File "C:\Users\clara\anaconda3\envs\tf_gpu\lib\site-packages\flwr\simulation\ray_transport\ray_client_proxy.py", line 94, in _submit_job
    out_mssg, updated_context = self.actor_pool.get_client_result(
  File "C:\Users\clara\anaconda3\envs\tf_gpu\lib\site-packages\flwr\simulation\ray_transport\ray_actor.py", line 398, in get_client_result
    return self._fetch_future_result(cid)
  File "C:\Users\clara\anaconda3\envs\tf_gpu\lib\site-packages\flwr\simulation\ray_transport\ray_actor.py", line 279, in _fetch_future_result
    res_cid, out_mssg, updated_context = ray.get(
  File "C:\Users\clara\anaconda3\envs\tf_gpu\lib\site-packages\ray\_private\auto_init_hook.py", line 21, in auto_init_wrapper
    return fn(*args, **kwargs)
  File "C:\Users\clara\anaconda3\envs\tf_gpu\lib\site-packages\ray\_private\client_mode_hook.py", line 103, in wrapper
    return func(*args, **kwargs)
  File "C:\Users\clara\anaconda3\envs\tf_gpu\lib\site-packages\ray\_private\worker.py", line 2753, in get
    values, debugger_breakpoint = worker.get_objects(object_refs, timeout=timeout)
  File "C:\Users\clara\anaconda3\envs\tf_gpu\lib\site-packages\ray\_private\worker.py", line 904, in get_objects
    raise value.as_instanceof_cause()
ray.exceptions.RayTaskError(ClientAppException): [36mray::ClientAppActor.run()[39m (pid=17372, ip=127.0.0.1, actor_id=38dbbf05716928ec6fb350bf01000000, repr=<flwr.simulation.ray_transport.ray_actor.ClientAppActor object at 0x00000210E74B0A60>)
  File "C:\Users\clara\anaconda3\envs\tf_gpu\lib\site-packages\flwr\client\client_app.py", line 143, in __call__
    return self._call(message, context)
  File "C:\Users\clara\anaconda3\envs\tf_gpu\lib\site-packages\flwr\client\client_app.py", line 126, in ffn
    out_message = handle_legacy_message_from_msgtype(
  File "C:\Users\clara\anaconda3\envs\tf_gpu\lib\site-packages\flwr\client\message_handler\message_handler.py", line 129, in handle_legacy_message_from_msgtype
    fit_res = maybe_call_fit(
  File "C:\Users\clara\anaconda3\envs\tf_gpu\lib\site-packages\flwr\client\client.py", line 255, in maybe_call_fit
    return client.fit(fit_ins)
  File "C:\Users\clara\anaconda3\envs\tf_gpu\lib\site-packages\flwr\client\numpy_client.py", line 259, in _fit
    results = self.numpy_client.fit(parameters, ins.config)  # type: ignore
  File "C:\Users\clara\Desktop\TFG\Codigo TFG\3.FederatedTraining\client.py", line 27, in fit
    self.model.set_weights(parameters)
  File "C:\Users\clara\anaconda3\envs\tf_gpu\lib\site-packages\keras\src\layers\layer.py", line 696, in set_weights
    raise ValueError(
ValueError: You called `set_weights(weights)` on layer 'sequential' with a weight list of length 0, but the layer was expecting 8 weights.

The above exception was the direct cause of the following exception:

[36mray::ClientAppActor.run()[39m (pid=17372, ip=127.0.0.1, actor_id=38dbbf05716928ec6fb350bf01000000, repr=<flwr.simulation.ray_transport.ray_actor.ClientAppActor object at 0x00000210E74B0A60>)
  File "python\ray\_raylet.pyx", line 1856, in ray._raylet.execute_task
  File "python\ray\_raylet.pyx", line 1957, in ray._raylet.execute_task
  File "python\ray\_raylet.pyx", line 1862, in ray._raylet.execute_task
  File "python\ray\_raylet.pyx", line 1803, in ray._raylet.execute_task.function_executor
  File "C:\Users\clara\anaconda3\envs\tf_gpu\lib\site-packages\ray\_private\function_manager.py", line 696, in actor_method_executor
    return method(__ray_actor, *args, **kwargs)
  File "C:\Users\clara\anaconda3\envs\tf_gpu\lib\site-packages\ray\util\tracing\tracing_helper.py", line 467, in _resume_span
    return method(self, *_args, **_kwargs)
  File "C:\Users\clara\anaconda3\envs\tf_gpu\lib\site-packages\flwr\simulation\ray_transport\ray_actor.py", line 63, in run
    raise ClientAppException(str(ex)) from ex
flwr.client.client_app.ClientAppException: 
Exception ClientAppException occurred. Message: You called `set_weights(weights)` on layer 'sequential' with a weight list of length 0, but the layer was expecting 8 weights.

[2024-12-03 16:27:00,377][flwr][ERROR] - [36mray::ClientAppActor.run()[39m (pid=17372, ip=127.0.0.1, actor_id=38dbbf05716928ec6fb350bf01000000, repr=<flwr.simulation.ray_transport.ray_actor.ClientAppActor object at 0x00000210E74B0A60>)
  File "C:\Users\clara\anaconda3\envs\tf_gpu\lib\site-packages\flwr\client\client_app.py", line 143, in __call__
    return self._call(message, context)
  File "C:\Users\clara\anaconda3\envs\tf_gpu\lib\site-packages\flwr\client\client_app.py", line 126, in ffn
    out_message = handle_legacy_message_from_msgtype(
  File "C:\Users\clara\anaconda3\envs\tf_gpu\lib\site-packages\flwr\client\message_handler\message_handler.py", line 129, in handle_legacy_message_from_msgtype
    fit_res = maybe_call_fit(
  File "C:\Users\clara\anaconda3\envs\tf_gpu\lib\site-packages\flwr\client\client.py", line 255, in maybe_call_fit
    return client.fit(fit_ins)
  File "C:\Users\clara\anaconda3\envs\tf_gpu\lib\site-packages\flwr\client\numpy_client.py", line 259, in _fit
    results = self.numpy_client.fit(parameters, ins.config)  # type: ignore
  File "C:\Users\clara\Desktop\TFG\Codigo TFG\3.FederatedTraining\client.py", line 27, in fit
    self.model.set_weights(parameters)
  File "C:\Users\clara\anaconda3\envs\tf_gpu\lib\site-packages\keras\src\layers\layer.py", line 696, in set_weights
    raise ValueError(
ValueError: You called `set_weights(weights)` on layer 'sequential' with a weight list of length 0, but the layer was expecting 8 weights.

The above exception was the direct cause of the following exception:

[36mray::ClientAppActor.run()[39m (pid=17372, ip=127.0.0.1, actor_id=38dbbf05716928ec6fb350bf01000000, repr=<flwr.simulation.ray_transport.ray_actor.ClientAppActor object at 0x00000210E74B0A60>)
  File "python\ray\_raylet.pyx", line 1856, in ray._raylet.execute_task
  File "python\ray\_raylet.pyx", line 1957, in ray._raylet.execute_task
  File "python\ray\_raylet.pyx", line 1862, in ray._raylet.execute_task
  File "python\ray\_raylet.pyx", line 1803, in ray._raylet.execute_task.function_executor
  File "C:\Users\clara\anaconda3\envs\tf_gpu\lib\site-packages\ray\_private\function_manager.py", line 696, in actor_method_executor
    return method(__ray_actor, *args, **kwargs)
  File "C:\Users\clara\anaconda3\envs\tf_gpu\lib\site-packages\ray\util\tracing\tracing_helper.py", line 467, in _resume_span
    return method(self, *_args, **_kwargs)
  File "C:\Users\clara\anaconda3\envs\tf_gpu\lib\site-packages\flwr\simulation\ray_transport\ray_actor.py", line 63, in run
    raise ClientAppException(str(ex)) from ex
flwr.client.client_app.ClientAppException: 
Exception ClientAppException occurred. Message: You called `set_weights(weights)` on layer 'sequential' with a weight list of length 0, but the layer was expecting 8 weights.
[2024-12-03 16:27:01,072][flwr][ERROR] - Traceback (most recent call last):
  File "C:\Users\clara\anaconda3\envs\tf_gpu\lib\site-packages\flwr\simulation\ray_transport\ray_client_proxy.py", line 94, in _submit_job
    out_mssg, updated_context = self.actor_pool.get_client_result(
  File "C:\Users\clara\anaconda3\envs\tf_gpu\lib\site-packages\flwr\simulation\ray_transport\ray_actor.py", line 398, in get_client_result
    return self._fetch_future_result(cid)
  File "C:\Users\clara\anaconda3\envs\tf_gpu\lib\site-packages\flwr\simulation\ray_transport\ray_actor.py", line 279, in _fetch_future_result
    res_cid, out_mssg, updated_context = ray.get(
  File "C:\Users\clara\anaconda3\envs\tf_gpu\lib\site-packages\ray\_private\auto_init_hook.py", line 21, in auto_init_wrapper
    return fn(*args, **kwargs)
  File "C:\Users\clara\anaconda3\envs\tf_gpu\lib\site-packages\ray\_private\client_mode_hook.py", line 103, in wrapper
    return func(*args, **kwargs)
  File "C:\Users\clara\anaconda3\envs\tf_gpu\lib\site-packages\ray\_private\worker.py", line 2753, in get
    values, debugger_breakpoint = worker.get_objects(object_refs, timeout=timeout)
  File "C:\Users\clara\anaconda3\envs\tf_gpu\lib\site-packages\ray\_private\worker.py", line 904, in get_objects
    raise value.as_instanceof_cause()
ray.exceptions.RayTaskError(ClientAppException): [36mray::ClientAppActor.run()[39m (pid=20408, ip=127.0.0.1, actor_id=e8f6c7b4b011b565c443b57701000000, repr=<flwr.simulation.ray_transport.ray_actor.ClientAppActor object at 0x0000015A5B8A28E0>)
  File "C:\Users\clara\anaconda3\envs\tf_gpu\lib\site-packages\flwr\client\client_app.py", line 143, in __call__
    return self._call(message, context)
  File "C:\Users\clara\anaconda3\envs\tf_gpu\lib\site-packages\flwr\client\client_app.py", line 126, in ffn
    out_message = handle_legacy_message_from_msgtype(
  File "C:\Users\clara\anaconda3\envs\tf_gpu\lib\site-packages\flwr\client\message_handler\message_handler.py", line 129, in handle_legacy_message_from_msgtype
    fit_res = maybe_call_fit(
  File "C:\Users\clara\anaconda3\envs\tf_gpu\lib\site-packages\flwr\client\client.py", line 255, in maybe_call_fit
    return client.fit(fit_ins)
  File "C:\Users\clara\anaconda3\envs\tf_gpu\lib\site-packages\flwr\client\numpy_client.py", line 259, in _fit
    results = self.numpy_client.fit(parameters, ins.config)  # type: ignore
  File "C:\Users\clara\Desktop\TFG\Codigo TFG\3.FederatedTraining\client.py", line 27, in fit
    self.model.set_weights(parameters)
  File "C:\Users\clara\anaconda3\envs\tf_gpu\lib\site-packages\keras\src\layers\layer.py", line 696, in set_weights
    raise ValueError(
ValueError: You called `set_weights(weights)` on layer 'sequential_1' with a weight list of length 0, but the layer was expecting 8 weights.

The above exception was the direct cause of the following exception:

[36mray::ClientAppActor.run()[39m (pid=20408, ip=127.0.0.1, actor_id=e8f6c7b4b011b565c443b57701000000, repr=<flwr.simulation.ray_transport.ray_actor.ClientAppActor object at 0x0000015A5B8A28E0>)
  File "python\ray\_raylet.pyx", line 1856, in ray._raylet.execute_task
  File "python\ray\_raylet.pyx", line 1957, in ray._raylet.execute_task
  File "python\ray\_raylet.pyx", line 1862, in ray._raylet.execute_task
  File "python\ray\_raylet.pyx", line 1803, in ray._raylet.execute_task.function_executor
  File "C:\Users\clara\anaconda3\envs\tf_gpu\lib\site-packages\ray\_private\function_manager.py", line 696, in actor_method_executor
    return method(__ray_actor, *args, **kwargs)
  File "C:\Users\clara\anaconda3\envs\tf_gpu\lib\site-packages\ray\util\tracing\tracing_helper.py", line 467, in _resume_span
    return method(self, *_args, **_kwargs)
  File "C:\Users\clara\anaconda3\envs\tf_gpu\lib\site-packages\flwr\simulation\ray_transport\ray_actor.py", line 63, in run
    raise ClientAppException(str(ex)) from ex
flwr.client.client_app.ClientAppException: 
Exception ClientAppException occurred. Message: You called `set_weights(weights)` on layer 'sequential_1' with a weight list of length 0, but the layer was expecting 8 weights.

[2024-12-03 16:27:01,084][flwr][ERROR] - [36mray::ClientAppActor.run()[39m (pid=20408, ip=127.0.0.1, actor_id=e8f6c7b4b011b565c443b57701000000, repr=<flwr.simulation.ray_transport.ray_actor.ClientAppActor object at 0x0000015A5B8A28E0>)
  File "C:\Users\clara\anaconda3\envs\tf_gpu\lib\site-packages\flwr\client\client_app.py", line 143, in __call__
    return self._call(message, context)
  File "C:\Users\clara\anaconda3\envs\tf_gpu\lib\site-packages\flwr\client\client_app.py", line 126, in ffn
    out_message = handle_legacy_message_from_msgtype(
  File "C:\Users\clara\anaconda3\envs\tf_gpu\lib\site-packages\flwr\client\message_handler\message_handler.py", line 129, in handle_legacy_message_from_msgtype
    fit_res = maybe_call_fit(
  File "C:\Users\clara\anaconda3\envs\tf_gpu\lib\site-packages\flwr\client\client.py", line 255, in maybe_call_fit
    return client.fit(fit_ins)
  File "C:\Users\clara\anaconda3\envs\tf_gpu\lib\site-packages\flwr\client\numpy_client.py", line 259, in _fit
    results = self.numpy_client.fit(parameters, ins.config)  # type: ignore
  File "C:\Users\clara\Desktop\TFG\Codigo TFG\3.FederatedTraining\client.py", line 27, in fit
    self.model.set_weights(parameters)
  File "C:\Users\clara\anaconda3\envs\tf_gpu\lib\site-packages\keras\src\layers\layer.py", line 696, in set_weights
    raise ValueError(
ValueError: You called `set_weights(weights)` on layer 'sequential_1' with a weight list of length 0, but the layer was expecting 8 weights.

The above exception was the direct cause of the following exception:

[36mray::ClientAppActor.run()[39m (pid=20408, ip=127.0.0.1, actor_id=e8f6c7b4b011b565c443b57701000000, repr=<flwr.simulation.ray_transport.ray_actor.ClientAppActor object at 0x0000015A5B8A28E0>)
  File "python\ray\_raylet.pyx", line 1856, in ray._raylet.execute_task
  File "python\ray\_raylet.pyx", line 1957, in ray._raylet.execute_task
  File "python\ray\_raylet.pyx", line 1862, in ray._raylet.execute_task
  File "python\ray\_raylet.pyx", line 1803, in ray._raylet.execute_task.function_executor
  File "C:\Users\clara\anaconda3\envs\tf_gpu\lib\site-packages\ray\_private\function_manager.py", line 696, in actor_method_executor
    return method(__ray_actor, *args, **kwargs)
  File "C:\Users\clara\anaconda3\envs\tf_gpu\lib\site-packages\ray\util\tracing\tracing_helper.py", line 467, in _resume_span
    return method(self, *_args, **_kwargs)
  File "C:\Users\clara\anaconda3\envs\tf_gpu\lib\site-packages\flwr\simulation\ray_transport\ray_actor.py", line 63, in run
    raise ClientAppException(str(ex)) from ex
flwr.client.client_app.ClientAppException: 
Exception ClientAppException occurred. Message: You called `set_weights(weights)` on layer 'sequential_1' with a weight list of length 0, but the layer was expecting 8 weights.
[2024-12-03 16:27:03,222][flwr][ERROR] - Traceback (most recent call last):
  File "C:\Users\clara\anaconda3\envs\tf_gpu\lib\site-packages\flwr\simulation\ray_transport\ray_client_proxy.py", line 94, in _submit_job
    out_mssg, updated_context = self.actor_pool.get_client_result(
  File "C:\Users\clara\anaconda3\envs\tf_gpu\lib\site-packages\flwr\simulation\ray_transport\ray_actor.py", line 398, in get_client_result
    return self._fetch_future_result(cid)
  File "C:\Users\clara\anaconda3\envs\tf_gpu\lib\site-packages\flwr\simulation\ray_transport\ray_actor.py", line 279, in _fetch_future_result
    res_cid, out_mssg, updated_context = ray.get(
  File "C:\Users\clara\anaconda3\envs\tf_gpu\lib\site-packages\ray\_private\auto_init_hook.py", line 21, in auto_init_wrapper
    return fn(*args, **kwargs)
  File "C:\Users\clara\anaconda3\envs\tf_gpu\lib\site-packages\ray\_private\client_mode_hook.py", line 103, in wrapper
    return func(*args, **kwargs)
  File "C:\Users\clara\anaconda3\envs\tf_gpu\lib\site-packages\ray\_private\worker.py", line 2753, in get
    values, debugger_breakpoint = worker.get_objects(object_refs, timeout=timeout)
  File "C:\Users\clara\anaconda3\envs\tf_gpu\lib\site-packages\ray\_private\worker.py", line 904, in get_objects
    raise value.as_instanceof_cause()
ray.exceptions.RayTaskError(ClientAppException): [36mray::ClientAppActor.run()[39m (pid=20408, ip=127.0.0.1, actor_id=e8f6c7b4b011b565c443b57701000000, repr=<flwr.simulation.ray_transport.ray_actor.ClientAppActor object at 0x0000015A5B8A28E0>)
  File "C:\Users\clara\anaconda3\envs\tf_gpu\lib\site-packages\flwr\client\client_app.py", line 143, in __call__
    return self._call(message, context)
  File "C:\Users\clara\anaconda3\envs\tf_gpu\lib\site-packages\flwr\client\client_app.py", line 126, in ffn
    out_message = handle_legacy_message_from_msgtype(
  File "C:\Users\clara\anaconda3\envs\tf_gpu\lib\site-packages\flwr\client\message_handler\message_handler.py", line 129, in handle_legacy_message_from_msgtype
    fit_res = maybe_call_fit(
  File "C:\Users\clara\anaconda3\envs\tf_gpu\lib\site-packages\flwr\client\client.py", line 255, in maybe_call_fit
    return client.fit(fit_ins)
  File "C:\Users\clara\anaconda3\envs\tf_gpu\lib\site-packages\flwr\client\numpy_client.py", line 259, in _fit
    results = self.numpy_client.fit(parameters, ins.config)  # type: ignore
  File "C:\Users\clara\Desktop\TFG\Codigo TFG\3.FederatedTraining\client.py", line 27, in fit
    self.model.set_weights(parameters)
  File "C:\Users\clara\anaconda3\envs\tf_gpu\lib\site-packages\keras\src\layers\layer.py", line 696, in set_weights
    raise ValueError(
ValueError: You called `set_weights(weights)` on layer 'sequential_2' with a weight list of length 0, but the layer was expecting 8 weights.

The above exception was the direct cause of the following exception:

[36mray::ClientAppActor.run()[39m (pid=20408, ip=127.0.0.1, actor_id=e8f6c7b4b011b565c443b57701000000, repr=<flwr.simulation.ray_transport.ray_actor.ClientAppActor object at 0x0000015A5B8A28E0>)
  File "python\ray\_raylet.pyx", line 1856, in ray._raylet.execute_task
  File "python\ray\_raylet.pyx", line 1957, in ray._raylet.execute_task
  File "python\ray\_raylet.pyx", line 1862, in ray._raylet.execute_task
  File "python\ray\_raylet.pyx", line 1803, in ray._raylet.execute_task.function_executor
  File "C:\Users\clara\anaconda3\envs\tf_gpu\lib\site-packages\ray\_private\function_manager.py", line 696, in actor_method_executor
    return method(__ray_actor, *args, **kwargs)
  File "C:\Users\clara\anaconda3\envs\tf_gpu\lib\site-packages\ray\util\tracing\tracing_helper.py", line 467, in _resume_span
    return method(self, *_args, **_kwargs)
  File "C:\Users\clara\anaconda3\envs\tf_gpu\lib\site-packages\flwr\simulation\ray_transport\ray_actor.py", line 63, in run
    raise ClientAppException(str(ex)) from ex
flwr.client.client_app.ClientAppException: 
Exception ClientAppException occurred. Message: You called `set_weights(weights)` on layer 'sequential_2' with a weight list of length 0, but the layer was expecting 8 weights.

[2024-12-03 16:27:03,235][flwr][ERROR] - [36mray::ClientAppActor.run()[39m (pid=20408, ip=127.0.0.1, actor_id=e8f6c7b4b011b565c443b57701000000, repr=<flwr.simulation.ray_transport.ray_actor.ClientAppActor object at 0x0000015A5B8A28E0>)
  File "C:\Users\clara\anaconda3\envs\tf_gpu\lib\site-packages\flwr\client\client_app.py", line 143, in __call__
    return self._call(message, context)
  File "C:\Users\clara\anaconda3\envs\tf_gpu\lib\site-packages\flwr\client\client_app.py", line 126, in ffn
    out_message = handle_legacy_message_from_msgtype(
  File "C:\Users\clara\anaconda3\envs\tf_gpu\lib\site-packages\flwr\client\message_handler\message_handler.py", line 129, in handle_legacy_message_from_msgtype
    fit_res = maybe_call_fit(
  File "C:\Users\clara\anaconda3\envs\tf_gpu\lib\site-packages\flwr\client\client.py", line 255, in maybe_call_fit
    return client.fit(fit_ins)
  File "C:\Users\clara\anaconda3\envs\tf_gpu\lib\site-packages\flwr\client\numpy_client.py", line 259, in _fit
    results = self.numpy_client.fit(parameters, ins.config)  # type: ignore
  File "C:\Users\clara\Desktop\TFG\Codigo TFG\3.FederatedTraining\client.py", line 27, in fit
    self.model.set_weights(parameters)
  File "C:\Users\clara\anaconda3\envs\tf_gpu\lib\site-packages\keras\src\layers\layer.py", line 696, in set_weights
    raise ValueError(
ValueError: You called `set_weights(weights)` on layer 'sequential_2' with a weight list of length 0, but the layer was expecting 8 weights.

The above exception was the direct cause of the following exception:

[36mray::ClientAppActor.run()[39m (pid=20408, ip=127.0.0.1, actor_id=e8f6c7b4b011b565c443b57701000000, repr=<flwr.simulation.ray_transport.ray_actor.ClientAppActor object at 0x0000015A5B8A28E0>)
  File "python\ray\_raylet.pyx", line 1856, in ray._raylet.execute_task
  File "python\ray\_raylet.pyx", line 1957, in ray._raylet.execute_task
  File "python\ray\_raylet.pyx", line 1862, in ray._raylet.execute_task
  File "python\ray\_raylet.pyx", line 1803, in ray._raylet.execute_task.function_executor
  File "C:\Users\clara\anaconda3\envs\tf_gpu\lib\site-packages\ray\_private\function_manager.py", line 696, in actor_method_executor
    return method(__ray_actor, *args, **kwargs)
  File "C:\Users\clara\anaconda3\envs\tf_gpu\lib\site-packages\ray\util\tracing\tracing_helper.py", line 467, in _resume_span
    return method(self, *_args, **_kwargs)
  File "C:\Users\clara\anaconda3\envs\tf_gpu\lib\site-packages\flwr\simulation\ray_transport\ray_actor.py", line 63, in run
    raise ClientAppException(str(ex)) from ex
flwr.client.client_app.ClientAppException: 
Exception ClientAppException occurred. Message: You called `set_weights(weights)` on layer 'sequential_2' with a weight list of length 0, but the layer was expecting 8 weights.
[2024-12-03 16:27:04,512][flwr][ERROR] - Traceback (most recent call last):
  File "C:\Users\clara\anaconda3\envs\tf_gpu\lib\site-packages\flwr\simulation\ray_transport\ray_client_proxy.py", line 94, in _submit_job
    out_mssg, updated_context = self.actor_pool.get_client_result(
  File "C:\Users\clara\anaconda3\envs\tf_gpu\lib\site-packages\flwr\simulation\ray_transport\ray_actor.py", line 398, in get_client_result
    return self._fetch_future_result(cid)
  File "C:\Users\clara\anaconda3\envs\tf_gpu\lib\site-packages\flwr\simulation\ray_transport\ray_actor.py", line 279, in _fetch_future_result
    res_cid, out_mssg, updated_context = ray.get(
  File "C:\Users\clara\anaconda3\envs\tf_gpu\lib\site-packages\ray\_private\auto_init_hook.py", line 21, in auto_init_wrapper
    return fn(*args, **kwargs)
  File "C:\Users\clara\anaconda3\envs\tf_gpu\lib\site-packages\ray\_private\client_mode_hook.py", line 103, in wrapper
    return func(*args, **kwargs)
  File "C:\Users\clara\anaconda3\envs\tf_gpu\lib\site-packages\ray\_private\worker.py", line 2753, in get
    values, debugger_breakpoint = worker.get_objects(object_refs, timeout=timeout)
  File "C:\Users\clara\anaconda3\envs\tf_gpu\lib\site-packages\ray\_private\worker.py", line 904, in get_objects
    raise value.as_instanceof_cause()
ray.exceptions.RayTaskError(ClientAppException): [36mray::ClientAppActor.run()[39m (pid=17372, ip=127.0.0.1, actor_id=38dbbf05716928ec6fb350bf01000000, repr=<flwr.simulation.ray_transport.ray_actor.ClientAppActor object at 0x00000210E74B0A60>)
  File "C:\Users\clara\anaconda3\envs\tf_gpu\lib\site-packages\flwr\client\client_app.py", line 143, in __call__
    return self._call(message, context)
  File "C:\Users\clara\anaconda3\envs\tf_gpu\lib\site-packages\flwr\client\client_app.py", line 126, in ffn
    out_message = handle_legacy_message_from_msgtype(
  File "C:\Users\clara\anaconda3\envs\tf_gpu\lib\site-packages\flwr\client\message_handler\message_handler.py", line 129, in handle_legacy_message_from_msgtype
    fit_res = maybe_call_fit(
  File "C:\Users\clara\anaconda3\envs\tf_gpu\lib\site-packages\flwr\client\client.py", line 255, in maybe_call_fit
    return client.fit(fit_ins)
  File "C:\Users\clara\anaconda3\envs\tf_gpu\lib\site-packages\flwr\client\numpy_client.py", line 259, in _fit
    results = self.numpy_client.fit(parameters, ins.config)  # type: ignore
  File "C:\Users\clara\Desktop\TFG\Codigo TFG\3.FederatedTraining\client.py", line 27, in fit
    self.model.set_weights(parameters)
  File "C:\Users\clara\anaconda3\envs\tf_gpu\lib\site-packages\keras\src\layers\layer.py", line 696, in set_weights
    raise ValueError(
ValueError: You called `set_weights(weights)` on layer 'sequential_1' with a weight list of length 0, but the layer was expecting 8 weights.

The above exception was the direct cause of the following exception:

[36mray::ClientAppActor.run()[39m (pid=17372, ip=127.0.0.1, actor_id=38dbbf05716928ec6fb350bf01000000, repr=<flwr.simulation.ray_transport.ray_actor.ClientAppActor object at 0x00000210E74B0A60>)
  File "python\ray\_raylet.pyx", line 1856, in ray._raylet.execute_task
  File "python\ray\_raylet.pyx", line 1957, in ray._raylet.execute_task
  File "python\ray\_raylet.pyx", line 1862, in ray._raylet.execute_task
  File "python\ray\_raylet.pyx", line 1803, in ray._raylet.execute_task.function_executor
  File "C:\Users\clara\anaconda3\envs\tf_gpu\lib\site-packages\ray\_private\function_manager.py", line 696, in actor_method_executor
    return method(__ray_actor, *args, **kwargs)
  File "C:\Users\clara\anaconda3\envs\tf_gpu\lib\site-packages\ray\util\tracing\tracing_helper.py", line 467, in _resume_span
    return method(self, *_args, **_kwargs)
  File "C:\Users\clara\anaconda3\envs\tf_gpu\lib\site-packages\flwr\simulation\ray_transport\ray_actor.py", line 63, in run
    raise ClientAppException(str(ex)) from ex
flwr.client.client_app.ClientAppException: 
Exception ClientAppException occurred. Message: You called `set_weights(weights)` on layer 'sequential_1' with a weight list of length 0, but the layer was expecting 8 weights.

[2024-12-03 16:27:04,522][flwr][ERROR] - [36mray::ClientAppActor.run()[39m (pid=17372, ip=127.0.0.1, actor_id=38dbbf05716928ec6fb350bf01000000, repr=<flwr.simulation.ray_transport.ray_actor.ClientAppActor object at 0x00000210E74B0A60>)
  File "C:\Users\clara\anaconda3\envs\tf_gpu\lib\site-packages\flwr\client\client_app.py", line 143, in __call__
    return self._call(message, context)
  File "C:\Users\clara\anaconda3\envs\tf_gpu\lib\site-packages\flwr\client\client_app.py", line 126, in ffn
    out_message = handle_legacy_message_from_msgtype(
  File "C:\Users\clara\anaconda3\envs\tf_gpu\lib\site-packages\flwr\client\message_handler\message_handler.py", line 129, in handle_legacy_message_from_msgtype
    fit_res = maybe_call_fit(
  File "C:\Users\clara\anaconda3\envs\tf_gpu\lib\site-packages\flwr\client\client.py", line 255, in maybe_call_fit
    return client.fit(fit_ins)
  File "C:\Users\clara\anaconda3\envs\tf_gpu\lib\site-packages\flwr\client\numpy_client.py", line 259, in _fit
    results = self.numpy_client.fit(parameters, ins.config)  # type: ignore
  File "C:\Users\clara\Desktop\TFG\Codigo TFG\3.FederatedTraining\client.py", line 27, in fit
    self.model.set_weights(parameters)
  File "C:\Users\clara\anaconda3\envs\tf_gpu\lib\site-packages\keras\src\layers\layer.py", line 696, in set_weights
    raise ValueError(
ValueError: You called `set_weights(weights)` on layer 'sequential_1' with a weight list of length 0, but the layer was expecting 8 weights.

The above exception was the direct cause of the following exception:

[36mray::ClientAppActor.run()[39m (pid=17372, ip=127.0.0.1, actor_id=38dbbf05716928ec6fb350bf01000000, repr=<flwr.simulation.ray_transport.ray_actor.ClientAppActor object at 0x00000210E74B0A60>)
  File "python\ray\_raylet.pyx", line 1856, in ray._raylet.execute_task
  File "python\ray\_raylet.pyx", line 1957, in ray._raylet.execute_task
  File "python\ray\_raylet.pyx", line 1862, in ray._raylet.execute_task
  File "python\ray\_raylet.pyx", line 1803, in ray._raylet.execute_task.function_executor
  File "C:\Users\clara\anaconda3\envs\tf_gpu\lib\site-packages\ray\_private\function_manager.py", line 696, in actor_method_executor
    return method(__ray_actor, *args, **kwargs)
  File "C:\Users\clara\anaconda3\envs\tf_gpu\lib\site-packages\ray\util\tracing\tracing_helper.py", line 467, in _resume_span
    return method(self, *_args, **_kwargs)
  File "C:\Users\clara\anaconda3\envs\tf_gpu\lib\site-packages\flwr\simulation\ray_transport\ray_actor.py", line 63, in run
    raise ClientAppException(str(ex)) from ex
flwr.client.client_app.ClientAppException: 
Exception ClientAppException occurred. Message: You called `set_weights(weights)` on layer 'sequential_1' with a weight list of length 0, but the layer was expecting 8 weights.
[2024-12-03 16:27:04,583][flwr][ERROR] - Traceback (most recent call last):
  File "C:\Users\clara\anaconda3\envs\tf_gpu\lib\site-packages\flwr\simulation\ray_transport\ray_client_proxy.py", line 94, in _submit_job
    out_mssg, updated_context = self.actor_pool.get_client_result(
  File "C:\Users\clara\anaconda3\envs\tf_gpu\lib\site-packages\flwr\simulation\ray_transport\ray_actor.py", line 398, in get_client_result
    return self._fetch_future_result(cid)
  File "C:\Users\clara\anaconda3\envs\tf_gpu\lib\site-packages\flwr\simulation\ray_transport\ray_actor.py", line 279, in _fetch_future_result
    res_cid, out_mssg, updated_context = ray.get(
  File "C:\Users\clara\anaconda3\envs\tf_gpu\lib\site-packages\ray\_private\auto_init_hook.py", line 21, in auto_init_wrapper
    return fn(*args, **kwargs)
  File "C:\Users\clara\anaconda3\envs\tf_gpu\lib\site-packages\ray\_private\client_mode_hook.py", line 103, in wrapper
    return func(*args, **kwargs)
  File "C:\Users\clara\anaconda3\envs\tf_gpu\lib\site-packages\ray\_private\worker.py", line 2753, in get
    values, debugger_breakpoint = worker.get_objects(object_refs, timeout=timeout)
  File "C:\Users\clara\anaconda3\envs\tf_gpu\lib\site-packages\ray\_private\worker.py", line 904, in get_objects
    raise value.as_instanceof_cause()
ray.exceptions.RayTaskError(ClientAppException): [36mray::ClientAppActor.run()[39m (pid=20408, ip=127.0.0.1, actor_id=e8f6c7b4b011b565c443b57701000000, repr=<flwr.simulation.ray_transport.ray_actor.ClientAppActor object at 0x0000015A5B8A28E0>)
  File "C:\Users\clara\anaconda3\envs\tf_gpu\lib\site-packages\flwr\client\client_app.py", line 143, in __call__
    return self._call(message, context)
  File "C:\Users\clara\anaconda3\envs\tf_gpu\lib\site-packages\flwr\client\client_app.py", line 126, in ffn
    out_message = handle_legacy_message_from_msgtype(
  File "C:\Users\clara\anaconda3\envs\tf_gpu\lib\site-packages\flwr\client\message_handler\message_handler.py", line 129, in handle_legacy_message_from_msgtype
    fit_res = maybe_call_fit(
  File "C:\Users\clara\anaconda3\envs\tf_gpu\lib\site-packages\flwr\client\client.py", line 255, in maybe_call_fit
    return client.fit(fit_ins)
  File "C:\Users\clara\anaconda3\envs\tf_gpu\lib\site-packages\flwr\client\numpy_client.py", line 259, in _fit
    results = self.numpy_client.fit(parameters, ins.config)  # type: ignore
  File "C:\Users\clara\Desktop\TFG\Codigo TFG\3.FederatedTraining\client.py", line 27, in fit
    self.model.set_weights(parameters)
  File "C:\Users\clara\anaconda3\envs\tf_gpu\lib\site-packages\keras\src\layers\layer.py", line 696, in set_weights
    raise ValueError(
ValueError: You called `set_weights(weights)` on layer 'sequential_3' with a weight list of length 0, but the layer was expecting 8 weights.

The above exception was the direct cause of the following exception:

[36mray::ClientAppActor.run()[39m (pid=20408, ip=127.0.0.1, actor_id=e8f6c7b4b011b565c443b57701000000, repr=<flwr.simulation.ray_transport.ray_actor.ClientAppActor object at 0x0000015A5B8A28E0>)
  File "python\ray\_raylet.pyx", line 1856, in ray._raylet.execute_task
  File "python\ray\_raylet.pyx", line 1957, in ray._raylet.execute_task
  File "python\ray\_raylet.pyx", line 1862, in ray._raylet.execute_task
  File "python\ray\_raylet.pyx", line 1803, in ray._raylet.execute_task.function_executor
  File "C:\Users\clara\anaconda3\envs\tf_gpu\lib\site-packages\ray\_private\function_manager.py", line 696, in actor_method_executor
    return method(__ray_actor, *args, **kwargs)
  File "C:\Users\clara\anaconda3\envs\tf_gpu\lib\site-packages\ray\util\tracing\tracing_helper.py", line 467, in _resume_span
    return method(self, *_args, **_kwargs)
  File "C:\Users\clara\anaconda3\envs\tf_gpu\lib\site-packages\flwr\simulation\ray_transport\ray_actor.py", line 63, in run
    raise ClientAppException(str(ex)) from ex
flwr.client.client_app.ClientAppException: 
Exception ClientAppException occurred. Message: You called `set_weights(weights)` on layer 'sequential_3' with a weight list of length 0, but the layer was expecting 8 weights.

[2024-12-03 16:27:04,597][flwr][ERROR] - [36mray::ClientAppActor.run()[39m (pid=20408, ip=127.0.0.1, actor_id=e8f6c7b4b011b565c443b57701000000, repr=<flwr.simulation.ray_transport.ray_actor.ClientAppActor object at 0x0000015A5B8A28E0>)
  File "C:\Users\clara\anaconda3\envs\tf_gpu\lib\site-packages\flwr\client\client_app.py", line 143, in __call__
    return self._call(message, context)
  File "C:\Users\clara\anaconda3\envs\tf_gpu\lib\site-packages\flwr\client\client_app.py", line 126, in ffn
    out_message = handle_legacy_message_from_msgtype(
  File "C:\Users\clara\anaconda3\envs\tf_gpu\lib\site-packages\flwr\client\message_handler\message_handler.py", line 129, in handle_legacy_message_from_msgtype
    fit_res = maybe_call_fit(
  File "C:\Users\clara\anaconda3\envs\tf_gpu\lib\site-packages\flwr\client\client.py", line 255, in maybe_call_fit
    return client.fit(fit_ins)
  File "C:\Users\clara\anaconda3\envs\tf_gpu\lib\site-packages\flwr\client\numpy_client.py", line 259, in _fit
    results = self.numpy_client.fit(parameters, ins.config)  # type: ignore
  File "C:\Users\clara\Desktop\TFG\Codigo TFG\3.FederatedTraining\client.py", line 27, in fit
    self.model.set_weights(parameters)
  File "C:\Users\clara\anaconda3\envs\tf_gpu\lib\site-packages\keras\src\layers\layer.py", line 696, in set_weights
    raise ValueError(
ValueError: You called `set_weights(weights)` on layer 'sequential_3' with a weight list of length 0, but the layer was expecting 8 weights.

The above exception was the direct cause of the following exception:

[36mray::ClientAppActor.run()[39m (pid=20408, ip=127.0.0.1, actor_id=e8f6c7b4b011b565c443b57701000000, repr=<flwr.simulation.ray_transport.ray_actor.ClientAppActor object at 0x0000015A5B8A28E0>)
  File "python\ray\_raylet.pyx", line 1856, in ray._raylet.execute_task
  File "python\ray\_raylet.pyx", line 1957, in ray._raylet.execute_task
  File "python\ray\_raylet.pyx", line 1862, in ray._raylet.execute_task
  File "python\ray\_raylet.pyx", line 1803, in ray._raylet.execute_task.function_executor
  File "C:\Users\clara\anaconda3\envs\tf_gpu\lib\site-packages\ray\_private\function_manager.py", line 696, in actor_method_executor
    return method(__ray_actor, *args, **kwargs)
  File "C:\Users\clara\anaconda3\envs\tf_gpu\lib\site-packages\ray\util\tracing\tracing_helper.py", line 467, in _resume_span
    return method(self, *_args, **_kwargs)
  File "C:\Users\clara\anaconda3\envs\tf_gpu\lib\site-packages\flwr\simulation\ray_transport\ray_actor.py", line 63, in run
    raise ClientAppException(str(ex)) from ex
flwr.client.client_app.ClientAppException: 
Exception ClientAppException occurred. Message: You called `set_weights(weights)` on layer 'sequential_3' with a weight list of length 0, but the layer was expecting 8 weights.
[2024-12-03 16:27:08,031][flwr][ERROR] - Traceback (most recent call last):
  File "C:\Users\clara\anaconda3\envs\tf_gpu\lib\site-packages\flwr\simulation\ray_transport\ray_client_proxy.py", line 94, in _submit_job
    out_mssg, updated_context = self.actor_pool.get_client_result(
  File "C:\Users\clara\anaconda3\envs\tf_gpu\lib\site-packages\flwr\simulation\ray_transport\ray_actor.py", line 398, in get_client_result
    return self._fetch_future_result(cid)
  File "C:\Users\clara\anaconda3\envs\tf_gpu\lib\site-packages\flwr\simulation\ray_transport\ray_actor.py", line 279, in _fetch_future_result
    res_cid, out_mssg, updated_context = ray.get(
  File "C:\Users\clara\anaconda3\envs\tf_gpu\lib\site-packages\ray\_private\auto_init_hook.py", line 21, in auto_init_wrapper
    return fn(*args, **kwargs)
  File "C:\Users\clara\anaconda3\envs\tf_gpu\lib\site-packages\ray\_private\client_mode_hook.py", line 103, in wrapper
    return func(*args, **kwargs)
  File "C:\Users\clara\anaconda3\envs\tf_gpu\lib\site-packages\ray\_private\worker.py", line 2753, in get
    values, debugger_breakpoint = worker.get_objects(object_refs, timeout=timeout)
  File "C:\Users\clara\anaconda3\envs\tf_gpu\lib\site-packages\ray\_private\worker.py", line 904, in get_objects
    raise value.as_instanceof_cause()
ray.exceptions.RayTaskError(ClientAppException): [36mray::ClientAppActor.run()[39m (pid=17372, ip=127.0.0.1, actor_id=38dbbf05716928ec6fb350bf01000000, repr=<flwr.simulation.ray_transport.ray_actor.ClientAppActor object at 0x00000210E74B0A60>)
  File "C:\Users\clara\anaconda3\envs\tf_gpu\lib\site-packages\flwr\client\client_app.py", line 143, in __call__
    return self._call(message, context)
  File "C:\Users\clara\anaconda3\envs\tf_gpu\lib\site-packages\flwr\client\client_app.py", line 126, in ffn
    out_message = handle_legacy_message_from_msgtype(
  File "C:\Users\clara\anaconda3\envs\tf_gpu\lib\site-packages\flwr\client\message_handler\message_handler.py", line 129, in handle_legacy_message_from_msgtype
    fit_res = maybe_call_fit(
  File "C:\Users\clara\anaconda3\envs\tf_gpu\lib\site-packages\flwr\client\client.py", line 255, in maybe_call_fit
    return client.fit(fit_ins)
  File "C:\Users\clara\anaconda3\envs\tf_gpu\lib\site-packages\flwr\client\numpy_client.py", line 259, in _fit
    results = self.numpy_client.fit(parameters, ins.config)  # type: ignore
  File "C:\Users\clara\Desktop\TFG\Codigo TFG\3.FederatedTraining\client.py", line 27, in fit
    self.model.set_weights(parameters)
  File "C:\Users\clara\anaconda3\envs\tf_gpu\lib\site-packages\keras\src\layers\layer.py", line 696, in set_weights
    raise ValueError(
ValueError: You called `set_weights(weights)` on layer 'sequential_2' with a weight list of length 0, but the layer was expecting 8 weights.

The above exception was the direct cause of the following exception:

[36mray::ClientAppActor.run()[39m (pid=17372, ip=127.0.0.1, actor_id=38dbbf05716928ec6fb350bf01000000, repr=<flwr.simulation.ray_transport.ray_actor.ClientAppActor object at 0x00000210E74B0A60>)
  File "python\ray\_raylet.pyx", line 1856, in ray._raylet.execute_task
  File "python\ray\_raylet.pyx", line 1957, in ray._raylet.execute_task
  File "python\ray\_raylet.pyx", line 1862, in ray._raylet.execute_task
  File "python\ray\_raylet.pyx", line 1803, in ray._raylet.execute_task.function_executor
  File "C:\Users\clara\anaconda3\envs\tf_gpu\lib\site-packages\ray\_private\function_manager.py", line 696, in actor_method_executor
    return method(__ray_actor, *args, **kwargs)
  File "C:\Users\clara\anaconda3\envs\tf_gpu\lib\site-packages\ray\util\tracing\tracing_helper.py", line 467, in _resume_span
    return method(self, *_args, **_kwargs)
  File "C:\Users\clara\anaconda3\envs\tf_gpu\lib\site-packages\flwr\simulation\ray_transport\ray_actor.py", line 63, in run
    raise ClientAppException(str(ex)) from ex
flwr.client.client_app.ClientAppException: 
Exception ClientAppException occurred. Message: You called `set_weights(weights)` on layer 'sequential_2' with a weight list of length 0, but the layer was expecting 8 weights.

[2024-12-03 16:27:08,044][flwr][ERROR] - [36mray::ClientAppActor.run()[39m (pid=17372, ip=127.0.0.1, actor_id=38dbbf05716928ec6fb350bf01000000, repr=<flwr.simulation.ray_transport.ray_actor.ClientAppActor object at 0x00000210E74B0A60>)
  File "C:\Users\clara\anaconda3\envs\tf_gpu\lib\site-packages\flwr\client\client_app.py", line 143, in __call__
    return self._call(message, context)
  File "C:\Users\clara\anaconda3\envs\tf_gpu\lib\site-packages\flwr\client\client_app.py", line 126, in ffn
    out_message = handle_legacy_message_from_msgtype(
  File "C:\Users\clara\anaconda3\envs\tf_gpu\lib\site-packages\flwr\client\message_handler\message_handler.py", line 129, in handle_legacy_message_from_msgtype
    fit_res = maybe_call_fit(
  File "C:\Users\clara\anaconda3\envs\tf_gpu\lib\site-packages\flwr\client\client.py", line 255, in maybe_call_fit
    return client.fit(fit_ins)
  File "C:\Users\clara\anaconda3\envs\tf_gpu\lib\site-packages\flwr\client\numpy_client.py", line 259, in _fit
    results = self.numpy_client.fit(parameters, ins.config)  # type: ignore
  File "C:\Users\clara\Desktop\TFG\Codigo TFG\3.FederatedTraining\client.py", line 27, in fit
    self.model.set_weights(parameters)
  File "C:\Users\clara\anaconda3\envs\tf_gpu\lib\site-packages\keras\src\layers\layer.py", line 696, in set_weights
    raise ValueError(
ValueError: You called `set_weights(weights)` on layer 'sequential_2' with a weight list of length 0, but the layer was expecting 8 weights.

The above exception was the direct cause of the following exception:

[36mray::ClientAppActor.run()[39m (pid=17372, ip=127.0.0.1, actor_id=38dbbf05716928ec6fb350bf01000000, repr=<flwr.simulation.ray_transport.ray_actor.ClientAppActor object at 0x00000210E74B0A60>)
  File "python\ray\_raylet.pyx", line 1856, in ray._raylet.execute_task
  File "python\ray\_raylet.pyx", line 1957, in ray._raylet.execute_task
  File "python\ray\_raylet.pyx", line 1862, in ray._raylet.execute_task
  File "python\ray\_raylet.pyx", line 1803, in ray._raylet.execute_task.function_executor
  File "C:\Users\clara\anaconda3\envs\tf_gpu\lib\site-packages\ray\_private\function_manager.py", line 696, in actor_method_executor
    return method(__ray_actor, *args, **kwargs)
  File "C:\Users\clara\anaconda3\envs\tf_gpu\lib\site-packages\ray\util\tracing\tracing_helper.py", line 467, in _resume_span
    return method(self, *_args, **_kwargs)
  File "C:\Users\clara\anaconda3\envs\tf_gpu\lib\site-packages\flwr\simulation\ray_transport\ray_actor.py", line 63, in run
    raise ClientAppException(str(ex)) from ex
flwr.client.client_app.ClientAppException: 
Exception ClientAppException occurred. Message: You called `set_weights(weights)` on layer 'sequential_2' with a weight list of length 0, but the layer was expecting 8 weights.
[2024-12-03 16:27:09,587][flwr][ERROR] - Traceback (most recent call last):
  File "C:\Users\clara\anaconda3\envs\tf_gpu\lib\site-packages\flwr\simulation\ray_transport\ray_client_proxy.py", line 94, in _submit_job
    out_mssg, updated_context = self.actor_pool.get_client_result(
  File "C:\Users\clara\anaconda3\envs\tf_gpu\lib\site-packages\flwr\simulation\ray_transport\ray_actor.py", line 398, in get_client_result
    return self._fetch_future_result(cid)
  File "C:\Users\clara\anaconda3\envs\tf_gpu\lib\site-packages\flwr\simulation\ray_transport\ray_actor.py", line 279, in _fetch_future_result
    res_cid, out_mssg, updated_context = ray.get(
  File "C:\Users\clara\anaconda3\envs\tf_gpu\lib\site-packages\ray\_private\auto_init_hook.py", line 21, in auto_init_wrapper
    return fn(*args, **kwargs)
  File "C:\Users\clara\anaconda3\envs\tf_gpu\lib\site-packages\ray\_private\client_mode_hook.py", line 103, in wrapper
    return func(*args, **kwargs)
  File "C:\Users\clara\anaconda3\envs\tf_gpu\lib\site-packages\ray\_private\worker.py", line 2753, in get
    values, debugger_breakpoint = worker.get_objects(object_refs, timeout=timeout)
  File "C:\Users\clara\anaconda3\envs\tf_gpu\lib\site-packages\ray\_private\worker.py", line 904, in get_objects
    raise value.as_instanceof_cause()
ray.exceptions.RayTaskError(ClientAppException): [36mray::ClientAppActor.run()[39m (pid=20408, ip=127.0.0.1, actor_id=e8f6c7b4b011b565c443b57701000000, repr=<flwr.simulation.ray_transport.ray_actor.ClientAppActor object at 0x0000015A5B8A28E0>)
  File "C:\Users\clara\anaconda3\envs\tf_gpu\lib\site-packages\flwr\client\client_app.py", line 143, in __call__
    return self._call(message, context)
  File "C:\Users\clara\anaconda3\envs\tf_gpu\lib\site-packages\flwr\client\client_app.py", line 126, in ffn
    out_message = handle_legacy_message_from_msgtype(
  File "C:\Users\clara\anaconda3\envs\tf_gpu\lib\site-packages\flwr\client\message_handler\message_handler.py", line 129, in handle_legacy_message_from_msgtype
    fit_res = maybe_call_fit(
  File "C:\Users\clara\anaconda3\envs\tf_gpu\lib\site-packages\flwr\client\client.py", line 255, in maybe_call_fit
    return client.fit(fit_ins)
  File "C:\Users\clara\anaconda3\envs\tf_gpu\lib\site-packages\flwr\client\numpy_client.py", line 259, in _fit
    results = self.numpy_client.fit(parameters, ins.config)  # type: ignore
  File "C:\Users\clara\Desktop\TFG\Codigo TFG\3.FederatedTraining\client.py", line 27, in fit
    self.model.set_weights(parameters)
  File "C:\Users\clara\anaconda3\envs\tf_gpu\lib\site-packages\keras\src\layers\layer.py", line 696, in set_weights
    raise ValueError(
ValueError: You called `set_weights(weights)` on layer 'sequential_4' with a weight list of length 0, but the layer was expecting 8 weights.

The above exception was the direct cause of the following exception:

[36mray::ClientAppActor.run()[39m (pid=20408, ip=127.0.0.1, actor_id=e8f6c7b4b011b565c443b57701000000, repr=<flwr.simulation.ray_transport.ray_actor.ClientAppActor object at 0x0000015A5B8A28E0>)
  File "python\ray\_raylet.pyx", line 1856, in ray._raylet.execute_task
  File "python\ray\_raylet.pyx", line 1957, in ray._raylet.execute_task
  File "python\ray\_raylet.pyx", line 1862, in ray._raylet.execute_task
  File "python\ray\_raylet.pyx", line 1803, in ray._raylet.execute_task.function_executor
  File "C:\Users\clara\anaconda3\envs\tf_gpu\lib\site-packages\ray\_private\function_manager.py", line 696, in actor_method_executor
    return method(__ray_actor, *args, **kwargs)
  File "C:\Users\clara\anaconda3\envs\tf_gpu\lib\site-packages\ray\util\tracing\tracing_helper.py", line 467, in _resume_span
    return method(self, *_args, **_kwargs)
  File "C:\Users\clara\anaconda3\envs\tf_gpu\lib\site-packages\flwr\simulation\ray_transport\ray_actor.py", line 63, in run
    raise ClientAppException(str(ex)) from ex
flwr.client.client_app.ClientAppException: 
Exception ClientAppException occurred. Message: You called `set_weights(weights)` on layer 'sequential_4' with a weight list of length 0, but the layer was expecting 8 weights.

[2024-12-03 16:27:09,599][flwr][ERROR] - [36mray::ClientAppActor.run()[39m (pid=20408, ip=127.0.0.1, actor_id=e8f6c7b4b011b565c443b57701000000, repr=<flwr.simulation.ray_transport.ray_actor.ClientAppActor object at 0x0000015A5B8A28E0>)
  File "C:\Users\clara\anaconda3\envs\tf_gpu\lib\site-packages\flwr\client\client_app.py", line 143, in __call__
    return self._call(message, context)
  File "C:\Users\clara\anaconda3\envs\tf_gpu\lib\site-packages\flwr\client\client_app.py", line 126, in ffn
    out_message = handle_legacy_message_from_msgtype(
  File "C:\Users\clara\anaconda3\envs\tf_gpu\lib\site-packages\flwr\client\message_handler\message_handler.py", line 129, in handle_legacy_message_from_msgtype
    fit_res = maybe_call_fit(
  File "C:\Users\clara\anaconda3\envs\tf_gpu\lib\site-packages\flwr\client\client.py", line 255, in maybe_call_fit
    return client.fit(fit_ins)
  File "C:\Users\clara\anaconda3\envs\tf_gpu\lib\site-packages\flwr\client\numpy_client.py", line 259, in _fit
    results = self.numpy_client.fit(parameters, ins.config)  # type: ignore
  File "C:\Users\clara\Desktop\TFG\Codigo TFG\3.FederatedTraining\client.py", line 27, in fit
    self.model.set_weights(parameters)
  File "C:\Users\clara\anaconda3\envs\tf_gpu\lib\site-packages\keras\src\layers\layer.py", line 696, in set_weights
    raise ValueError(
ValueError: You called `set_weights(weights)` on layer 'sequential_4' with a weight list of length 0, but the layer was expecting 8 weights.

The above exception was the direct cause of the following exception:

[36mray::ClientAppActor.run()[39m (pid=20408, ip=127.0.0.1, actor_id=e8f6c7b4b011b565c443b57701000000, repr=<flwr.simulation.ray_transport.ray_actor.ClientAppActor object at 0x0000015A5B8A28E0>)
  File "python\ray\_raylet.pyx", line 1856, in ray._raylet.execute_task
  File "python\ray\_raylet.pyx", line 1957, in ray._raylet.execute_task
  File "python\ray\_raylet.pyx", line 1862, in ray._raylet.execute_task
  File "python\ray\_raylet.pyx", line 1803, in ray._raylet.execute_task.function_executor
  File "C:\Users\clara\anaconda3\envs\tf_gpu\lib\site-packages\ray\_private\function_manager.py", line 696, in actor_method_executor
    return method(__ray_actor, *args, **kwargs)
  File "C:\Users\clara\anaconda3\envs\tf_gpu\lib\site-packages\ray\util\tracing\tracing_helper.py", line 467, in _resume_span
    return method(self, *_args, **_kwargs)
  File "C:\Users\clara\anaconda3\envs\tf_gpu\lib\site-packages\flwr\simulation\ray_transport\ray_actor.py", line 63, in run
    raise ClientAppException(str(ex)) from ex
flwr.client.client_app.ClientAppException: 
Exception ClientAppException occurred. Message: You called `set_weights(weights)` on layer 'sequential_4' with a weight list of length 0, but the layer was expecting 8 weights.
[2024-12-03 16:27:12,639][flwr][ERROR] - Traceback (most recent call last):
  File "C:\Users\clara\anaconda3\envs\tf_gpu\lib\site-packages\flwr\simulation\ray_transport\ray_client_proxy.py", line 94, in _submit_job
    out_mssg, updated_context = self.actor_pool.get_client_result(
  File "C:\Users\clara\anaconda3\envs\tf_gpu\lib\site-packages\flwr\simulation\ray_transport\ray_actor.py", line 398, in get_client_result
    return self._fetch_future_result(cid)
  File "C:\Users\clara\anaconda3\envs\tf_gpu\lib\site-packages\flwr\simulation\ray_transport\ray_actor.py", line 279, in _fetch_future_result
    res_cid, out_mssg, updated_context = ray.get(
  File "C:\Users\clara\anaconda3\envs\tf_gpu\lib\site-packages\ray\_private\auto_init_hook.py", line 21, in auto_init_wrapper
    return fn(*args, **kwargs)
  File "C:\Users\clara\anaconda3\envs\tf_gpu\lib\site-packages\ray\_private\client_mode_hook.py", line 103, in wrapper
    return func(*args, **kwargs)
  File "C:\Users\clara\anaconda3\envs\tf_gpu\lib\site-packages\ray\_private\worker.py", line 2753, in get
    values, debugger_breakpoint = worker.get_objects(object_refs, timeout=timeout)
  File "C:\Users\clara\anaconda3\envs\tf_gpu\lib\site-packages\ray\_private\worker.py", line 904, in get_objects
    raise value.as_instanceof_cause()
ray.exceptions.RayTaskError(ClientAppException): [36mray::ClientAppActor.run()[39m (pid=17372, ip=127.0.0.1, actor_id=38dbbf05716928ec6fb350bf01000000, repr=<flwr.simulation.ray_transport.ray_actor.ClientAppActor object at 0x00000210E74B0A60>)
  File "C:\Users\clara\anaconda3\envs\tf_gpu\lib\site-packages\flwr\client\client_app.py", line 143, in __call__
    return self._call(message, context)
  File "C:\Users\clara\anaconda3\envs\tf_gpu\lib\site-packages\flwr\client\client_app.py", line 126, in ffn
    out_message = handle_legacy_message_from_msgtype(
  File "C:\Users\clara\anaconda3\envs\tf_gpu\lib\site-packages\flwr\client\message_handler\message_handler.py", line 129, in handle_legacy_message_from_msgtype
    fit_res = maybe_call_fit(
  File "C:\Users\clara\anaconda3\envs\tf_gpu\lib\site-packages\flwr\client\client.py", line 255, in maybe_call_fit
    return client.fit(fit_ins)
  File "C:\Users\clara\anaconda3\envs\tf_gpu\lib\site-packages\flwr\client\numpy_client.py", line 259, in _fit
    results = self.numpy_client.fit(parameters, ins.config)  # type: ignore
  File "C:\Users\clara\Desktop\TFG\Codigo TFG\3.FederatedTraining\client.py", line 27, in fit
    self.model.set_weights(parameters)
  File "C:\Users\clara\anaconda3\envs\tf_gpu\lib\site-packages\keras\src\layers\layer.py", line 696, in set_weights
    raise ValueError(
ValueError: You called `set_weights(weights)` on layer 'sequential_3' with a weight list of length 0, but the layer was expecting 8 weights.

The above exception was the direct cause of the following exception:

[36mray::ClientAppActor.run()[39m (pid=17372, ip=127.0.0.1, actor_id=38dbbf05716928ec6fb350bf01000000, repr=<flwr.simulation.ray_transport.ray_actor.ClientAppActor object at 0x00000210E74B0A60>)
  File "python\ray\_raylet.pyx", line 1856, in ray._raylet.execute_task
  File "python\ray\_raylet.pyx", line 1957, in ray._raylet.execute_task
  File "python\ray\_raylet.pyx", line 1862, in ray._raylet.execute_task
  File "python\ray\_raylet.pyx", line 1803, in ray._raylet.execute_task.function_executor
  File "C:\Users\clara\anaconda3\envs\tf_gpu\lib\site-packages\ray\_private\function_manager.py", line 696, in actor_method_executor
    return method(__ray_actor, *args, **kwargs)
  File "C:\Users\clara\anaconda3\envs\tf_gpu\lib\site-packages\ray\util\tracing\tracing_helper.py", line 467, in _resume_span
    return method(self, *_args, **_kwargs)
  File "C:\Users\clara\anaconda3\envs\tf_gpu\lib\site-packages\flwr\simulation\ray_transport\ray_actor.py", line 63, in run
    raise ClientAppException(str(ex)) from ex
flwr.client.client_app.ClientAppException: 
Exception ClientAppException occurred. Message: You called `set_weights(weights)` on layer 'sequential_3' with a weight list of length 0, but the layer was expecting 8 weights.

[2024-12-03 16:27:12,650][flwr][ERROR] - [36mray::ClientAppActor.run()[39m (pid=17372, ip=127.0.0.1, actor_id=38dbbf05716928ec6fb350bf01000000, repr=<flwr.simulation.ray_transport.ray_actor.ClientAppActor object at 0x00000210E74B0A60>)
  File "C:\Users\clara\anaconda3\envs\tf_gpu\lib\site-packages\flwr\client\client_app.py", line 143, in __call__
    return self._call(message, context)
  File "C:\Users\clara\anaconda3\envs\tf_gpu\lib\site-packages\flwr\client\client_app.py", line 126, in ffn
    out_message = handle_legacy_message_from_msgtype(
  File "C:\Users\clara\anaconda3\envs\tf_gpu\lib\site-packages\flwr\client\message_handler\message_handler.py", line 129, in handle_legacy_message_from_msgtype
    fit_res = maybe_call_fit(
  File "C:\Users\clara\anaconda3\envs\tf_gpu\lib\site-packages\flwr\client\client.py", line 255, in maybe_call_fit
    return client.fit(fit_ins)
  File "C:\Users\clara\anaconda3\envs\tf_gpu\lib\site-packages\flwr\client\numpy_client.py", line 259, in _fit
    results = self.numpy_client.fit(parameters, ins.config)  # type: ignore
  File "C:\Users\clara\Desktop\TFG\Codigo TFG\3.FederatedTraining\client.py", line 27, in fit
    self.model.set_weights(parameters)
  File "C:\Users\clara\anaconda3\envs\tf_gpu\lib\site-packages\keras\src\layers\layer.py", line 696, in set_weights
    raise ValueError(
ValueError: You called `set_weights(weights)` on layer 'sequential_3' with a weight list of length 0, but the layer was expecting 8 weights.

The above exception was the direct cause of the following exception:

[36mray::ClientAppActor.run()[39m (pid=17372, ip=127.0.0.1, actor_id=38dbbf05716928ec6fb350bf01000000, repr=<flwr.simulation.ray_transport.ray_actor.ClientAppActor object at 0x00000210E74B0A60>)
  File "python\ray\_raylet.pyx", line 1856, in ray._raylet.execute_task
  File "python\ray\_raylet.pyx", line 1957, in ray._raylet.execute_task
  File "python\ray\_raylet.pyx", line 1862, in ray._raylet.execute_task
  File "python\ray\_raylet.pyx", line 1803, in ray._raylet.execute_task.function_executor
  File "C:\Users\clara\anaconda3\envs\tf_gpu\lib\site-packages\ray\_private\function_manager.py", line 696, in actor_method_executor
    return method(__ray_actor, *args, **kwargs)
  File "C:\Users\clara\anaconda3\envs\tf_gpu\lib\site-packages\ray\util\tracing\tracing_helper.py", line 467, in _resume_span
    return method(self, *_args, **_kwargs)
  File "C:\Users\clara\anaconda3\envs\tf_gpu\lib\site-packages\flwr\simulation\ray_transport\ray_actor.py", line 63, in run
    raise ClientAppException(str(ex)) from ex
flwr.client.client_app.ClientAppException: 
Exception ClientAppException occurred. Message: You called `set_weights(weights)` on layer 'sequential_3' with a weight list of length 0, but the layer was expecting 8 weights.
[2024-12-03 16:27:12,659][flwr][INFO] - aggregate_fit: received 0 results and 8 failures
[2024-12-03 16:27:26,618][flwr][INFO] - fit progress: (1, 0.14584900438785553, {'mae': 0.34009531140327454}, 29.9656679)
[2024-12-03 16:27:26,619][flwr][INFO] - configure_evaluate: strategy sampled 10 clients (out of 12)
[2024-12-03 16:27:28,055][flwr][ERROR] - Traceback (most recent call last):
  File "C:\Users\clara\anaconda3\envs\tf_gpu\lib\site-packages\flwr\simulation\ray_transport\ray_client_proxy.py", line 94, in _submit_job
    out_mssg, updated_context = self.actor_pool.get_client_result(
  File "C:\Users\clara\anaconda3\envs\tf_gpu\lib\site-packages\flwr\simulation\ray_transport\ray_actor.py", line 398, in get_client_result
    return self._fetch_future_result(cid)
  File "C:\Users\clara\anaconda3\envs\tf_gpu\lib\site-packages\flwr\simulation\ray_transport\ray_actor.py", line 279, in _fetch_future_result
    res_cid, out_mssg, updated_context = ray.get(
  File "C:\Users\clara\anaconda3\envs\tf_gpu\lib\site-packages\ray\_private\auto_init_hook.py", line 21, in auto_init_wrapper
    return fn(*args, **kwargs)
  File "C:\Users\clara\anaconda3\envs\tf_gpu\lib\site-packages\ray\_private\client_mode_hook.py", line 103, in wrapper
    return func(*args, **kwargs)
  File "C:\Users\clara\anaconda3\envs\tf_gpu\lib\site-packages\ray\_private\worker.py", line 2753, in get
    values, debugger_breakpoint = worker.get_objects(object_refs, timeout=timeout)
  File "C:\Users\clara\anaconda3\envs\tf_gpu\lib\site-packages\ray\_private\worker.py", line 904, in get_objects
    raise value.as_instanceof_cause()
ray.exceptions.RayTaskError(ClientAppException): [36mray::ClientAppActor.run()[39m (pid=17372, ip=127.0.0.1, actor_id=38dbbf05716928ec6fb350bf01000000, repr=<flwr.simulation.ray_transport.ray_actor.ClientAppActor object at 0x00000210E74B0A60>)
  File "C:\Users\clara\anaconda3\envs\tf_gpu\lib\site-packages\flwr\client\client_app.py", line 143, in __call__
    return self._call(message, context)
  File "C:\Users\clara\anaconda3\envs\tf_gpu\lib\site-packages\flwr\client\client_app.py", line 126, in ffn
    out_message = handle_legacy_message_from_msgtype(
  File "C:\Users\clara\anaconda3\envs\tf_gpu\lib\site-packages\flwr\client\message_handler\message_handler.py", line 136, in handle_legacy_message_from_msgtype
    evaluate_res = maybe_call_evaluate(
  File "C:\Users\clara\anaconda3\envs\tf_gpu\lib\site-packages\flwr\client\client.py", line 275, in maybe_call_evaluate
    return client.evaluate(evaluate_ins)
  File "C:\Users\clara\anaconda3\envs\tf_gpu\lib\site-packages\flwr\client\numpy_client.py", line 283, in _evaluate
    results = self.numpy_client.evaluate(parameters, ins.config)  # type: ignore
  File "C:\Users\clara\Desktop\TFG\Codigo TFG\3.FederatedTraining\client.py", line 38, in evaluate
    self.model.set_weights(parameters)
  File "C:\Users\clara\anaconda3\envs\tf_gpu\lib\site-packages\keras\src\layers\layer.py", line 696, in set_weights
    raise ValueError(
ValueError: You called `set_weights(weights)` on layer 'sequential_4' with a weight list of length 0, but the layer was expecting 8 weights.

The above exception was the direct cause of the following exception:

[36mray::ClientAppActor.run()[39m (pid=17372, ip=127.0.0.1, actor_id=38dbbf05716928ec6fb350bf01000000, repr=<flwr.simulation.ray_transport.ray_actor.ClientAppActor object at 0x00000210E74B0A60>)
  File "python\ray\_raylet.pyx", line 1856, in ray._raylet.execute_task
  File "python\ray\_raylet.pyx", line 1957, in ray._raylet.execute_task
  File "python\ray\_raylet.pyx", line 1862, in ray._raylet.execute_task
  File "python\ray\_raylet.pyx", line 1803, in ray._raylet.execute_task.function_executor
  File "C:\Users\clara\anaconda3\envs\tf_gpu\lib\site-packages\ray\_private\function_manager.py", line 696, in actor_method_executor
    return method(__ray_actor, *args, **kwargs)
  File "C:\Users\clara\anaconda3\envs\tf_gpu\lib\site-packages\ray\util\tracing\tracing_helper.py", line 467, in _resume_span
    return method(self, *_args, **_kwargs)
  File "C:\Users\clara\anaconda3\envs\tf_gpu\lib\site-packages\flwr\simulation\ray_transport\ray_actor.py", line 63, in run
    raise ClientAppException(str(ex)) from ex
flwr.client.client_app.ClientAppException: 
Exception ClientAppException occurred. Message: You called `set_weights(weights)` on layer 'sequential_4' with a weight list of length 0, but the layer was expecting 8 weights.

[2024-12-03 16:27:28,068][flwr][ERROR] - [36mray::ClientAppActor.run()[39m (pid=17372, ip=127.0.0.1, actor_id=38dbbf05716928ec6fb350bf01000000, repr=<flwr.simulation.ray_transport.ray_actor.ClientAppActor object at 0x00000210E74B0A60>)
  File "C:\Users\clara\anaconda3\envs\tf_gpu\lib\site-packages\flwr\client\client_app.py", line 143, in __call__
    return self._call(message, context)
  File "C:\Users\clara\anaconda3\envs\tf_gpu\lib\site-packages\flwr\client\client_app.py", line 126, in ffn
    out_message = handle_legacy_message_from_msgtype(
  File "C:\Users\clara\anaconda3\envs\tf_gpu\lib\site-packages\flwr\client\message_handler\message_handler.py", line 136, in handle_legacy_message_from_msgtype
    evaluate_res = maybe_call_evaluate(
  File "C:\Users\clara\anaconda3\envs\tf_gpu\lib\site-packages\flwr\client\client.py", line 275, in maybe_call_evaluate
    return client.evaluate(evaluate_ins)
  File "C:\Users\clara\anaconda3\envs\tf_gpu\lib\site-packages\flwr\client\numpy_client.py", line 283, in _evaluate
    results = self.numpy_client.evaluate(parameters, ins.config)  # type: ignore
  File "C:\Users\clara\Desktop\TFG\Codigo TFG\3.FederatedTraining\client.py", line 38, in evaluate
    self.model.set_weights(parameters)
  File "C:\Users\clara\anaconda3\envs\tf_gpu\lib\site-packages\keras\src\layers\layer.py", line 696, in set_weights
    raise ValueError(
ValueError: You called `set_weights(weights)` on layer 'sequential_4' with a weight list of length 0, but the layer was expecting 8 weights.

The above exception was the direct cause of the following exception:

[36mray::ClientAppActor.run()[39m (pid=17372, ip=127.0.0.1, actor_id=38dbbf05716928ec6fb350bf01000000, repr=<flwr.simulation.ray_transport.ray_actor.ClientAppActor object at 0x00000210E74B0A60>)
  File "python\ray\_raylet.pyx", line 1856, in ray._raylet.execute_task
  File "python\ray\_raylet.pyx", line 1957, in ray._raylet.execute_task
  File "python\ray\_raylet.pyx", line 1862, in ray._raylet.execute_task
  File "python\ray\_raylet.pyx", line 1803, in ray._raylet.execute_task.function_executor
  File "C:\Users\clara\anaconda3\envs\tf_gpu\lib\site-packages\ray\_private\function_manager.py", line 696, in actor_method_executor
    return method(__ray_actor, *args, **kwargs)
  File "C:\Users\clara\anaconda3\envs\tf_gpu\lib\site-packages\ray\util\tracing\tracing_helper.py", line 467, in _resume_span
    return method(self, *_args, **_kwargs)
  File "C:\Users\clara\anaconda3\envs\tf_gpu\lib\site-packages\flwr\simulation\ray_transport\ray_actor.py", line 63, in run
    raise ClientAppException(str(ex)) from ex
flwr.client.client_app.ClientAppException: 
Exception ClientAppException occurred. Message: You called `set_weights(weights)` on layer 'sequential_4' with a weight list of length 0, but the layer was expecting 8 weights.
[2024-12-03 16:27:29,334][flwr][ERROR] - Traceback (most recent call last):
  File "C:\Users\clara\anaconda3\envs\tf_gpu\lib\site-packages\flwr\simulation\ray_transport\ray_client_proxy.py", line 94, in _submit_job
    out_mssg, updated_context = self.actor_pool.get_client_result(
  File "C:\Users\clara\anaconda3\envs\tf_gpu\lib\site-packages\flwr\simulation\ray_transport\ray_actor.py", line 398, in get_client_result
    return self._fetch_future_result(cid)
  File "C:\Users\clara\anaconda3\envs\tf_gpu\lib\site-packages\flwr\simulation\ray_transport\ray_actor.py", line 279, in _fetch_future_result
    res_cid, out_mssg, updated_context = ray.get(
  File "C:\Users\clara\anaconda3\envs\tf_gpu\lib\site-packages\ray\_private\auto_init_hook.py", line 21, in auto_init_wrapper
    return fn(*args, **kwargs)
  File "C:\Users\clara\anaconda3\envs\tf_gpu\lib\site-packages\ray\_private\client_mode_hook.py", line 103, in wrapper
    return func(*args, **kwargs)
  File "C:\Users\clara\anaconda3\envs\tf_gpu\lib\site-packages\ray\_private\worker.py", line 2753, in get
    values, debugger_breakpoint = worker.get_objects(object_refs, timeout=timeout)
  File "C:\Users\clara\anaconda3\envs\tf_gpu\lib\site-packages\ray\_private\worker.py", line 904, in get_objects
    raise value.as_instanceof_cause()
ray.exceptions.RayTaskError(ClientAppException): [36mray::ClientAppActor.run()[39m (pid=20408, ip=127.0.0.1, actor_id=e8f6c7b4b011b565c443b57701000000, repr=<flwr.simulation.ray_transport.ray_actor.ClientAppActor object at 0x0000015A5B8A28E0>)
  File "C:\Users\clara\anaconda3\envs\tf_gpu\lib\site-packages\flwr\client\client_app.py", line 143, in __call__
    return self._call(message, context)
  File "C:\Users\clara\anaconda3\envs\tf_gpu\lib\site-packages\flwr\client\client_app.py", line 126, in ffn
    out_message = handle_legacy_message_from_msgtype(
  File "C:\Users\clara\anaconda3\envs\tf_gpu\lib\site-packages\flwr\client\message_handler\message_handler.py", line 136, in handle_legacy_message_from_msgtype
    evaluate_res = maybe_call_evaluate(
  File "C:\Users\clara\anaconda3\envs\tf_gpu\lib\site-packages\flwr\client\client.py", line 275, in maybe_call_evaluate
    return client.evaluate(evaluate_ins)
  File "C:\Users\clara\anaconda3\envs\tf_gpu\lib\site-packages\flwr\client\numpy_client.py", line 283, in _evaluate
    results = self.numpy_client.evaluate(parameters, ins.config)  # type: ignore
  File "C:\Users\clara\Desktop\TFG\Codigo TFG\3.FederatedTraining\client.py", line 38, in evaluate
    self.model.set_weights(parameters)
  File "C:\Users\clara\anaconda3\envs\tf_gpu\lib\site-packages\keras\src\layers\layer.py", line 696, in set_weights
    raise ValueError(
ValueError: You called `set_weights(weights)` on layer 'sequential_5' with a weight list of length 0, but the layer was expecting 8 weights.

The above exception was the direct cause of the following exception:

[36mray::ClientAppActor.run()[39m (pid=20408, ip=127.0.0.1, actor_id=e8f6c7b4b011b565c443b57701000000, repr=<flwr.simulation.ray_transport.ray_actor.ClientAppActor object at 0x0000015A5B8A28E0>)
  File "python\ray\_raylet.pyx", line 1856, in ray._raylet.execute_task
  File "python\ray\_raylet.pyx", line 1957, in ray._raylet.execute_task
  File "python\ray\_raylet.pyx", line 1862, in ray._raylet.execute_task
  File "python\ray\_raylet.pyx", line 1803, in ray._raylet.execute_task.function_executor
  File "C:\Users\clara\anaconda3\envs\tf_gpu\lib\site-packages\ray\_private\function_manager.py", line 696, in actor_method_executor
    return method(__ray_actor, *args, **kwargs)
  File "C:\Users\clara\anaconda3\envs\tf_gpu\lib\site-packages\ray\util\tracing\tracing_helper.py", line 467, in _resume_span
    return method(self, *_args, **_kwargs)
  File "C:\Users\clara\anaconda3\envs\tf_gpu\lib\site-packages\flwr\simulation\ray_transport\ray_actor.py", line 63, in run
    raise ClientAppException(str(ex)) from ex
flwr.client.client_app.ClientAppException: 
Exception ClientAppException occurred. Message: You called `set_weights(weights)` on layer 'sequential_5' with a weight list of length 0, but the layer was expecting 8 weights.

[2024-12-03 16:27:29,346][flwr][ERROR] - [36mray::ClientAppActor.run()[39m (pid=20408, ip=127.0.0.1, actor_id=e8f6c7b4b011b565c443b57701000000, repr=<flwr.simulation.ray_transport.ray_actor.ClientAppActor object at 0x0000015A5B8A28E0>)
  File "C:\Users\clara\anaconda3\envs\tf_gpu\lib\site-packages\flwr\client\client_app.py", line 143, in __call__
    return self._call(message, context)
  File "C:\Users\clara\anaconda3\envs\tf_gpu\lib\site-packages\flwr\client\client_app.py", line 126, in ffn
    out_message = handle_legacy_message_from_msgtype(
  File "C:\Users\clara\anaconda3\envs\tf_gpu\lib\site-packages\flwr\client\message_handler\message_handler.py", line 136, in handle_legacy_message_from_msgtype
    evaluate_res = maybe_call_evaluate(
  File "C:\Users\clara\anaconda3\envs\tf_gpu\lib\site-packages\flwr\client\client.py", line 275, in maybe_call_evaluate
    return client.evaluate(evaluate_ins)
  File "C:\Users\clara\anaconda3\envs\tf_gpu\lib\site-packages\flwr\client\numpy_client.py", line 283, in _evaluate
    results = self.numpy_client.evaluate(parameters, ins.config)  # type: ignore
  File "C:\Users\clara\Desktop\TFG\Codigo TFG\3.FederatedTraining\client.py", line 38, in evaluate
    self.model.set_weights(parameters)
  File "C:\Users\clara\anaconda3\envs\tf_gpu\lib\site-packages\keras\src\layers\layer.py", line 696, in set_weights
    raise ValueError(
ValueError: You called `set_weights(weights)` on layer 'sequential_5' with a weight list of length 0, but the layer was expecting 8 weights.

The above exception was the direct cause of the following exception:

[36mray::ClientAppActor.run()[39m (pid=20408, ip=127.0.0.1, actor_id=e8f6c7b4b011b565c443b57701000000, repr=<flwr.simulation.ray_transport.ray_actor.ClientAppActor object at 0x0000015A5B8A28E0>)
  File "python\ray\_raylet.pyx", line 1856, in ray._raylet.execute_task
  File "python\ray\_raylet.pyx", line 1957, in ray._raylet.execute_task
  File "python\ray\_raylet.pyx", line 1862, in ray._raylet.execute_task
  File "python\ray\_raylet.pyx", line 1803, in ray._raylet.execute_task.function_executor
  File "C:\Users\clara\anaconda3\envs\tf_gpu\lib\site-packages\ray\_private\function_manager.py", line 696, in actor_method_executor
    return method(__ray_actor, *args, **kwargs)
  File "C:\Users\clara\anaconda3\envs\tf_gpu\lib\site-packages\ray\util\tracing\tracing_helper.py", line 467, in _resume_span
    return method(self, *_args, **_kwargs)
  File "C:\Users\clara\anaconda3\envs\tf_gpu\lib\site-packages\flwr\simulation\ray_transport\ray_actor.py", line 63, in run
    raise ClientAppException(str(ex)) from ex
flwr.client.client_app.ClientAppException: 
Exception ClientAppException occurred. Message: You called `set_weights(weights)` on layer 'sequential_5' with a weight list of length 0, but the layer was expecting 8 weights.
[2024-12-03 16:27:32,047][flwr][ERROR] - Traceback (most recent call last):
  File "C:\Users\clara\anaconda3\envs\tf_gpu\lib\site-packages\flwr\simulation\ray_transport\ray_client_proxy.py", line 94, in _submit_job
    out_mssg, updated_context = self.actor_pool.get_client_result(
  File "C:\Users\clara\anaconda3\envs\tf_gpu\lib\site-packages\flwr\simulation\ray_transport\ray_actor.py", line 398, in get_client_result
    return self._fetch_future_result(cid)
  File "C:\Users\clara\anaconda3\envs\tf_gpu\lib\site-packages\flwr\simulation\ray_transport\ray_actor.py", line 279, in _fetch_future_result
    res_cid, out_mssg, updated_context = ray.get(
  File "C:\Users\clara\anaconda3\envs\tf_gpu\lib\site-packages\ray\_private\auto_init_hook.py", line 21, in auto_init_wrapper
    return fn(*args, **kwargs)
  File "C:\Users\clara\anaconda3\envs\tf_gpu\lib\site-packages\ray\_private\client_mode_hook.py", line 103, in wrapper
    return func(*args, **kwargs)
  File "C:\Users\clara\anaconda3\envs\tf_gpu\lib\site-packages\ray\_private\worker.py", line 2753, in get
    values, debugger_breakpoint = worker.get_objects(object_refs, timeout=timeout)
  File "C:\Users\clara\anaconda3\envs\tf_gpu\lib\site-packages\ray\_private\worker.py", line 904, in get_objects
    raise value.as_instanceof_cause()
ray.exceptions.RayTaskError(ClientAppException): [36mray::ClientAppActor.run()[39m (pid=17372, ip=127.0.0.1, actor_id=38dbbf05716928ec6fb350bf01000000, repr=<flwr.simulation.ray_transport.ray_actor.ClientAppActor object at 0x00000210E74B0A60>)
  File "C:\Users\clara\anaconda3\envs\tf_gpu\lib\site-packages\flwr\client\client_app.py", line 143, in __call__
    return self._call(message, context)
  File "C:\Users\clara\anaconda3\envs\tf_gpu\lib\site-packages\flwr\client\client_app.py", line 126, in ffn
    out_message = handle_legacy_message_from_msgtype(
  File "C:\Users\clara\anaconda3\envs\tf_gpu\lib\site-packages\flwr\client\message_handler\message_handler.py", line 136, in handle_legacy_message_from_msgtype
    evaluate_res = maybe_call_evaluate(
  File "C:\Users\clara\anaconda3\envs\tf_gpu\lib\site-packages\flwr\client\client.py", line 275, in maybe_call_evaluate
    return client.evaluate(evaluate_ins)
  File "C:\Users\clara\anaconda3\envs\tf_gpu\lib\site-packages\flwr\client\numpy_client.py", line 283, in _evaluate
    results = self.numpy_client.evaluate(parameters, ins.config)  # type: ignore
  File "C:\Users\clara\Desktop\TFG\Codigo TFG\3.FederatedTraining\client.py", line 38, in evaluate
    self.model.set_weights(parameters)
  File "C:\Users\clara\anaconda3\envs\tf_gpu\lib\site-packages\keras\src\layers\layer.py", line 696, in set_weights
    raise ValueError(
ValueError: You called `set_weights(weights)` on layer 'sequential_5' with a weight list of length 0, but the layer was expecting 8 weights.

The above exception was the direct cause of the following exception:

[36mray::ClientAppActor.run()[39m (pid=17372, ip=127.0.0.1, actor_id=38dbbf05716928ec6fb350bf01000000, repr=<flwr.simulation.ray_transport.ray_actor.ClientAppActor object at 0x00000210E74B0A60>)
  File "python\ray\_raylet.pyx", line 1856, in ray._raylet.execute_task
  File "python\ray\_raylet.pyx", line 1957, in ray._raylet.execute_task
  File "python\ray\_raylet.pyx", line 1862, in ray._raylet.execute_task
  File "python\ray\_raylet.pyx", line 1803, in ray._raylet.execute_task.function_executor
  File "C:\Users\clara\anaconda3\envs\tf_gpu\lib\site-packages\ray\_private\function_manager.py", line 696, in actor_method_executor
    return method(__ray_actor, *args, **kwargs)
  File "C:\Users\clara\anaconda3\envs\tf_gpu\lib\site-packages\ray\util\tracing\tracing_helper.py", line 467, in _resume_span
    return method(self, *_args, **_kwargs)
  File "C:\Users\clara\anaconda3\envs\tf_gpu\lib\site-packages\flwr\simulation\ray_transport\ray_actor.py", line 63, in run
    raise ClientAppException(str(ex)) from ex
flwr.client.client_app.ClientAppException: 
Exception ClientAppException occurred. Message: You called `set_weights(weights)` on layer 'sequential_5' with a weight list of length 0, but the layer was expecting 8 weights.

[2024-12-03 16:27:32,057][flwr][ERROR] - [36mray::ClientAppActor.run()[39m (pid=17372, ip=127.0.0.1, actor_id=38dbbf05716928ec6fb350bf01000000, repr=<flwr.simulation.ray_transport.ray_actor.ClientAppActor object at 0x00000210E74B0A60>)
  File "C:\Users\clara\anaconda3\envs\tf_gpu\lib\site-packages\flwr\client\client_app.py", line 143, in __call__
    return self._call(message, context)
  File "C:\Users\clara\anaconda3\envs\tf_gpu\lib\site-packages\flwr\client\client_app.py", line 126, in ffn
    out_message = handle_legacy_message_from_msgtype(
  File "C:\Users\clara\anaconda3\envs\tf_gpu\lib\site-packages\flwr\client\message_handler\message_handler.py", line 136, in handle_legacy_message_from_msgtype
    evaluate_res = maybe_call_evaluate(
  File "C:\Users\clara\anaconda3\envs\tf_gpu\lib\site-packages\flwr\client\client.py", line 275, in maybe_call_evaluate
    return client.evaluate(evaluate_ins)
  File "C:\Users\clara\anaconda3\envs\tf_gpu\lib\site-packages\flwr\client\numpy_client.py", line 283, in _evaluate
    results = self.numpy_client.evaluate(parameters, ins.config)  # type: ignore
  File "C:\Users\clara\Desktop\TFG\Codigo TFG\3.FederatedTraining\client.py", line 38, in evaluate
    self.model.set_weights(parameters)
  File "C:\Users\clara\anaconda3\envs\tf_gpu\lib\site-packages\keras\src\layers\layer.py", line 696, in set_weights
    raise ValueError(
ValueError: You called `set_weights(weights)` on layer 'sequential_5' with a weight list of length 0, but the layer was expecting 8 weights.

The above exception was the direct cause of the following exception:

[36mray::ClientAppActor.run()[39m (pid=17372, ip=127.0.0.1, actor_id=38dbbf05716928ec6fb350bf01000000, repr=<flwr.simulation.ray_transport.ray_actor.ClientAppActor object at 0x00000210E74B0A60>)
  File "python\ray\_raylet.pyx", line 1856, in ray._raylet.execute_task
  File "python\ray\_raylet.pyx", line 1957, in ray._raylet.execute_task
  File "python\ray\_raylet.pyx", line 1862, in ray._raylet.execute_task
  File "python\ray\_raylet.pyx", line 1803, in ray._raylet.execute_task.function_executor
  File "C:\Users\clara\anaconda3\envs\tf_gpu\lib\site-packages\ray\_private\function_manager.py", line 696, in actor_method_executor
    return method(__ray_actor, *args, **kwargs)
  File "C:\Users\clara\anaconda3\envs\tf_gpu\lib\site-packages\ray\util\tracing\tracing_helper.py", line 467, in _resume_span
    return method(self, *_args, **_kwargs)
  File "C:\Users\clara\anaconda3\envs\tf_gpu\lib\site-packages\flwr\simulation\ray_transport\ray_actor.py", line 63, in run
    raise ClientAppException(str(ex)) from ex
flwr.client.client_app.ClientAppException: 
Exception ClientAppException occurred. Message: You called `set_weights(weights)` on layer 'sequential_5' with a weight list of length 0, but the layer was expecting 8 weights.
[2024-12-03 16:27:33,567][flwr][ERROR] - Traceback (most recent call last):
  File "C:\Users\clara\anaconda3\envs\tf_gpu\lib\site-packages\flwr\simulation\ray_transport\ray_client_proxy.py", line 94, in _submit_job
    out_mssg, updated_context = self.actor_pool.get_client_result(
  File "C:\Users\clara\anaconda3\envs\tf_gpu\lib\site-packages\flwr\simulation\ray_transport\ray_actor.py", line 398, in get_client_result
    return self._fetch_future_result(cid)
  File "C:\Users\clara\anaconda3\envs\tf_gpu\lib\site-packages\flwr\simulation\ray_transport\ray_actor.py", line 279, in _fetch_future_result
    res_cid, out_mssg, updated_context = ray.get(
  File "C:\Users\clara\anaconda3\envs\tf_gpu\lib\site-packages\ray\_private\auto_init_hook.py", line 21, in auto_init_wrapper
    return fn(*args, **kwargs)
  File "C:\Users\clara\anaconda3\envs\tf_gpu\lib\site-packages\ray\_private\client_mode_hook.py", line 103, in wrapper
    return func(*args, **kwargs)
  File "C:\Users\clara\anaconda3\envs\tf_gpu\lib\site-packages\ray\_private\worker.py", line 2753, in get
    values, debugger_breakpoint = worker.get_objects(object_refs, timeout=timeout)
  File "C:\Users\clara\anaconda3\envs\tf_gpu\lib\site-packages\ray\_private\worker.py", line 904, in get_objects
    raise value.as_instanceof_cause()
ray.exceptions.RayTaskError(ClientAppException): [36mray::ClientAppActor.run()[39m (pid=20408, ip=127.0.0.1, actor_id=e8f6c7b4b011b565c443b57701000000, repr=<flwr.simulation.ray_transport.ray_actor.ClientAppActor object at 0x0000015A5B8A28E0>)
  File "C:\Users\clara\anaconda3\envs\tf_gpu\lib\site-packages\flwr\client\client_app.py", line 143, in __call__
    return self._call(message, context)
  File "C:\Users\clara\anaconda3\envs\tf_gpu\lib\site-packages\flwr\client\client_app.py", line 126, in ffn
    out_message = handle_legacy_message_from_msgtype(
  File "C:\Users\clara\anaconda3\envs\tf_gpu\lib\site-packages\flwr\client\message_handler\message_handler.py", line 136, in handle_legacy_message_from_msgtype
    evaluate_res = maybe_call_evaluate(
  File "C:\Users\clara\anaconda3\envs\tf_gpu\lib\site-packages\flwr\client\client.py", line 275, in maybe_call_evaluate
    return client.evaluate(evaluate_ins)
  File "C:\Users\clara\anaconda3\envs\tf_gpu\lib\site-packages\flwr\client\numpy_client.py", line 283, in _evaluate
    results = self.numpy_client.evaluate(parameters, ins.config)  # type: ignore
  File "C:\Users\clara\Desktop\TFG\Codigo TFG\3.FederatedTraining\client.py", line 38, in evaluate
    self.model.set_weights(parameters)
  File "C:\Users\clara\anaconda3\envs\tf_gpu\lib\site-packages\keras\src\layers\layer.py", line 696, in set_weights
    raise ValueError(
ValueError: You called `set_weights(weights)` on layer 'sequential_6' with a weight list of length 0, but the layer was expecting 8 weights.

The above exception was the direct cause of the following exception:

[36mray::ClientAppActor.run()[39m (pid=20408, ip=127.0.0.1, actor_id=e8f6c7b4b011b565c443b57701000000, repr=<flwr.simulation.ray_transport.ray_actor.ClientAppActor object at 0x0000015A5B8A28E0>)
  File "python\ray\_raylet.pyx", line 1856, in ray._raylet.execute_task
  File "python\ray\_raylet.pyx", line 1957, in ray._raylet.execute_task
  File "python\ray\_raylet.pyx", line 1862, in ray._raylet.execute_task
  File "python\ray\_raylet.pyx", line 1803, in ray._raylet.execute_task.function_executor
  File "C:\Users\clara\anaconda3\envs\tf_gpu\lib\site-packages\ray\_private\function_manager.py", line 696, in actor_method_executor
    return method(__ray_actor, *args, **kwargs)
  File "C:\Users\clara\anaconda3\envs\tf_gpu\lib\site-packages\ray\util\tracing\tracing_helper.py", line 467, in _resume_span
    return method(self, *_args, **_kwargs)
  File "C:\Users\clara\anaconda3\envs\tf_gpu\lib\site-packages\flwr\simulation\ray_transport\ray_actor.py", line 63, in run
    raise ClientAppException(str(ex)) from ex
flwr.client.client_app.ClientAppException: 
Exception ClientAppException occurred. Message: You called `set_weights(weights)` on layer 'sequential_6' with a weight list of length 0, but the layer was expecting 8 weights.

[2024-12-03 16:27:33,578][flwr][ERROR] - [36mray::ClientAppActor.run()[39m (pid=20408, ip=127.0.0.1, actor_id=e8f6c7b4b011b565c443b57701000000, repr=<flwr.simulation.ray_transport.ray_actor.ClientAppActor object at 0x0000015A5B8A28E0>)
  File "C:\Users\clara\anaconda3\envs\tf_gpu\lib\site-packages\flwr\client\client_app.py", line 143, in __call__
    return self._call(message, context)
  File "C:\Users\clara\anaconda3\envs\tf_gpu\lib\site-packages\flwr\client\client_app.py", line 126, in ffn
    out_message = handle_legacy_message_from_msgtype(
  File "C:\Users\clara\anaconda3\envs\tf_gpu\lib\site-packages\flwr\client\message_handler\message_handler.py", line 136, in handle_legacy_message_from_msgtype
    evaluate_res = maybe_call_evaluate(
  File "C:\Users\clara\anaconda3\envs\tf_gpu\lib\site-packages\flwr\client\client.py", line 275, in maybe_call_evaluate
    return client.evaluate(evaluate_ins)
  File "C:\Users\clara\anaconda3\envs\tf_gpu\lib\site-packages\flwr\client\numpy_client.py", line 283, in _evaluate
    results = self.numpy_client.evaluate(parameters, ins.config)  # type: ignore
  File "C:\Users\clara\Desktop\TFG\Codigo TFG\3.FederatedTraining\client.py", line 38, in evaluate
    self.model.set_weights(parameters)
  File "C:\Users\clara\anaconda3\envs\tf_gpu\lib\site-packages\keras\src\layers\layer.py", line 696, in set_weights
    raise ValueError(
ValueError: You called `set_weights(weights)` on layer 'sequential_6' with a weight list of length 0, but the layer was expecting 8 weights.

The above exception was the direct cause of the following exception:

[36mray::ClientAppActor.run()[39m (pid=20408, ip=127.0.0.1, actor_id=e8f6c7b4b011b565c443b57701000000, repr=<flwr.simulation.ray_transport.ray_actor.ClientAppActor object at 0x0000015A5B8A28E0>)
  File "python\ray\_raylet.pyx", line 1856, in ray._raylet.execute_task
  File "python\ray\_raylet.pyx", line 1957, in ray._raylet.execute_task
  File "python\ray\_raylet.pyx", line 1862, in ray._raylet.execute_task
  File "python\ray\_raylet.pyx", line 1803, in ray._raylet.execute_task.function_executor
  File "C:\Users\clara\anaconda3\envs\tf_gpu\lib\site-packages\ray\_private\function_manager.py", line 696, in actor_method_executor
    return method(__ray_actor, *args, **kwargs)
  File "C:\Users\clara\anaconda3\envs\tf_gpu\lib\site-packages\ray\util\tracing\tracing_helper.py", line 467, in _resume_span
    return method(self, *_args, **_kwargs)
  File "C:\Users\clara\anaconda3\envs\tf_gpu\lib\site-packages\flwr\simulation\ray_transport\ray_actor.py", line 63, in run
    raise ClientAppException(str(ex)) from ex
flwr.client.client_app.ClientAppException: 
Exception ClientAppException occurred. Message: You called `set_weights(weights)` on layer 'sequential_6' with a weight list of length 0, but the layer was expecting 8 weights.
[2024-12-03 16:27:35,118][flwr][ERROR] - Traceback (most recent call last):
  File "C:\Users\clara\anaconda3\envs\tf_gpu\lib\site-packages\flwr\simulation\ray_transport\ray_client_proxy.py", line 94, in _submit_job
    out_mssg, updated_context = self.actor_pool.get_client_result(
  File "C:\Users\clara\anaconda3\envs\tf_gpu\lib\site-packages\flwr\simulation\ray_transport\ray_actor.py", line 398, in get_client_result
    return self._fetch_future_result(cid)
  File "C:\Users\clara\anaconda3\envs\tf_gpu\lib\site-packages\flwr\simulation\ray_transport\ray_actor.py", line 279, in _fetch_future_result
    res_cid, out_mssg, updated_context = ray.get(
  File "C:\Users\clara\anaconda3\envs\tf_gpu\lib\site-packages\ray\_private\auto_init_hook.py", line 21, in auto_init_wrapper
    return fn(*args, **kwargs)
  File "C:\Users\clara\anaconda3\envs\tf_gpu\lib\site-packages\ray\_private\client_mode_hook.py", line 103, in wrapper
    return func(*args, **kwargs)
  File "C:\Users\clara\anaconda3\envs\tf_gpu\lib\site-packages\ray\_private\worker.py", line 2753, in get
    values, debugger_breakpoint = worker.get_objects(object_refs, timeout=timeout)
  File "C:\Users\clara\anaconda3\envs\tf_gpu\lib\site-packages\ray\_private\worker.py", line 904, in get_objects
    raise value.as_instanceof_cause()
ray.exceptions.RayTaskError(ClientAppException): [36mray::ClientAppActor.run()[39m (pid=17372, ip=127.0.0.1, actor_id=38dbbf05716928ec6fb350bf01000000, repr=<flwr.simulation.ray_transport.ray_actor.ClientAppActor object at 0x00000210E74B0A60>)
  File "C:\Users\clara\anaconda3\envs\tf_gpu\lib\site-packages\flwr\client\client_app.py", line 143, in __call__
    return self._call(message, context)
  File "C:\Users\clara\anaconda3\envs\tf_gpu\lib\site-packages\flwr\client\client_app.py", line 126, in ffn
    out_message = handle_legacy_message_from_msgtype(
  File "C:\Users\clara\anaconda3\envs\tf_gpu\lib\site-packages\flwr\client\message_handler\message_handler.py", line 136, in handle_legacy_message_from_msgtype
    evaluate_res = maybe_call_evaluate(
  File "C:\Users\clara\anaconda3\envs\tf_gpu\lib\site-packages\flwr\client\client.py", line 275, in maybe_call_evaluate
    return client.evaluate(evaluate_ins)
  File "C:\Users\clara\anaconda3\envs\tf_gpu\lib\site-packages\flwr\client\numpy_client.py", line 283, in _evaluate
    results = self.numpy_client.evaluate(parameters, ins.config)  # type: ignore
  File "C:\Users\clara\Desktop\TFG\Codigo TFG\3.FederatedTraining\client.py", line 38, in evaluate
    self.model.set_weights(parameters)
  File "C:\Users\clara\anaconda3\envs\tf_gpu\lib\site-packages\keras\src\layers\layer.py", line 696, in set_weights
    raise ValueError(
ValueError: You called `set_weights(weights)` on layer 'sequential_6' with a weight list of length 0, but the layer was expecting 8 weights.

The above exception was the direct cause of the following exception:

[36mray::ClientAppActor.run()[39m (pid=17372, ip=127.0.0.1, actor_id=38dbbf05716928ec6fb350bf01000000, repr=<flwr.simulation.ray_transport.ray_actor.ClientAppActor object at 0x00000210E74B0A60>)
  File "python\ray\_raylet.pyx", line 1856, in ray._raylet.execute_task
  File "python\ray\_raylet.pyx", line 1957, in ray._raylet.execute_task
  File "python\ray\_raylet.pyx", line 1862, in ray._raylet.execute_task
  File "python\ray\_raylet.pyx", line 1803, in ray._raylet.execute_task.function_executor
  File "C:\Users\clara\anaconda3\envs\tf_gpu\lib\site-packages\ray\_private\function_manager.py", line 696, in actor_method_executor
    return method(__ray_actor, *args, **kwargs)
  File "C:\Users\clara\anaconda3\envs\tf_gpu\lib\site-packages\ray\util\tracing\tracing_helper.py", line 467, in _resume_span
    return method(self, *_args, **_kwargs)
  File "C:\Users\clara\anaconda3\envs\tf_gpu\lib\site-packages\flwr\simulation\ray_transport\ray_actor.py", line 63, in run
    raise ClientAppException(str(ex)) from ex
flwr.client.client_app.ClientAppException: 
Exception ClientAppException occurred. Message: You called `set_weights(weights)` on layer 'sequential_6' with a weight list of length 0, but the layer was expecting 8 weights.

[2024-12-03 16:27:35,128][flwr][ERROR] - [36mray::ClientAppActor.run()[39m (pid=17372, ip=127.0.0.1, actor_id=38dbbf05716928ec6fb350bf01000000, repr=<flwr.simulation.ray_transport.ray_actor.ClientAppActor object at 0x00000210E74B0A60>)
  File "C:\Users\clara\anaconda3\envs\tf_gpu\lib\site-packages\flwr\client\client_app.py", line 143, in __call__
    return self._call(message, context)
  File "C:\Users\clara\anaconda3\envs\tf_gpu\lib\site-packages\flwr\client\client_app.py", line 126, in ffn
    out_message = handle_legacy_message_from_msgtype(
  File "C:\Users\clara\anaconda3\envs\tf_gpu\lib\site-packages\flwr\client\message_handler\message_handler.py", line 136, in handle_legacy_message_from_msgtype
    evaluate_res = maybe_call_evaluate(
  File "C:\Users\clara\anaconda3\envs\tf_gpu\lib\site-packages\flwr\client\client.py", line 275, in maybe_call_evaluate
    return client.evaluate(evaluate_ins)
  File "C:\Users\clara\anaconda3\envs\tf_gpu\lib\site-packages\flwr\client\numpy_client.py", line 283, in _evaluate
    results = self.numpy_client.evaluate(parameters, ins.config)  # type: ignore
  File "C:\Users\clara\Desktop\TFG\Codigo TFG\3.FederatedTraining\client.py", line 38, in evaluate
    self.model.set_weights(parameters)
  File "C:\Users\clara\anaconda3\envs\tf_gpu\lib\site-packages\keras\src\layers\layer.py", line 696, in set_weights
    raise ValueError(
ValueError: You called `set_weights(weights)` on layer 'sequential_6' with a weight list of length 0, but the layer was expecting 8 weights.

The above exception was the direct cause of the following exception:

[36mray::ClientAppActor.run()[39m (pid=17372, ip=127.0.0.1, actor_id=38dbbf05716928ec6fb350bf01000000, repr=<flwr.simulation.ray_transport.ray_actor.ClientAppActor object at 0x00000210E74B0A60>)
  File "python\ray\_raylet.pyx", line 1856, in ray._raylet.execute_task
  File "python\ray\_raylet.pyx", line 1957, in ray._raylet.execute_task
  File "python\ray\_raylet.pyx", line 1862, in ray._raylet.execute_task
  File "python\ray\_raylet.pyx", line 1803, in ray._raylet.execute_task.function_executor
  File "C:\Users\clara\anaconda3\envs\tf_gpu\lib\site-packages\ray\_private\function_manager.py", line 696, in actor_method_executor
    return method(__ray_actor, *args, **kwargs)
  File "C:\Users\clara\anaconda3\envs\tf_gpu\lib\site-packages\ray\util\tracing\tracing_helper.py", line 467, in _resume_span
    return method(self, *_args, **_kwargs)
  File "C:\Users\clara\anaconda3\envs\tf_gpu\lib\site-packages\flwr\simulation\ray_transport\ray_actor.py", line 63, in run
    raise ClientAppException(str(ex)) from ex
flwr.client.client_app.ClientAppException: 
Exception ClientAppException occurred. Message: You called `set_weights(weights)` on layer 'sequential_6' with a weight list of length 0, but the layer was expecting 8 weights.
[2024-12-03 16:27:35,708][flwr][ERROR] - Traceback (most recent call last):
  File "C:\Users\clara\anaconda3\envs\tf_gpu\lib\site-packages\flwr\simulation\ray_transport\ray_client_proxy.py", line 94, in _submit_job
    out_mssg, updated_context = self.actor_pool.get_client_result(
  File "C:\Users\clara\anaconda3\envs\tf_gpu\lib\site-packages\flwr\simulation\ray_transport\ray_actor.py", line 398, in get_client_result
    return self._fetch_future_result(cid)
  File "C:\Users\clara\anaconda3\envs\tf_gpu\lib\site-packages\flwr\simulation\ray_transport\ray_actor.py", line 279, in _fetch_future_result
    res_cid, out_mssg, updated_context = ray.get(
  File "C:\Users\clara\anaconda3\envs\tf_gpu\lib\site-packages\ray\_private\auto_init_hook.py", line 21, in auto_init_wrapper
    return fn(*args, **kwargs)
  File "C:\Users\clara\anaconda3\envs\tf_gpu\lib\site-packages\ray\_private\client_mode_hook.py", line 103, in wrapper
    return func(*args, **kwargs)
  File "C:\Users\clara\anaconda3\envs\tf_gpu\lib\site-packages\ray\_private\worker.py", line 2753, in get
    values, debugger_breakpoint = worker.get_objects(object_refs, timeout=timeout)
  File "C:\Users\clara\anaconda3\envs\tf_gpu\lib\site-packages\ray\_private\worker.py", line 904, in get_objects
    raise value.as_instanceof_cause()
ray.exceptions.RayTaskError(ClientAppException): [36mray::ClientAppActor.run()[39m (pid=20408, ip=127.0.0.1, actor_id=e8f6c7b4b011b565c443b57701000000, repr=<flwr.simulation.ray_transport.ray_actor.ClientAppActor object at 0x0000015A5B8A28E0>)
  File "C:\Users\clara\anaconda3\envs\tf_gpu\lib\site-packages\flwr\client\client_app.py", line 143, in __call__
    return self._call(message, context)
  File "C:\Users\clara\anaconda3\envs\tf_gpu\lib\site-packages\flwr\client\client_app.py", line 126, in ffn
    out_message = handle_legacy_message_from_msgtype(
  File "C:\Users\clara\anaconda3\envs\tf_gpu\lib\site-packages\flwr\client\message_handler\message_handler.py", line 136, in handle_legacy_message_from_msgtype
    evaluate_res = maybe_call_evaluate(
  File "C:\Users\clara\anaconda3\envs\tf_gpu\lib\site-packages\flwr\client\client.py", line 275, in maybe_call_evaluate
    return client.evaluate(evaluate_ins)
  File "C:\Users\clara\anaconda3\envs\tf_gpu\lib\site-packages\flwr\client\numpy_client.py", line 283, in _evaluate
    results = self.numpy_client.evaluate(parameters, ins.config)  # type: ignore
  File "C:\Users\clara\Desktop\TFG\Codigo TFG\3.FederatedTraining\client.py", line 38, in evaluate
    self.model.set_weights(parameters)
  File "C:\Users\clara\anaconda3\envs\tf_gpu\lib\site-packages\keras\src\layers\layer.py", line 696, in set_weights
    raise ValueError(
ValueError: You called `set_weights(weights)` on layer 'sequential_7' with a weight list of length 0, but the layer was expecting 8 weights.

The above exception was the direct cause of the following exception:

[36mray::ClientAppActor.run()[39m (pid=20408, ip=127.0.0.1, actor_id=e8f6c7b4b011b565c443b57701000000, repr=<flwr.simulation.ray_transport.ray_actor.ClientAppActor object at 0x0000015A5B8A28E0>)
  File "python\ray\_raylet.pyx", line 1856, in ray._raylet.execute_task
  File "python\ray\_raylet.pyx", line 1957, in ray._raylet.execute_task
  File "python\ray\_raylet.pyx", line 1862, in ray._raylet.execute_task
  File "python\ray\_raylet.pyx", line 1803, in ray._raylet.execute_task.function_executor
  File "C:\Users\clara\anaconda3\envs\tf_gpu\lib\site-packages\ray\_private\function_manager.py", line 696, in actor_method_executor
    return method(__ray_actor, *args, **kwargs)
  File "C:\Users\clara\anaconda3\envs\tf_gpu\lib\site-packages\ray\util\tracing\tracing_helper.py", line 467, in _resume_span
    return method(self, *_args, **_kwargs)
  File "C:\Users\clara\anaconda3\envs\tf_gpu\lib\site-packages\flwr\simulation\ray_transport\ray_actor.py", line 63, in run
    raise ClientAppException(str(ex)) from ex
flwr.client.client_app.ClientAppException: 
Exception ClientAppException occurred. Message: You called `set_weights(weights)` on layer 'sequential_7' with a weight list of length 0, but the layer was expecting 8 weights.

[2024-12-03 16:27:35,721][flwr][ERROR] - [36mray::ClientAppActor.run()[39m (pid=20408, ip=127.0.0.1, actor_id=e8f6c7b4b011b565c443b57701000000, repr=<flwr.simulation.ray_transport.ray_actor.ClientAppActor object at 0x0000015A5B8A28E0>)
  File "C:\Users\clara\anaconda3\envs\tf_gpu\lib\site-packages\flwr\client\client_app.py", line 143, in __call__
    return self._call(message, context)
  File "C:\Users\clara\anaconda3\envs\tf_gpu\lib\site-packages\flwr\client\client_app.py", line 126, in ffn
    out_message = handle_legacy_message_from_msgtype(
  File "C:\Users\clara\anaconda3\envs\tf_gpu\lib\site-packages\flwr\client\message_handler\message_handler.py", line 136, in handle_legacy_message_from_msgtype
    evaluate_res = maybe_call_evaluate(
  File "C:\Users\clara\anaconda3\envs\tf_gpu\lib\site-packages\flwr\client\client.py", line 275, in maybe_call_evaluate
    return client.evaluate(evaluate_ins)
  File "C:\Users\clara\anaconda3\envs\tf_gpu\lib\site-packages\flwr\client\numpy_client.py", line 283, in _evaluate
    results = self.numpy_client.evaluate(parameters, ins.config)  # type: ignore
  File "C:\Users\clara\Desktop\TFG\Codigo TFG\3.FederatedTraining\client.py", line 38, in evaluate
    self.model.set_weights(parameters)
  File "C:\Users\clara\anaconda3\envs\tf_gpu\lib\site-packages\keras\src\layers\layer.py", line 696, in set_weights
    raise ValueError(
ValueError: You called `set_weights(weights)` on layer 'sequential_7' with a weight list of length 0, but the layer was expecting 8 weights.

The above exception was the direct cause of the following exception:

[36mray::ClientAppActor.run()[39m (pid=20408, ip=127.0.0.1, actor_id=e8f6c7b4b011b565c443b57701000000, repr=<flwr.simulation.ray_transport.ray_actor.ClientAppActor object at 0x0000015A5B8A28E0>)
  File "python\ray\_raylet.pyx", line 1856, in ray._raylet.execute_task
  File "python\ray\_raylet.pyx", line 1957, in ray._raylet.execute_task
  File "python\ray\_raylet.pyx", line 1862, in ray._raylet.execute_task
  File "python\ray\_raylet.pyx", line 1803, in ray._raylet.execute_task.function_executor
  File "C:\Users\clara\anaconda3\envs\tf_gpu\lib\site-packages\ray\_private\function_manager.py", line 696, in actor_method_executor
    return method(__ray_actor, *args, **kwargs)
  File "C:\Users\clara\anaconda3\envs\tf_gpu\lib\site-packages\ray\util\tracing\tracing_helper.py", line 467, in _resume_span
    return method(self, *_args, **_kwargs)
  File "C:\Users\clara\anaconda3\envs\tf_gpu\lib\site-packages\flwr\simulation\ray_transport\ray_actor.py", line 63, in run
    raise ClientAppException(str(ex)) from ex
flwr.client.client_app.ClientAppException: 
Exception ClientAppException occurred. Message: You called `set_weights(weights)` on layer 'sequential_7' with a weight list of length 0, but the layer was expecting 8 weights.
[2024-12-03 16:27:38,579][flwr][ERROR] - Traceback (most recent call last):
  File "C:\Users\clara\anaconda3\envs\tf_gpu\lib\site-packages\flwr\simulation\ray_transport\ray_client_proxy.py", line 94, in _submit_job
    out_mssg, updated_context = self.actor_pool.get_client_result(
  File "C:\Users\clara\anaconda3\envs\tf_gpu\lib\site-packages\flwr\simulation\ray_transport\ray_actor.py", line 398, in get_client_result
    return self._fetch_future_result(cid)
  File "C:\Users\clara\anaconda3\envs\tf_gpu\lib\site-packages\flwr\simulation\ray_transport\ray_actor.py", line 279, in _fetch_future_result
    res_cid, out_mssg, updated_context = ray.get(
  File "C:\Users\clara\anaconda3\envs\tf_gpu\lib\site-packages\ray\_private\auto_init_hook.py", line 21, in auto_init_wrapper
    return fn(*args, **kwargs)
  File "C:\Users\clara\anaconda3\envs\tf_gpu\lib\site-packages\ray\_private\client_mode_hook.py", line 103, in wrapper
    return func(*args, **kwargs)
  File "C:\Users\clara\anaconda3\envs\tf_gpu\lib\site-packages\ray\_private\worker.py", line 2753, in get
    values, debugger_breakpoint = worker.get_objects(object_refs, timeout=timeout)
  File "C:\Users\clara\anaconda3\envs\tf_gpu\lib\site-packages\ray\_private\worker.py", line 904, in get_objects
    raise value.as_instanceof_cause()
ray.exceptions.RayTaskError(ClientAppException): [36mray::ClientAppActor.run()[39m (pid=17372, ip=127.0.0.1, actor_id=38dbbf05716928ec6fb350bf01000000, repr=<flwr.simulation.ray_transport.ray_actor.ClientAppActor object at 0x00000210E74B0A60>)
  File "C:\Users\clara\anaconda3\envs\tf_gpu\lib\site-packages\flwr\client\client_app.py", line 143, in __call__
    return self._call(message, context)
  File "C:\Users\clara\anaconda3\envs\tf_gpu\lib\site-packages\flwr\client\client_app.py", line 126, in ffn
    out_message = handle_legacy_message_from_msgtype(
  File "C:\Users\clara\anaconda3\envs\tf_gpu\lib\site-packages\flwr\client\message_handler\message_handler.py", line 136, in handle_legacy_message_from_msgtype
    evaluate_res = maybe_call_evaluate(
  File "C:\Users\clara\anaconda3\envs\tf_gpu\lib\site-packages\flwr\client\client.py", line 275, in maybe_call_evaluate
    return client.evaluate(evaluate_ins)
  File "C:\Users\clara\anaconda3\envs\tf_gpu\lib\site-packages\flwr\client\numpy_client.py", line 283, in _evaluate
    results = self.numpy_client.evaluate(parameters, ins.config)  # type: ignore
  File "C:\Users\clara\Desktop\TFG\Codigo TFG\3.FederatedTraining\client.py", line 38, in evaluate
    self.model.set_weights(parameters)
  File "C:\Users\clara\anaconda3\envs\tf_gpu\lib\site-packages\keras\src\layers\layer.py", line 696, in set_weights
    raise ValueError(
ValueError: You called `set_weights(weights)` on layer 'sequential_7' with a weight list of length 0, but the layer was expecting 8 weights.

The above exception was the direct cause of the following exception:

[36mray::ClientAppActor.run()[39m (pid=17372, ip=127.0.0.1, actor_id=38dbbf05716928ec6fb350bf01000000, repr=<flwr.simulation.ray_transport.ray_actor.ClientAppActor object at 0x00000210E74B0A60>)
  File "python\ray\_raylet.pyx", line 1856, in ray._raylet.execute_task
  File "python\ray\_raylet.pyx", line 1957, in ray._raylet.execute_task
  File "python\ray\_raylet.pyx", line 1862, in ray._raylet.execute_task
  File "python\ray\_raylet.pyx", line 1803, in ray._raylet.execute_task.function_executor
  File "C:\Users\clara\anaconda3\envs\tf_gpu\lib\site-packages\ray\_private\function_manager.py", line 696, in actor_method_executor
    return method(__ray_actor, *args, **kwargs)
  File "C:\Users\clara\anaconda3\envs\tf_gpu\lib\site-packages\ray\util\tracing\tracing_helper.py", line 467, in _resume_span
    return method(self, *_args, **_kwargs)
  File "C:\Users\clara\anaconda3\envs\tf_gpu\lib\site-packages\flwr\simulation\ray_transport\ray_actor.py", line 63, in run
    raise ClientAppException(str(ex)) from ex
flwr.client.client_app.ClientAppException: 
Exception ClientAppException occurred. Message: You called `set_weights(weights)` on layer 'sequential_7' with a weight list of length 0, but the layer was expecting 8 weights.

[2024-12-03 16:27:38,591][flwr][ERROR] - [36mray::ClientAppActor.run()[39m (pid=17372, ip=127.0.0.1, actor_id=38dbbf05716928ec6fb350bf01000000, repr=<flwr.simulation.ray_transport.ray_actor.ClientAppActor object at 0x00000210E74B0A60>)
  File "C:\Users\clara\anaconda3\envs\tf_gpu\lib\site-packages\flwr\client\client_app.py", line 143, in __call__
    return self._call(message, context)
  File "C:\Users\clara\anaconda3\envs\tf_gpu\lib\site-packages\flwr\client\client_app.py", line 126, in ffn
    out_message = handle_legacy_message_from_msgtype(
  File "C:\Users\clara\anaconda3\envs\tf_gpu\lib\site-packages\flwr\client\message_handler\message_handler.py", line 136, in handle_legacy_message_from_msgtype
    evaluate_res = maybe_call_evaluate(
  File "C:\Users\clara\anaconda3\envs\tf_gpu\lib\site-packages\flwr\client\client.py", line 275, in maybe_call_evaluate
    return client.evaluate(evaluate_ins)
  File "C:\Users\clara\anaconda3\envs\tf_gpu\lib\site-packages\flwr\client\numpy_client.py", line 283, in _evaluate
    results = self.numpy_client.evaluate(parameters, ins.config)  # type: ignore
  File "C:\Users\clara\Desktop\TFG\Codigo TFG\3.FederatedTraining\client.py", line 38, in evaluate
    self.model.set_weights(parameters)
  File "C:\Users\clara\anaconda3\envs\tf_gpu\lib\site-packages\keras\src\layers\layer.py", line 696, in set_weights
    raise ValueError(
ValueError: You called `set_weights(weights)` on layer 'sequential_7' with a weight list of length 0, but the layer was expecting 8 weights.

The above exception was the direct cause of the following exception:

[36mray::ClientAppActor.run()[39m (pid=17372, ip=127.0.0.1, actor_id=38dbbf05716928ec6fb350bf01000000, repr=<flwr.simulation.ray_transport.ray_actor.ClientAppActor object at 0x00000210E74B0A60>)
  File "python\ray\_raylet.pyx", line 1856, in ray._raylet.execute_task
  File "python\ray\_raylet.pyx", line 1957, in ray._raylet.execute_task
  File "python\ray\_raylet.pyx", line 1862, in ray._raylet.execute_task
  File "python\ray\_raylet.pyx", line 1803, in ray._raylet.execute_task.function_executor
  File "C:\Users\clara\anaconda3\envs\tf_gpu\lib\site-packages\ray\_private\function_manager.py", line 696, in actor_method_executor
    return method(__ray_actor, *args, **kwargs)
  File "C:\Users\clara\anaconda3\envs\tf_gpu\lib\site-packages\ray\util\tracing\tracing_helper.py", line 467, in _resume_span
    return method(self, *_args, **_kwargs)
  File "C:\Users\clara\anaconda3\envs\tf_gpu\lib\site-packages\flwr\simulation\ray_transport\ray_actor.py", line 63, in run
    raise ClientAppException(str(ex)) from ex
flwr.client.client_app.ClientAppException: 
Exception ClientAppException occurred. Message: You called `set_weights(weights)` on layer 'sequential_7' with a weight list of length 0, but the layer was expecting 8 weights.
[2024-12-03 16:27:40,404][flwr][ERROR] - Traceback (most recent call last):
  File "C:\Users\clara\anaconda3\envs\tf_gpu\lib\site-packages\flwr\simulation\ray_transport\ray_client_proxy.py", line 94, in _submit_job
    out_mssg, updated_context = self.actor_pool.get_client_result(
  File "C:\Users\clara\anaconda3\envs\tf_gpu\lib\site-packages\flwr\simulation\ray_transport\ray_actor.py", line 398, in get_client_result
    return self._fetch_future_result(cid)
  File "C:\Users\clara\anaconda3\envs\tf_gpu\lib\site-packages\flwr\simulation\ray_transport\ray_actor.py", line 279, in _fetch_future_result
    res_cid, out_mssg, updated_context = ray.get(
  File "C:\Users\clara\anaconda3\envs\tf_gpu\lib\site-packages\ray\_private\auto_init_hook.py", line 21, in auto_init_wrapper
    return fn(*args, **kwargs)
  File "C:\Users\clara\anaconda3\envs\tf_gpu\lib\site-packages\ray\_private\client_mode_hook.py", line 103, in wrapper
    return func(*args, **kwargs)
  File "C:\Users\clara\anaconda3\envs\tf_gpu\lib\site-packages\ray\_private\worker.py", line 2753, in get
    values, debugger_breakpoint = worker.get_objects(object_refs, timeout=timeout)
  File "C:\Users\clara\anaconda3\envs\tf_gpu\lib\site-packages\ray\_private\worker.py", line 904, in get_objects
    raise value.as_instanceof_cause()
ray.exceptions.RayTaskError(ClientAppException): [36mray::ClientAppActor.run()[39m (pid=20408, ip=127.0.0.1, actor_id=e8f6c7b4b011b565c443b57701000000, repr=<flwr.simulation.ray_transport.ray_actor.ClientAppActor object at 0x0000015A5B8A28E0>)
  File "C:\Users\clara\anaconda3\envs\tf_gpu\lib\site-packages\flwr\client\client_app.py", line 143, in __call__
    return self._call(message, context)
  File "C:\Users\clara\anaconda3\envs\tf_gpu\lib\site-packages\flwr\client\client_app.py", line 126, in ffn
    out_message = handle_legacy_message_from_msgtype(
  File "C:\Users\clara\anaconda3\envs\tf_gpu\lib\site-packages\flwr\client\message_handler\message_handler.py", line 136, in handle_legacy_message_from_msgtype
    evaluate_res = maybe_call_evaluate(
  File "C:\Users\clara\anaconda3\envs\tf_gpu\lib\site-packages\flwr\client\client.py", line 275, in maybe_call_evaluate
    return client.evaluate(evaluate_ins)
  File "C:\Users\clara\anaconda3\envs\tf_gpu\lib\site-packages\flwr\client\numpy_client.py", line 283, in _evaluate
    results = self.numpy_client.evaluate(parameters, ins.config)  # type: ignore
  File "C:\Users\clara\Desktop\TFG\Codigo TFG\3.FederatedTraining\client.py", line 38, in evaluate
    self.model.set_weights(parameters)
  File "C:\Users\clara\anaconda3\envs\tf_gpu\lib\site-packages\keras\src\layers\layer.py", line 696, in set_weights
    raise ValueError(
ValueError: You called `set_weights(weights)` on layer 'sequential_8' with a weight list of length 0, but the layer was expecting 8 weights.

The above exception was the direct cause of the following exception:

[36mray::ClientAppActor.run()[39m (pid=20408, ip=127.0.0.1, actor_id=e8f6c7b4b011b565c443b57701000000, repr=<flwr.simulation.ray_transport.ray_actor.ClientAppActor object at 0x0000015A5B8A28E0>)
  File "python\ray\_raylet.pyx", line 1856, in ray._raylet.execute_task
  File "python\ray\_raylet.pyx", line 1957, in ray._raylet.execute_task
  File "python\ray\_raylet.pyx", line 1862, in ray._raylet.execute_task
  File "python\ray\_raylet.pyx", line 1803, in ray._raylet.execute_task.function_executor
  File "C:\Users\clara\anaconda3\envs\tf_gpu\lib\site-packages\ray\_private\function_manager.py", line 696, in actor_method_executor
    return method(__ray_actor, *args, **kwargs)
  File "C:\Users\clara\anaconda3\envs\tf_gpu\lib\site-packages\ray\util\tracing\tracing_helper.py", line 467, in _resume_span
    return method(self, *_args, **_kwargs)
  File "C:\Users\clara\anaconda3\envs\tf_gpu\lib\site-packages\flwr\simulation\ray_transport\ray_actor.py", line 63, in run
    raise ClientAppException(str(ex)) from ex
flwr.client.client_app.ClientAppException: 
Exception ClientAppException occurred. Message: You called `set_weights(weights)` on layer 'sequential_8' with a weight list of length 0, but the layer was expecting 8 weights.

[2024-12-03 16:27:40,416][flwr][ERROR] - [36mray::ClientAppActor.run()[39m (pid=20408, ip=127.0.0.1, actor_id=e8f6c7b4b011b565c443b57701000000, repr=<flwr.simulation.ray_transport.ray_actor.ClientAppActor object at 0x0000015A5B8A28E0>)
  File "C:\Users\clara\anaconda3\envs\tf_gpu\lib\site-packages\flwr\client\client_app.py", line 143, in __call__
    return self._call(message, context)
  File "C:\Users\clara\anaconda3\envs\tf_gpu\lib\site-packages\flwr\client\client_app.py", line 126, in ffn
    out_message = handle_legacy_message_from_msgtype(
  File "C:\Users\clara\anaconda3\envs\tf_gpu\lib\site-packages\flwr\client\message_handler\message_handler.py", line 136, in handle_legacy_message_from_msgtype
    evaluate_res = maybe_call_evaluate(
  File "C:\Users\clara\anaconda3\envs\tf_gpu\lib\site-packages\flwr\client\client.py", line 275, in maybe_call_evaluate
    return client.evaluate(evaluate_ins)
  File "C:\Users\clara\anaconda3\envs\tf_gpu\lib\site-packages\flwr\client\numpy_client.py", line 283, in _evaluate
    results = self.numpy_client.evaluate(parameters, ins.config)  # type: ignore
  File "C:\Users\clara\Desktop\TFG\Codigo TFG\3.FederatedTraining\client.py", line 38, in evaluate
    self.model.set_weights(parameters)
  File "C:\Users\clara\anaconda3\envs\tf_gpu\lib\site-packages\keras\src\layers\layer.py", line 696, in set_weights
    raise ValueError(
ValueError: You called `set_weights(weights)` on layer 'sequential_8' with a weight list of length 0, but the layer was expecting 8 weights.

The above exception was the direct cause of the following exception:

[36mray::ClientAppActor.run()[39m (pid=20408, ip=127.0.0.1, actor_id=e8f6c7b4b011b565c443b57701000000, repr=<flwr.simulation.ray_transport.ray_actor.ClientAppActor object at 0x0000015A5B8A28E0>)
  File "python\ray\_raylet.pyx", line 1856, in ray._raylet.execute_task
  File "python\ray\_raylet.pyx", line 1957, in ray._raylet.execute_task
  File "python\ray\_raylet.pyx", line 1862, in ray._raylet.execute_task
  File "python\ray\_raylet.pyx", line 1803, in ray._raylet.execute_task.function_executor
  File "C:\Users\clara\anaconda3\envs\tf_gpu\lib\site-packages\ray\_private\function_manager.py", line 696, in actor_method_executor
    return method(__ray_actor, *args, **kwargs)
  File "C:\Users\clara\anaconda3\envs\tf_gpu\lib\site-packages\ray\util\tracing\tracing_helper.py", line 467, in _resume_span
    return method(self, *_args, **_kwargs)
  File "C:\Users\clara\anaconda3\envs\tf_gpu\lib\site-packages\flwr\simulation\ray_transport\ray_actor.py", line 63, in run
    raise ClientAppException(str(ex)) from ex
flwr.client.client_app.ClientAppException: 
Exception ClientAppException occurred. Message: You called `set_weights(weights)` on layer 'sequential_8' with a weight list of length 0, but the layer was expecting 8 weights.
[2024-12-03 16:27:40,815][flwr][ERROR] - Traceback (most recent call last):
  File "C:\Users\clara\anaconda3\envs\tf_gpu\lib\site-packages\flwr\simulation\ray_transport\ray_client_proxy.py", line 94, in _submit_job
    out_mssg, updated_context = self.actor_pool.get_client_result(
  File "C:\Users\clara\anaconda3\envs\tf_gpu\lib\site-packages\flwr\simulation\ray_transport\ray_actor.py", line 398, in get_client_result
    return self._fetch_future_result(cid)
  File "C:\Users\clara\anaconda3\envs\tf_gpu\lib\site-packages\flwr\simulation\ray_transport\ray_actor.py", line 279, in _fetch_future_result
    res_cid, out_mssg, updated_context = ray.get(
  File "C:\Users\clara\anaconda3\envs\tf_gpu\lib\site-packages\ray\_private\auto_init_hook.py", line 21, in auto_init_wrapper
    return fn(*args, **kwargs)
  File "C:\Users\clara\anaconda3\envs\tf_gpu\lib\site-packages\ray\_private\client_mode_hook.py", line 103, in wrapper
    return func(*args, **kwargs)
  File "C:\Users\clara\anaconda3\envs\tf_gpu\lib\site-packages\ray\_private\worker.py", line 2753, in get
    values, debugger_breakpoint = worker.get_objects(object_refs, timeout=timeout)
  File "C:\Users\clara\anaconda3\envs\tf_gpu\lib\site-packages\ray\_private\worker.py", line 904, in get_objects
    raise value.as_instanceof_cause()
ray.exceptions.RayTaskError(ClientAppException): [36mray::ClientAppActor.run()[39m (pid=17372, ip=127.0.0.1, actor_id=38dbbf05716928ec6fb350bf01000000, repr=<flwr.simulation.ray_transport.ray_actor.ClientAppActor object at 0x00000210E74B0A60>)
  File "C:\Users\clara\anaconda3\envs\tf_gpu\lib\site-packages\flwr\client\client_app.py", line 143, in __call__
    return self._call(message, context)
  File "C:\Users\clara\anaconda3\envs\tf_gpu\lib\site-packages\flwr\client\client_app.py", line 126, in ffn
    out_message = handle_legacy_message_from_msgtype(
  File "C:\Users\clara\anaconda3\envs\tf_gpu\lib\site-packages\flwr\client\message_handler\message_handler.py", line 136, in handle_legacy_message_from_msgtype
    evaluate_res = maybe_call_evaluate(
  File "C:\Users\clara\anaconda3\envs\tf_gpu\lib\site-packages\flwr\client\client.py", line 275, in maybe_call_evaluate
    return client.evaluate(evaluate_ins)
  File "C:\Users\clara\anaconda3\envs\tf_gpu\lib\site-packages\flwr\client\numpy_client.py", line 283, in _evaluate
    results = self.numpy_client.evaluate(parameters, ins.config)  # type: ignore
  File "C:\Users\clara\Desktop\TFG\Codigo TFG\3.FederatedTraining\client.py", line 38, in evaluate
    self.model.set_weights(parameters)
  File "C:\Users\clara\anaconda3\envs\tf_gpu\lib\site-packages\keras\src\layers\layer.py", line 696, in set_weights
    raise ValueError(
ValueError: You called `set_weights(weights)` on layer 'sequential_8' with a weight list of length 0, but the layer was expecting 8 weights.

The above exception was the direct cause of the following exception:

[36mray::ClientAppActor.run()[39m (pid=17372, ip=127.0.0.1, actor_id=38dbbf05716928ec6fb350bf01000000, repr=<flwr.simulation.ray_transport.ray_actor.ClientAppActor object at 0x00000210E74B0A60>)
  File "python\ray\_raylet.pyx", line 1856, in ray._raylet.execute_task
  File "python\ray\_raylet.pyx", line 1957, in ray._raylet.execute_task
  File "python\ray\_raylet.pyx", line 1862, in ray._raylet.execute_task
  File "python\ray\_raylet.pyx", line 1803, in ray._raylet.execute_task.function_executor
  File "C:\Users\clara\anaconda3\envs\tf_gpu\lib\site-packages\ray\_private\function_manager.py", line 696, in actor_method_executor
    return method(__ray_actor, *args, **kwargs)
  File "C:\Users\clara\anaconda3\envs\tf_gpu\lib\site-packages\ray\util\tracing\tracing_helper.py", line 467, in _resume_span
    return method(self, *_args, **_kwargs)
  File "C:\Users\clara\anaconda3\envs\tf_gpu\lib\site-packages\flwr\simulation\ray_transport\ray_actor.py", line 63, in run
    raise ClientAppException(str(ex)) from ex
flwr.client.client_app.ClientAppException: 
Exception ClientAppException occurred. Message: You called `set_weights(weights)` on layer 'sequential_8' with a weight list of length 0, but the layer was expecting 8 weights.

[2024-12-03 16:27:40,827][flwr][ERROR] - [36mray::ClientAppActor.run()[39m (pid=17372, ip=127.0.0.1, actor_id=38dbbf05716928ec6fb350bf01000000, repr=<flwr.simulation.ray_transport.ray_actor.ClientAppActor object at 0x00000210E74B0A60>)
  File "C:\Users\clara\anaconda3\envs\tf_gpu\lib\site-packages\flwr\client\client_app.py", line 143, in __call__
    return self._call(message, context)
  File "C:\Users\clara\anaconda3\envs\tf_gpu\lib\site-packages\flwr\client\client_app.py", line 126, in ffn
    out_message = handle_legacy_message_from_msgtype(
  File "C:\Users\clara\anaconda3\envs\tf_gpu\lib\site-packages\flwr\client\message_handler\message_handler.py", line 136, in handle_legacy_message_from_msgtype
    evaluate_res = maybe_call_evaluate(
  File "C:\Users\clara\anaconda3\envs\tf_gpu\lib\site-packages\flwr\client\client.py", line 275, in maybe_call_evaluate
    return client.evaluate(evaluate_ins)
  File "C:\Users\clara\anaconda3\envs\tf_gpu\lib\site-packages\flwr\client\numpy_client.py", line 283, in _evaluate
    results = self.numpy_client.evaluate(parameters, ins.config)  # type: ignore
  File "C:\Users\clara\Desktop\TFG\Codigo TFG\3.FederatedTraining\client.py", line 38, in evaluate
    self.model.set_weights(parameters)
  File "C:\Users\clara\anaconda3\envs\tf_gpu\lib\site-packages\keras\src\layers\layer.py", line 696, in set_weights
    raise ValueError(
ValueError: You called `set_weights(weights)` on layer 'sequential_8' with a weight list of length 0, but the layer was expecting 8 weights.

The above exception was the direct cause of the following exception:

[36mray::ClientAppActor.run()[39m (pid=17372, ip=127.0.0.1, actor_id=38dbbf05716928ec6fb350bf01000000, repr=<flwr.simulation.ray_transport.ray_actor.ClientAppActor object at 0x00000210E74B0A60>)
  File "python\ray\_raylet.pyx", line 1856, in ray._raylet.execute_task
  File "python\ray\_raylet.pyx", line 1957, in ray._raylet.execute_task
  File "python\ray\_raylet.pyx", line 1862, in ray._raylet.execute_task
  File "python\ray\_raylet.pyx", line 1803, in ray._raylet.execute_task.function_executor
  File "C:\Users\clara\anaconda3\envs\tf_gpu\lib\site-packages\ray\_private\function_manager.py", line 696, in actor_method_executor
    return method(__ray_actor, *args, **kwargs)
  File "C:\Users\clara\anaconda3\envs\tf_gpu\lib\site-packages\ray\util\tracing\tracing_helper.py", line 467, in _resume_span
    return method(self, *_args, **_kwargs)
  File "C:\Users\clara\anaconda3\envs\tf_gpu\lib\site-packages\flwr\simulation\ray_transport\ray_actor.py", line 63, in run
    raise ClientAppException(str(ex)) from ex
flwr.client.client_app.ClientAppException: 
Exception ClientAppException occurred. Message: You called `set_weights(weights)` on layer 'sequential_8' with a weight list of length 0, but the layer was expecting 8 weights.
[2024-12-03 16:27:43,397][flwr][ERROR] - Traceback (most recent call last):
  File "C:\Users\clara\anaconda3\envs\tf_gpu\lib\site-packages\flwr\simulation\ray_transport\ray_client_proxy.py", line 94, in _submit_job
    out_mssg, updated_context = self.actor_pool.get_client_result(
  File "C:\Users\clara\anaconda3\envs\tf_gpu\lib\site-packages\flwr\simulation\ray_transport\ray_actor.py", line 398, in get_client_result
    return self._fetch_future_result(cid)
  File "C:\Users\clara\anaconda3\envs\tf_gpu\lib\site-packages\flwr\simulation\ray_transport\ray_actor.py", line 279, in _fetch_future_result
    res_cid, out_mssg, updated_context = ray.get(
  File "C:\Users\clara\anaconda3\envs\tf_gpu\lib\site-packages\ray\_private\auto_init_hook.py", line 21, in auto_init_wrapper
    return fn(*args, **kwargs)
  File "C:\Users\clara\anaconda3\envs\tf_gpu\lib\site-packages\ray\_private\client_mode_hook.py", line 103, in wrapper
    return func(*args, **kwargs)
  File "C:\Users\clara\anaconda3\envs\tf_gpu\lib\site-packages\ray\_private\worker.py", line 2753, in get
    values, debugger_breakpoint = worker.get_objects(object_refs, timeout=timeout)
  File "C:\Users\clara\anaconda3\envs\tf_gpu\lib\site-packages\ray\_private\worker.py", line 904, in get_objects
    raise value.as_instanceof_cause()
ray.exceptions.RayTaskError(ClientAppException): [36mray::ClientAppActor.run()[39m (pid=20408, ip=127.0.0.1, actor_id=e8f6c7b4b011b565c443b57701000000, repr=<flwr.simulation.ray_transport.ray_actor.ClientAppActor object at 0x0000015A5B8A28E0>)
  File "C:\Users\clara\anaconda3\envs\tf_gpu\lib\site-packages\flwr\client\client_app.py", line 143, in __call__
    return self._call(message, context)
  File "C:\Users\clara\anaconda3\envs\tf_gpu\lib\site-packages\flwr\client\client_app.py", line 126, in ffn
    out_message = handle_legacy_message_from_msgtype(
  File "C:\Users\clara\anaconda3\envs\tf_gpu\lib\site-packages\flwr\client\message_handler\message_handler.py", line 136, in handle_legacy_message_from_msgtype
    evaluate_res = maybe_call_evaluate(
  File "C:\Users\clara\anaconda3\envs\tf_gpu\lib\site-packages\flwr\client\client.py", line 275, in maybe_call_evaluate
    return client.evaluate(evaluate_ins)
  File "C:\Users\clara\anaconda3\envs\tf_gpu\lib\site-packages\flwr\client\numpy_client.py", line 283, in _evaluate
    results = self.numpy_client.evaluate(parameters, ins.config)  # type: ignore
  File "C:\Users\clara\Desktop\TFG\Codigo TFG\3.FederatedTraining\client.py", line 38, in evaluate
    self.model.set_weights(parameters)
  File "C:\Users\clara\anaconda3\envs\tf_gpu\lib\site-packages\keras\src\layers\layer.py", line 696, in set_weights
    raise ValueError(
ValueError: You called `set_weights(weights)` on layer 'sequential_9' with a weight list of length 0, but the layer was expecting 8 weights.

The above exception was the direct cause of the following exception:

[36mray::ClientAppActor.run()[39m (pid=20408, ip=127.0.0.1, actor_id=e8f6c7b4b011b565c443b57701000000, repr=<flwr.simulation.ray_transport.ray_actor.ClientAppActor object at 0x0000015A5B8A28E0>)
  File "python\ray\_raylet.pyx", line 1856, in ray._raylet.execute_task
  File "python\ray\_raylet.pyx", line 1957, in ray._raylet.execute_task
  File "python\ray\_raylet.pyx", line 1862, in ray._raylet.execute_task
  File "python\ray\_raylet.pyx", line 1803, in ray._raylet.execute_task.function_executor
  File "C:\Users\clara\anaconda3\envs\tf_gpu\lib\site-packages\ray\_private\function_manager.py", line 696, in actor_method_executor
    return method(__ray_actor, *args, **kwargs)
  File "C:\Users\clara\anaconda3\envs\tf_gpu\lib\site-packages\ray\util\tracing\tracing_helper.py", line 467, in _resume_span
    return method(self, *_args, **_kwargs)
  File "C:\Users\clara\anaconda3\envs\tf_gpu\lib\site-packages\flwr\simulation\ray_transport\ray_actor.py", line 63, in run
    raise ClientAppException(str(ex)) from ex
flwr.client.client_app.ClientAppException: 
Exception ClientAppException occurred. Message: You called `set_weights(weights)` on layer 'sequential_9' with a weight list of length 0, but the layer was expecting 8 weights.

[2024-12-03 16:27:43,405][flwr][ERROR] - [36mray::ClientAppActor.run()[39m (pid=20408, ip=127.0.0.1, actor_id=e8f6c7b4b011b565c443b57701000000, repr=<flwr.simulation.ray_transport.ray_actor.ClientAppActor object at 0x0000015A5B8A28E0>)
  File "C:\Users\clara\anaconda3\envs\tf_gpu\lib\site-packages\flwr\client\client_app.py", line 143, in __call__
    return self._call(message, context)
  File "C:\Users\clara\anaconda3\envs\tf_gpu\lib\site-packages\flwr\client\client_app.py", line 126, in ffn
    out_message = handle_legacy_message_from_msgtype(
  File "C:\Users\clara\anaconda3\envs\tf_gpu\lib\site-packages\flwr\client\message_handler\message_handler.py", line 136, in handle_legacy_message_from_msgtype
    evaluate_res = maybe_call_evaluate(
  File "C:\Users\clara\anaconda3\envs\tf_gpu\lib\site-packages\flwr\client\client.py", line 275, in maybe_call_evaluate
    return client.evaluate(evaluate_ins)
  File "C:\Users\clara\anaconda3\envs\tf_gpu\lib\site-packages\flwr\client\numpy_client.py", line 283, in _evaluate
    results = self.numpy_client.evaluate(parameters, ins.config)  # type: ignore
  File "C:\Users\clara\Desktop\TFG\Codigo TFG\3.FederatedTraining\client.py", line 38, in evaluate
    self.model.set_weights(parameters)
  File "C:\Users\clara\anaconda3\envs\tf_gpu\lib\site-packages\keras\src\layers\layer.py", line 696, in set_weights
    raise ValueError(
ValueError: You called `set_weights(weights)` on layer 'sequential_9' with a weight list of length 0, but the layer was expecting 8 weights.

The above exception was the direct cause of the following exception:

[36mray::ClientAppActor.run()[39m (pid=20408, ip=127.0.0.1, actor_id=e8f6c7b4b011b565c443b57701000000, repr=<flwr.simulation.ray_transport.ray_actor.ClientAppActor object at 0x0000015A5B8A28E0>)
  File "python\ray\_raylet.pyx", line 1856, in ray._raylet.execute_task
  File "python\ray\_raylet.pyx", line 1957, in ray._raylet.execute_task
  File "python\ray\_raylet.pyx", line 1862, in ray._raylet.execute_task
  File "python\ray\_raylet.pyx", line 1803, in ray._raylet.execute_task.function_executor
  File "C:\Users\clara\anaconda3\envs\tf_gpu\lib\site-packages\ray\_private\function_manager.py", line 696, in actor_method_executor
    return method(__ray_actor, *args, **kwargs)
  File "C:\Users\clara\anaconda3\envs\tf_gpu\lib\site-packages\ray\util\tracing\tracing_helper.py", line 467, in _resume_span
    return method(self, *_args, **_kwargs)
  File "C:\Users\clara\anaconda3\envs\tf_gpu\lib\site-packages\flwr\simulation\ray_transport\ray_actor.py", line 63, in run
    raise ClientAppException(str(ex)) from ex
flwr.client.client_app.ClientAppException: 
Exception ClientAppException occurred. Message: You called `set_weights(weights)` on layer 'sequential_9' with a weight list of length 0, but the layer was expecting 8 weights.
[2024-12-03 16:27:43,410][flwr][INFO] - aggregate_evaluate: received 0 results and 10 failures
[2024-12-03 16:27:43,411][flwr][INFO] - 
[2024-12-03 16:27:43,411][flwr][INFO] - [ROUND 2]
[2024-12-03 16:27:43,412][flwr][INFO] - configure_fit: strategy sampled 8 clients (out of 12)
[2024-12-03 16:27:45,566][flwr][ERROR] - Traceback (most recent call last):
  File "C:\Users\clara\anaconda3\envs\tf_gpu\lib\site-packages\flwr\simulation\ray_transport\ray_client_proxy.py", line 94, in _submit_job
    out_mssg, updated_context = self.actor_pool.get_client_result(
  File "C:\Users\clara\anaconda3\envs\tf_gpu\lib\site-packages\flwr\simulation\ray_transport\ray_actor.py", line 398, in get_client_result
    return self._fetch_future_result(cid)
  File "C:\Users\clara\anaconda3\envs\tf_gpu\lib\site-packages\flwr\simulation\ray_transport\ray_actor.py", line 279, in _fetch_future_result
    res_cid, out_mssg, updated_context = ray.get(
  File "C:\Users\clara\anaconda3\envs\tf_gpu\lib\site-packages\ray\_private\auto_init_hook.py", line 21, in auto_init_wrapper
    return fn(*args, **kwargs)
  File "C:\Users\clara\anaconda3\envs\tf_gpu\lib\site-packages\ray\_private\client_mode_hook.py", line 103, in wrapper
    return func(*args, **kwargs)
  File "C:\Users\clara\anaconda3\envs\tf_gpu\lib\site-packages\ray\_private\worker.py", line 2753, in get
    values, debugger_breakpoint = worker.get_objects(object_refs, timeout=timeout)
  File "C:\Users\clara\anaconda3\envs\tf_gpu\lib\site-packages\ray\_private\worker.py", line 904, in get_objects
    raise value.as_instanceof_cause()
ray.exceptions.RayTaskError(ClientAppException): [36mray::ClientAppActor.run()[39m (pid=20408, ip=127.0.0.1, actor_id=e8f6c7b4b011b565c443b57701000000, repr=<flwr.simulation.ray_transport.ray_actor.ClientAppActor object at 0x0000015A5B8A28E0>)
  File "C:\Users\clara\anaconda3\envs\tf_gpu\lib\site-packages\flwr\client\client_app.py", line 143, in __call__
    return self._call(message, context)
  File "C:\Users\clara\anaconda3\envs\tf_gpu\lib\site-packages\flwr\client\client_app.py", line 126, in ffn
    out_message = handle_legacy_message_from_msgtype(
  File "C:\Users\clara\anaconda3\envs\tf_gpu\lib\site-packages\flwr\client\message_handler\message_handler.py", line 129, in handle_legacy_message_from_msgtype
    fit_res = maybe_call_fit(
  File "C:\Users\clara\anaconda3\envs\tf_gpu\lib\site-packages\flwr\client\client.py", line 255, in maybe_call_fit
    return client.fit(fit_ins)
  File "C:\Users\clara\anaconda3\envs\tf_gpu\lib\site-packages\flwr\client\numpy_client.py", line 259, in _fit
    results = self.numpy_client.fit(parameters, ins.config)  # type: ignore
  File "C:\Users\clara\Desktop\TFG\Codigo TFG\3.FederatedTraining\client.py", line 27, in fit
    self.model.set_weights(parameters)
  File "C:\Users\clara\anaconda3\envs\tf_gpu\lib\site-packages\keras\src\layers\layer.py", line 696, in set_weights
    raise ValueError(
ValueError: You called `set_weights(weights)` on layer 'sequential_10' with a weight list of length 0, but the layer was expecting 8 weights.

The above exception was the direct cause of the following exception:

[36mray::ClientAppActor.run()[39m (pid=20408, ip=127.0.0.1, actor_id=e8f6c7b4b011b565c443b57701000000, repr=<flwr.simulation.ray_transport.ray_actor.ClientAppActor object at 0x0000015A5B8A28E0>)
  File "python\ray\_raylet.pyx", line 1856, in ray._raylet.execute_task
  File "python\ray\_raylet.pyx", line 1957, in ray._raylet.execute_task
  File "python\ray\_raylet.pyx", line 1862, in ray._raylet.execute_task
  File "python\ray\_raylet.pyx", line 1803, in ray._raylet.execute_task.function_executor
  File "C:\Users\clara\anaconda3\envs\tf_gpu\lib\site-packages\ray\_private\function_manager.py", line 696, in actor_method_executor
    return method(__ray_actor, *args, **kwargs)
  File "C:\Users\clara\anaconda3\envs\tf_gpu\lib\site-packages\ray\util\tracing\tracing_helper.py", line 467, in _resume_span
    return method(self, *_args, **_kwargs)
  File "C:\Users\clara\anaconda3\envs\tf_gpu\lib\site-packages\flwr\simulation\ray_transport\ray_actor.py", line 63, in run
    raise ClientAppException(str(ex)) from ex
flwr.client.client_app.ClientAppException: 
Exception ClientAppException occurred. Message: You called `set_weights(weights)` on layer 'sequential_10' with a weight list of length 0, but the layer was expecting 8 weights.

[2024-12-03 16:27:45,577][flwr][ERROR] - [36mray::ClientAppActor.run()[39m (pid=20408, ip=127.0.0.1, actor_id=e8f6c7b4b011b565c443b57701000000, repr=<flwr.simulation.ray_transport.ray_actor.ClientAppActor object at 0x0000015A5B8A28E0>)
  File "C:\Users\clara\anaconda3\envs\tf_gpu\lib\site-packages\flwr\client\client_app.py", line 143, in __call__
    return self._call(message, context)
  File "C:\Users\clara\anaconda3\envs\tf_gpu\lib\site-packages\flwr\client\client_app.py", line 126, in ffn
    out_message = handle_legacy_message_from_msgtype(
  File "C:\Users\clara\anaconda3\envs\tf_gpu\lib\site-packages\flwr\client\message_handler\message_handler.py", line 129, in handle_legacy_message_from_msgtype
    fit_res = maybe_call_fit(
  File "C:\Users\clara\anaconda3\envs\tf_gpu\lib\site-packages\flwr\client\client.py", line 255, in maybe_call_fit
    return client.fit(fit_ins)
  File "C:\Users\clara\anaconda3\envs\tf_gpu\lib\site-packages\flwr\client\numpy_client.py", line 259, in _fit
    results = self.numpy_client.fit(parameters, ins.config)  # type: ignore
  File "C:\Users\clara\Desktop\TFG\Codigo TFG\3.FederatedTraining\client.py", line 27, in fit
    self.model.set_weights(parameters)
  File "C:\Users\clara\anaconda3\envs\tf_gpu\lib\site-packages\keras\src\layers\layer.py", line 696, in set_weights
    raise ValueError(
ValueError: You called `set_weights(weights)` on layer 'sequential_10' with a weight list of length 0, but the layer was expecting 8 weights.

The above exception was the direct cause of the following exception:

[36mray::ClientAppActor.run()[39m (pid=20408, ip=127.0.0.1, actor_id=e8f6c7b4b011b565c443b57701000000, repr=<flwr.simulation.ray_transport.ray_actor.ClientAppActor object at 0x0000015A5B8A28E0>)
  File "python\ray\_raylet.pyx", line 1856, in ray._raylet.execute_task
  File "python\ray\_raylet.pyx", line 1957, in ray._raylet.execute_task
  File "python\ray\_raylet.pyx", line 1862, in ray._raylet.execute_task
  File "python\ray\_raylet.pyx", line 1803, in ray._raylet.execute_task.function_executor
  File "C:\Users\clara\anaconda3\envs\tf_gpu\lib\site-packages\ray\_private\function_manager.py", line 696, in actor_method_executor
    return method(__ray_actor, *args, **kwargs)
  File "C:\Users\clara\anaconda3\envs\tf_gpu\lib\site-packages\ray\util\tracing\tracing_helper.py", line 467, in _resume_span
    return method(self, *_args, **_kwargs)
  File "C:\Users\clara\anaconda3\envs\tf_gpu\lib\site-packages\flwr\simulation\ray_transport\ray_actor.py", line 63, in run
    raise ClientAppException(str(ex)) from ex
flwr.client.client_app.ClientAppException: 
Exception ClientAppException occurred. Message: You called `set_weights(weights)` on layer 'sequential_10' with a weight list of length 0, but the layer was expecting 8 weights.
[2024-12-03 16:27:46,708][flwr][ERROR] - Traceback (most recent call last):
  File "C:\Users\clara\anaconda3\envs\tf_gpu\lib\site-packages\flwr\simulation\ray_transport\ray_client_proxy.py", line 94, in _submit_job
    out_mssg, updated_context = self.actor_pool.get_client_result(
  File "C:\Users\clara\anaconda3\envs\tf_gpu\lib\site-packages\flwr\simulation\ray_transport\ray_actor.py", line 398, in get_client_result
    return self._fetch_future_result(cid)
  File "C:\Users\clara\anaconda3\envs\tf_gpu\lib\site-packages\flwr\simulation\ray_transport\ray_actor.py", line 279, in _fetch_future_result
    res_cid, out_mssg, updated_context = ray.get(
  File "C:\Users\clara\anaconda3\envs\tf_gpu\lib\site-packages\ray\_private\auto_init_hook.py", line 21, in auto_init_wrapper
    return fn(*args, **kwargs)
  File "C:\Users\clara\anaconda3\envs\tf_gpu\lib\site-packages\ray\_private\client_mode_hook.py", line 103, in wrapper
    return func(*args, **kwargs)
  File "C:\Users\clara\anaconda3\envs\tf_gpu\lib\site-packages\ray\_private\worker.py", line 2753, in get
    values, debugger_breakpoint = worker.get_objects(object_refs, timeout=timeout)
  File "C:\Users\clara\anaconda3\envs\tf_gpu\lib\site-packages\ray\_private\worker.py", line 904, in get_objects
    raise value.as_instanceof_cause()
ray.exceptions.RayTaskError(ClientAppException): [36mray::ClientAppActor.run()[39m (pid=17372, ip=127.0.0.1, actor_id=38dbbf05716928ec6fb350bf01000000, repr=<flwr.simulation.ray_transport.ray_actor.ClientAppActor object at 0x00000210E74B0A60>)
  File "C:\Users\clara\anaconda3\envs\tf_gpu\lib\site-packages\flwr\client\client_app.py", line 143, in __call__
    return self._call(message, context)
  File "C:\Users\clara\anaconda3\envs\tf_gpu\lib\site-packages\flwr\client\client_app.py", line 126, in ffn
    out_message = handle_legacy_message_from_msgtype(
  File "C:\Users\clara\anaconda3\envs\tf_gpu\lib\site-packages\flwr\client\message_handler\message_handler.py", line 129, in handle_legacy_message_from_msgtype
    fit_res = maybe_call_fit(
  File "C:\Users\clara\anaconda3\envs\tf_gpu\lib\site-packages\flwr\client\client.py", line 255, in maybe_call_fit
    return client.fit(fit_ins)
  File "C:\Users\clara\anaconda3\envs\tf_gpu\lib\site-packages\flwr\client\numpy_client.py", line 259, in _fit
    results = self.numpy_client.fit(parameters, ins.config)  # type: ignore
  File "C:\Users\clara\Desktop\TFG\Codigo TFG\3.FederatedTraining\client.py", line 27, in fit
    self.model.set_weights(parameters)
  File "C:\Users\clara\anaconda3\envs\tf_gpu\lib\site-packages\keras\src\layers\layer.py", line 696, in set_weights
    raise ValueError(
ValueError: You called `set_weights(weights)` on layer 'sequential_9' with a weight list of length 0, but the layer was expecting 8 weights.

The above exception was the direct cause of the following exception:

[36mray::ClientAppActor.run()[39m (pid=17372, ip=127.0.0.1, actor_id=38dbbf05716928ec6fb350bf01000000, repr=<flwr.simulation.ray_transport.ray_actor.ClientAppActor object at 0x00000210E74B0A60>)
  File "python\ray\_raylet.pyx", line 1856, in ray._raylet.execute_task
  File "python\ray\_raylet.pyx", line 1957, in ray._raylet.execute_task
  File "python\ray\_raylet.pyx", line 1862, in ray._raylet.execute_task
  File "python\ray\_raylet.pyx", line 1803, in ray._raylet.execute_task.function_executor
  File "C:\Users\clara\anaconda3\envs\tf_gpu\lib\site-packages\ray\_private\function_manager.py", line 696, in actor_method_executor
    return method(__ray_actor, *args, **kwargs)
  File "C:\Users\clara\anaconda3\envs\tf_gpu\lib\site-packages\ray\util\tracing\tracing_helper.py", line 467, in _resume_span
    return method(self, *_args, **_kwargs)
  File "C:\Users\clara\anaconda3\envs\tf_gpu\lib\site-packages\flwr\simulation\ray_transport\ray_actor.py", line 63, in run
    raise ClientAppException(str(ex)) from ex
flwr.client.client_app.ClientAppException: 
Exception ClientAppException occurred. Message: You called `set_weights(weights)` on layer 'sequential_9' with a weight list of length 0, but the layer was expecting 8 weights.

[2024-12-03 16:27:46,719][flwr][ERROR] - [36mray::ClientAppActor.run()[39m (pid=17372, ip=127.0.0.1, actor_id=38dbbf05716928ec6fb350bf01000000, repr=<flwr.simulation.ray_transport.ray_actor.ClientAppActor object at 0x00000210E74B0A60>)
  File "C:\Users\clara\anaconda3\envs\tf_gpu\lib\site-packages\flwr\client\client_app.py", line 143, in __call__
    return self._call(message, context)
  File "C:\Users\clara\anaconda3\envs\tf_gpu\lib\site-packages\flwr\client\client_app.py", line 126, in ffn
    out_message = handle_legacy_message_from_msgtype(
  File "C:\Users\clara\anaconda3\envs\tf_gpu\lib\site-packages\flwr\client\message_handler\message_handler.py", line 129, in handle_legacy_message_from_msgtype
    fit_res = maybe_call_fit(
  File "C:\Users\clara\anaconda3\envs\tf_gpu\lib\site-packages\flwr\client\client.py", line 255, in maybe_call_fit
    return client.fit(fit_ins)
  File "C:\Users\clara\anaconda3\envs\tf_gpu\lib\site-packages\flwr\client\numpy_client.py", line 259, in _fit
    results = self.numpy_client.fit(parameters, ins.config)  # type: ignore
  File "C:\Users\clara\Desktop\TFG\Codigo TFG\3.FederatedTraining\client.py", line 27, in fit
    self.model.set_weights(parameters)
  File "C:\Users\clara\anaconda3\envs\tf_gpu\lib\site-packages\keras\src\layers\layer.py", line 696, in set_weights
    raise ValueError(
ValueError: You called `set_weights(weights)` on layer 'sequential_9' with a weight list of length 0, but the layer was expecting 8 weights.

The above exception was the direct cause of the following exception:

[36mray::ClientAppActor.run()[39m (pid=17372, ip=127.0.0.1, actor_id=38dbbf05716928ec6fb350bf01000000, repr=<flwr.simulation.ray_transport.ray_actor.ClientAppActor object at 0x00000210E74B0A60>)
  File "python\ray\_raylet.pyx", line 1856, in ray._raylet.execute_task
  File "python\ray\_raylet.pyx", line 1957, in ray._raylet.execute_task
  File "python\ray\_raylet.pyx", line 1862, in ray._raylet.execute_task
  File "python\ray\_raylet.pyx", line 1803, in ray._raylet.execute_task.function_executor
  File "C:\Users\clara\anaconda3\envs\tf_gpu\lib\site-packages\ray\_private\function_manager.py", line 696, in actor_method_executor
    return method(__ray_actor, *args, **kwargs)
  File "C:\Users\clara\anaconda3\envs\tf_gpu\lib\site-packages\ray\util\tracing\tracing_helper.py", line 467, in _resume_span
    return method(self, *_args, **_kwargs)
  File "C:\Users\clara\anaconda3\envs\tf_gpu\lib\site-packages\flwr\simulation\ray_transport\ray_actor.py", line 63, in run
    raise ClientAppException(str(ex)) from ex
flwr.client.client_app.ClientAppException: 
Exception ClientAppException occurred. Message: You called `set_weights(weights)` on layer 'sequential_9' with a weight list of length 0, but the layer was expecting 8 weights.
[2024-12-03 16:27:49,976][flwr][ERROR] - Traceback (most recent call last):
  File "C:\Users\clara\anaconda3\envs\tf_gpu\lib\site-packages\flwr\simulation\ray_transport\ray_client_proxy.py", line 94, in _submit_job
    out_mssg, updated_context = self.actor_pool.get_client_result(
  File "C:\Users\clara\anaconda3\envs\tf_gpu\lib\site-packages\flwr\simulation\ray_transport\ray_actor.py", line 398, in get_client_result
    return self._fetch_future_result(cid)
  File "C:\Users\clara\anaconda3\envs\tf_gpu\lib\site-packages\flwr\simulation\ray_transport\ray_actor.py", line 279, in _fetch_future_result
    res_cid, out_mssg, updated_context = ray.get(
  File "C:\Users\clara\anaconda3\envs\tf_gpu\lib\site-packages\ray\_private\auto_init_hook.py", line 21, in auto_init_wrapper
    return fn(*args, **kwargs)
  File "C:\Users\clara\anaconda3\envs\tf_gpu\lib\site-packages\ray\_private\client_mode_hook.py", line 103, in wrapper
    return func(*args, **kwargs)
  File "C:\Users\clara\anaconda3\envs\tf_gpu\lib\site-packages\ray\_private\worker.py", line 2753, in get
    values, debugger_breakpoint = worker.get_objects(object_refs, timeout=timeout)
  File "C:\Users\clara\anaconda3\envs\tf_gpu\lib\site-packages\ray\_private\worker.py", line 904, in get_objects
    raise value.as_instanceof_cause()
ray.exceptions.RayTaskError(ClientAppException): [36mray::ClientAppActor.run()[39m (pid=20408, ip=127.0.0.1, actor_id=e8f6c7b4b011b565c443b57701000000, repr=<flwr.simulation.ray_transport.ray_actor.ClientAppActor object at 0x0000015A5B8A28E0>)
  File "C:\Users\clara\anaconda3\envs\tf_gpu\lib\site-packages\flwr\client\client_app.py", line 143, in __call__
    return self._call(message, context)
  File "C:\Users\clara\anaconda3\envs\tf_gpu\lib\site-packages\flwr\client\client_app.py", line 126, in ffn
    out_message = handle_legacy_message_from_msgtype(
  File "C:\Users\clara\anaconda3\envs\tf_gpu\lib\site-packages\flwr\client\message_handler\message_handler.py", line 129, in handle_legacy_message_from_msgtype
    fit_res = maybe_call_fit(
  File "C:\Users\clara\anaconda3\envs\tf_gpu\lib\site-packages\flwr\client\client.py", line 255, in maybe_call_fit
    return client.fit(fit_ins)
  File "C:\Users\clara\anaconda3\envs\tf_gpu\lib\site-packages\flwr\client\numpy_client.py", line 259, in _fit
    results = self.numpy_client.fit(parameters, ins.config)  # type: ignore
  File "C:\Users\clara\Desktop\TFG\Codigo TFG\3.FederatedTraining\client.py", line 27, in fit
    self.model.set_weights(parameters)
  File "C:\Users\clara\anaconda3\envs\tf_gpu\lib\site-packages\keras\src\layers\layer.py", line 696, in set_weights
    raise ValueError(
ValueError: You called `set_weights(weights)` on layer 'sequential_11' with a weight list of length 0, but the layer was expecting 8 weights.

The above exception was the direct cause of the following exception:

[36mray::ClientAppActor.run()[39m (pid=20408, ip=127.0.0.1, actor_id=e8f6c7b4b011b565c443b57701000000, repr=<flwr.simulation.ray_transport.ray_actor.ClientAppActor object at 0x0000015A5B8A28E0>)
  File "python\ray\_raylet.pyx", line 1856, in ray._raylet.execute_task
  File "python\ray\_raylet.pyx", line 1957, in ray._raylet.execute_task
  File "python\ray\_raylet.pyx", line 1862, in ray._raylet.execute_task
  File "python\ray\_raylet.pyx", line 1803, in ray._raylet.execute_task.function_executor
  File "C:\Users\clara\anaconda3\envs\tf_gpu\lib\site-packages\ray\_private\function_manager.py", line 696, in actor_method_executor
    return method(__ray_actor, *args, **kwargs)
  File "C:\Users\clara\anaconda3\envs\tf_gpu\lib\site-packages\ray\util\tracing\tracing_helper.py", line 467, in _resume_span
    return method(self, *_args, **_kwargs)
  File "C:\Users\clara\anaconda3\envs\tf_gpu\lib\site-packages\flwr\simulation\ray_transport\ray_actor.py", line 63, in run
    raise ClientAppException(str(ex)) from ex
flwr.client.client_app.ClientAppException: 
Exception ClientAppException occurred. Message: You called `set_weights(weights)` on layer 'sequential_11' with a weight list of length 0, but the layer was expecting 8 weights.

[2024-12-03 16:27:49,986][flwr][ERROR] - [36mray::ClientAppActor.run()[39m (pid=20408, ip=127.0.0.1, actor_id=e8f6c7b4b011b565c443b57701000000, repr=<flwr.simulation.ray_transport.ray_actor.ClientAppActor object at 0x0000015A5B8A28E0>)
  File "C:\Users\clara\anaconda3\envs\tf_gpu\lib\site-packages\flwr\client\client_app.py", line 143, in __call__
    return self._call(message, context)
  File "C:\Users\clara\anaconda3\envs\tf_gpu\lib\site-packages\flwr\client\client_app.py", line 126, in ffn
    out_message = handle_legacy_message_from_msgtype(
  File "C:\Users\clara\anaconda3\envs\tf_gpu\lib\site-packages\flwr\client\message_handler\message_handler.py", line 129, in handle_legacy_message_from_msgtype
    fit_res = maybe_call_fit(
  File "C:\Users\clara\anaconda3\envs\tf_gpu\lib\site-packages\flwr\client\client.py", line 255, in maybe_call_fit
    return client.fit(fit_ins)
  File "C:\Users\clara\anaconda3\envs\tf_gpu\lib\site-packages\flwr\client\numpy_client.py", line 259, in _fit
    results = self.numpy_client.fit(parameters, ins.config)  # type: ignore
  File "C:\Users\clara\Desktop\TFG\Codigo TFG\3.FederatedTraining\client.py", line 27, in fit
    self.model.set_weights(parameters)
  File "C:\Users\clara\anaconda3\envs\tf_gpu\lib\site-packages\keras\src\layers\layer.py", line 696, in set_weights
    raise ValueError(
ValueError: You called `set_weights(weights)` on layer 'sequential_11' with a weight list of length 0, but the layer was expecting 8 weights.

The above exception was the direct cause of the following exception:

[36mray::ClientAppActor.run()[39m (pid=20408, ip=127.0.0.1, actor_id=e8f6c7b4b011b565c443b57701000000, repr=<flwr.simulation.ray_transport.ray_actor.ClientAppActor object at 0x0000015A5B8A28E0>)
  File "python\ray\_raylet.pyx", line 1856, in ray._raylet.execute_task
  File "python\ray\_raylet.pyx", line 1957, in ray._raylet.execute_task
  File "python\ray\_raylet.pyx", line 1862, in ray._raylet.execute_task
  File "python\ray\_raylet.pyx", line 1803, in ray._raylet.execute_task.function_executor
  File "C:\Users\clara\anaconda3\envs\tf_gpu\lib\site-packages\ray\_private\function_manager.py", line 696, in actor_method_executor
    return method(__ray_actor, *args, **kwargs)
  File "C:\Users\clara\anaconda3\envs\tf_gpu\lib\site-packages\ray\util\tracing\tracing_helper.py", line 467, in _resume_span
    return method(self, *_args, **_kwargs)
  File "C:\Users\clara\anaconda3\envs\tf_gpu\lib\site-packages\flwr\simulation\ray_transport\ray_actor.py", line 63, in run
    raise ClientAppException(str(ex)) from ex
flwr.client.client_app.ClientAppException: 
Exception ClientAppException occurred. Message: You called `set_weights(weights)` on layer 'sequential_11' with a weight list of length 0, but the layer was expecting 8 weights.
[2024-12-03 16:27:50,086][flwr][ERROR] - Traceback (most recent call last):
  File "C:\Users\clara\anaconda3\envs\tf_gpu\lib\site-packages\flwr\simulation\ray_transport\ray_client_proxy.py", line 94, in _submit_job
    out_mssg, updated_context = self.actor_pool.get_client_result(
  File "C:\Users\clara\anaconda3\envs\tf_gpu\lib\site-packages\flwr\simulation\ray_transport\ray_actor.py", line 398, in get_client_result
    return self._fetch_future_result(cid)
  File "C:\Users\clara\anaconda3\envs\tf_gpu\lib\site-packages\flwr\simulation\ray_transport\ray_actor.py", line 279, in _fetch_future_result
    res_cid, out_mssg, updated_context = ray.get(
  File "C:\Users\clara\anaconda3\envs\tf_gpu\lib\site-packages\ray\_private\auto_init_hook.py", line 21, in auto_init_wrapper
    return fn(*args, **kwargs)
  File "C:\Users\clara\anaconda3\envs\tf_gpu\lib\site-packages\ray\_private\client_mode_hook.py", line 103, in wrapper
    return func(*args, **kwargs)
  File "C:\Users\clara\anaconda3\envs\tf_gpu\lib\site-packages\ray\_private\worker.py", line 2753, in get
    values, debugger_breakpoint = worker.get_objects(object_refs, timeout=timeout)
  File "C:\Users\clara\anaconda3\envs\tf_gpu\lib\site-packages\ray\_private\worker.py", line 904, in get_objects
    raise value.as_instanceof_cause()
ray.exceptions.RayTaskError(ClientAppException): [36mray::ClientAppActor.run()[39m (pid=17372, ip=127.0.0.1, actor_id=38dbbf05716928ec6fb350bf01000000, repr=<flwr.simulation.ray_transport.ray_actor.ClientAppActor object at 0x00000210E74B0A60>)
  File "C:\Users\clara\anaconda3\envs\tf_gpu\lib\site-packages\flwr\client\client_app.py", line 143, in __call__
    return self._call(message, context)
  File "C:\Users\clara\anaconda3\envs\tf_gpu\lib\site-packages\flwr\client\client_app.py", line 126, in ffn
    out_message = handle_legacy_message_from_msgtype(
  File "C:\Users\clara\anaconda3\envs\tf_gpu\lib\site-packages\flwr\client\message_handler\message_handler.py", line 129, in handle_legacy_message_from_msgtype
    fit_res = maybe_call_fit(
  File "C:\Users\clara\anaconda3\envs\tf_gpu\lib\site-packages\flwr\client\client.py", line 255, in maybe_call_fit
    return client.fit(fit_ins)
  File "C:\Users\clara\anaconda3\envs\tf_gpu\lib\site-packages\flwr\client\numpy_client.py", line 259, in _fit
    results = self.numpy_client.fit(parameters, ins.config)  # type: ignore
  File "C:\Users\clara\Desktop\TFG\Codigo TFG\3.FederatedTraining\client.py", line 27, in fit
    self.model.set_weights(parameters)
  File "C:\Users\clara\anaconda3\envs\tf_gpu\lib\site-packages\keras\src\layers\layer.py", line 696, in set_weights
    raise ValueError(
ValueError: You called `set_weights(weights)` on layer 'sequential_10' with a weight list of length 0, but the layer was expecting 8 weights.

The above exception was the direct cause of the following exception:

[36mray::ClientAppActor.run()[39m (pid=17372, ip=127.0.0.1, actor_id=38dbbf05716928ec6fb350bf01000000, repr=<flwr.simulation.ray_transport.ray_actor.ClientAppActor object at 0x00000210E74B0A60>)
  File "python\ray\_raylet.pyx", line 1856, in ray._raylet.execute_task
  File "python\ray\_raylet.pyx", line 1957, in ray._raylet.execute_task
  File "python\ray\_raylet.pyx", line 1862, in ray._raylet.execute_task
  File "python\ray\_raylet.pyx", line 1803, in ray._raylet.execute_task.function_executor
  File "C:\Users\clara\anaconda3\envs\tf_gpu\lib\site-packages\ray\_private\function_manager.py", line 696, in actor_method_executor
    return method(__ray_actor, *args, **kwargs)
  File "C:\Users\clara\anaconda3\envs\tf_gpu\lib\site-packages\ray\util\tracing\tracing_helper.py", line 467, in _resume_span
    return method(self, *_args, **_kwargs)
  File "C:\Users\clara\anaconda3\envs\tf_gpu\lib\site-packages\flwr\simulation\ray_transport\ray_actor.py", line 63, in run
    raise ClientAppException(str(ex)) from ex
flwr.client.client_app.ClientAppException: 
Exception ClientAppException occurred. Message: You called `set_weights(weights)` on layer 'sequential_10' with a weight list of length 0, but the layer was expecting 8 weights.

[2024-12-03 16:27:50,098][flwr][ERROR] - [36mray::ClientAppActor.run()[39m (pid=17372, ip=127.0.0.1, actor_id=38dbbf05716928ec6fb350bf01000000, repr=<flwr.simulation.ray_transport.ray_actor.ClientAppActor object at 0x00000210E74B0A60>)
  File "C:\Users\clara\anaconda3\envs\tf_gpu\lib\site-packages\flwr\client\client_app.py", line 143, in __call__
    return self._call(message, context)
  File "C:\Users\clara\anaconda3\envs\tf_gpu\lib\site-packages\flwr\client\client_app.py", line 126, in ffn
    out_message = handle_legacy_message_from_msgtype(
  File "C:\Users\clara\anaconda3\envs\tf_gpu\lib\site-packages\flwr\client\message_handler\message_handler.py", line 129, in handle_legacy_message_from_msgtype
    fit_res = maybe_call_fit(
  File "C:\Users\clara\anaconda3\envs\tf_gpu\lib\site-packages\flwr\client\client.py", line 255, in maybe_call_fit
    return client.fit(fit_ins)
  File "C:\Users\clara\anaconda3\envs\tf_gpu\lib\site-packages\flwr\client\numpy_client.py", line 259, in _fit
    results = self.numpy_client.fit(parameters, ins.config)  # type: ignore
  File "C:\Users\clara\Desktop\TFG\Codigo TFG\3.FederatedTraining\client.py", line 27, in fit
    self.model.set_weights(parameters)
  File "C:\Users\clara\anaconda3\envs\tf_gpu\lib\site-packages\keras\src\layers\layer.py", line 696, in set_weights
    raise ValueError(
ValueError: You called `set_weights(weights)` on layer 'sequential_10' with a weight list of length 0, but the layer was expecting 8 weights.

The above exception was the direct cause of the following exception:

[36mray::ClientAppActor.run()[39m (pid=17372, ip=127.0.0.1, actor_id=38dbbf05716928ec6fb350bf01000000, repr=<flwr.simulation.ray_transport.ray_actor.ClientAppActor object at 0x00000210E74B0A60>)
  File "python\ray\_raylet.pyx", line 1856, in ray._raylet.execute_task
  File "python\ray\_raylet.pyx", line 1957, in ray._raylet.execute_task
  File "python\ray\_raylet.pyx", line 1862, in ray._raylet.execute_task
  File "python\ray\_raylet.pyx", line 1803, in ray._raylet.execute_task.function_executor
  File "C:\Users\clara\anaconda3\envs\tf_gpu\lib\site-packages\ray\_private\function_manager.py", line 696, in actor_method_executor
    return method(__ray_actor, *args, **kwargs)
  File "C:\Users\clara\anaconda3\envs\tf_gpu\lib\site-packages\ray\util\tracing\tracing_helper.py", line 467, in _resume_span
    return method(self, *_args, **_kwargs)
  File "C:\Users\clara\anaconda3\envs\tf_gpu\lib\site-packages\flwr\simulation\ray_transport\ray_actor.py", line 63, in run
    raise ClientAppException(str(ex)) from ex
flwr.client.client_app.ClientAppException: 
Exception ClientAppException occurred. Message: You called `set_weights(weights)` on layer 'sequential_10' with a weight list of length 0, but the layer was expecting 8 weights.
[2024-12-03 16:27:53,698][flwr][ERROR] - Traceback (most recent call last):
  File "C:\Users\clara\anaconda3\envs\tf_gpu\lib\site-packages\flwr\simulation\ray_transport\ray_client_proxy.py", line 94, in _submit_job
    out_mssg, updated_context = self.actor_pool.get_client_result(
  File "C:\Users\clara\anaconda3\envs\tf_gpu\lib\site-packages\flwr\simulation\ray_transport\ray_actor.py", line 398, in get_client_result
    return self._fetch_future_result(cid)
  File "C:\Users\clara\anaconda3\envs\tf_gpu\lib\site-packages\flwr\simulation\ray_transport\ray_actor.py", line 279, in _fetch_future_result
    res_cid, out_mssg, updated_context = ray.get(
  File "C:\Users\clara\anaconda3\envs\tf_gpu\lib\site-packages\ray\_private\auto_init_hook.py", line 21, in auto_init_wrapper
    return fn(*args, **kwargs)
  File "C:\Users\clara\anaconda3\envs\tf_gpu\lib\site-packages\ray\_private\client_mode_hook.py", line 103, in wrapper
    return func(*args, **kwargs)
  File "C:\Users\clara\anaconda3\envs\tf_gpu\lib\site-packages\ray\_private\worker.py", line 2753, in get
    values, debugger_breakpoint = worker.get_objects(object_refs, timeout=timeout)
  File "C:\Users\clara\anaconda3\envs\tf_gpu\lib\site-packages\ray\_private\worker.py", line 904, in get_objects
    raise value.as_instanceof_cause()
ray.exceptions.RayTaskError(ClientAppException): [36mray::ClientAppActor.run()[39m (pid=20408, ip=127.0.0.1, actor_id=e8f6c7b4b011b565c443b57701000000, repr=<flwr.simulation.ray_transport.ray_actor.ClientAppActor object at 0x0000015A5B8A28E0>)
  File "C:\Users\clara\anaconda3\envs\tf_gpu\lib\site-packages\flwr\client\client_app.py", line 143, in __call__
    return self._call(message, context)
  File "C:\Users\clara\anaconda3\envs\tf_gpu\lib\site-packages\flwr\client\client_app.py", line 126, in ffn
    out_message = handle_legacy_message_from_msgtype(
  File "C:\Users\clara\anaconda3\envs\tf_gpu\lib\site-packages\flwr\client\message_handler\message_handler.py", line 129, in handle_legacy_message_from_msgtype
    fit_res = maybe_call_fit(
  File "C:\Users\clara\anaconda3\envs\tf_gpu\lib\site-packages\flwr\client\client.py", line 255, in maybe_call_fit
    return client.fit(fit_ins)
  File "C:\Users\clara\anaconda3\envs\tf_gpu\lib\site-packages\flwr\client\numpy_client.py", line 259, in _fit
    results = self.numpy_client.fit(parameters, ins.config)  # type: ignore
  File "C:\Users\clara\Desktop\TFG\Codigo TFG\3.FederatedTraining\client.py", line 27, in fit
    self.model.set_weights(parameters)
  File "C:\Users\clara\anaconda3\envs\tf_gpu\lib\site-packages\keras\src\layers\layer.py", line 696, in set_weights
    raise ValueError(
ValueError: You called `set_weights(weights)` on layer 'sequential_12' with a weight list of length 0, but the layer was expecting 8 weights.

The above exception was the direct cause of the following exception:

[36mray::ClientAppActor.run()[39m (pid=20408, ip=127.0.0.1, actor_id=e8f6c7b4b011b565c443b57701000000, repr=<flwr.simulation.ray_transport.ray_actor.ClientAppActor object at 0x0000015A5B8A28E0>)
  File "python\ray\_raylet.pyx", line 1856, in ray._raylet.execute_task
  File "python\ray\_raylet.pyx", line 1957, in ray._raylet.execute_task
  File "python\ray\_raylet.pyx", line 1862, in ray._raylet.execute_task
  File "python\ray\_raylet.pyx", line 1803, in ray._raylet.execute_task.function_executor
  File "C:\Users\clara\anaconda3\envs\tf_gpu\lib\site-packages\ray\_private\function_manager.py", line 696, in actor_method_executor
    return method(__ray_actor, *args, **kwargs)
  File "C:\Users\clara\anaconda3\envs\tf_gpu\lib\site-packages\ray\util\tracing\tracing_helper.py", line 467, in _resume_span
    return method(self, *_args, **_kwargs)
  File "C:\Users\clara\anaconda3\envs\tf_gpu\lib\site-packages\flwr\simulation\ray_transport\ray_actor.py", line 63, in run
    raise ClientAppException(str(ex)) from ex
flwr.client.client_app.ClientAppException: 
Exception ClientAppException occurred. Message: You called `set_weights(weights)` on layer 'sequential_12' with a weight list of length 0, but the layer was expecting 8 weights.

[2024-12-03 16:27:53,716][flwr][ERROR] - [36mray::ClientAppActor.run()[39m (pid=20408, ip=127.0.0.1, actor_id=e8f6c7b4b011b565c443b57701000000, repr=<flwr.simulation.ray_transport.ray_actor.ClientAppActor object at 0x0000015A5B8A28E0>)
  File "C:\Users\clara\anaconda3\envs\tf_gpu\lib\site-packages\flwr\client\client_app.py", line 143, in __call__
    return self._call(message, context)
  File "C:\Users\clara\anaconda3\envs\tf_gpu\lib\site-packages\flwr\client\client_app.py", line 126, in ffn
    out_message = handle_legacy_message_from_msgtype(
  File "C:\Users\clara\anaconda3\envs\tf_gpu\lib\site-packages\flwr\client\message_handler\message_handler.py", line 129, in handle_legacy_message_from_msgtype
    fit_res = maybe_call_fit(
  File "C:\Users\clara\anaconda3\envs\tf_gpu\lib\site-packages\flwr\client\client.py", line 255, in maybe_call_fit
    return client.fit(fit_ins)
  File "C:\Users\clara\anaconda3\envs\tf_gpu\lib\site-packages\flwr\client\numpy_client.py", line 259, in _fit
    results = self.numpy_client.fit(parameters, ins.config)  # type: ignore
  File "C:\Users\clara\Desktop\TFG\Codigo TFG\3.FederatedTraining\client.py", line 27, in fit
    self.model.set_weights(parameters)
  File "C:\Users\clara\anaconda3\envs\tf_gpu\lib\site-packages\keras\src\layers\layer.py", line 696, in set_weights
    raise ValueError(
ValueError: You called `set_weights(weights)` on layer 'sequential_12' with a weight list of length 0, but the layer was expecting 8 weights.

The above exception was the direct cause of the following exception:

[36mray::ClientAppActor.run()[39m (pid=20408, ip=127.0.0.1, actor_id=e8f6c7b4b011b565c443b57701000000, repr=<flwr.simulation.ray_transport.ray_actor.ClientAppActor object at 0x0000015A5B8A28E0>)
  File "python\ray\_raylet.pyx", line 1856, in ray._raylet.execute_task
  File "python\ray\_raylet.pyx", line 1957, in ray._raylet.execute_task
  File "python\ray\_raylet.pyx", line 1862, in ray._raylet.execute_task
  File "python\ray\_raylet.pyx", line 1803, in ray._raylet.execute_task.function_executor
  File "C:\Users\clara\anaconda3\envs\tf_gpu\lib\site-packages\ray\_private\function_manager.py", line 696, in actor_method_executor
    return method(__ray_actor, *args, **kwargs)
  File "C:\Users\clara\anaconda3\envs\tf_gpu\lib\site-packages\ray\util\tracing\tracing_helper.py", line 467, in _resume_span
    return method(self, *_args, **_kwargs)
  File "C:\Users\clara\anaconda3\envs\tf_gpu\lib\site-packages\flwr\simulation\ray_transport\ray_actor.py", line 63, in run
    raise ClientAppException(str(ex)) from ex
flwr.client.client_app.ClientAppException: 
Exception ClientAppException occurred. Message: You called `set_weights(weights)` on layer 'sequential_12' with a weight list of length 0, but the layer was expecting 8 weights.
[2024-12-03 16:27:54,885][flwr][ERROR] - Traceback (most recent call last):
  File "C:\Users\clara\anaconda3\envs\tf_gpu\lib\site-packages\flwr\simulation\ray_transport\ray_client_proxy.py", line 94, in _submit_job
    out_mssg, updated_context = self.actor_pool.get_client_result(
  File "C:\Users\clara\anaconda3\envs\tf_gpu\lib\site-packages\flwr\simulation\ray_transport\ray_actor.py", line 398, in get_client_result
    return self._fetch_future_result(cid)
  File "C:\Users\clara\anaconda3\envs\tf_gpu\lib\site-packages\flwr\simulation\ray_transport\ray_actor.py", line 279, in _fetch_future_result
    res_cid, out_mssg, updated_context = ray.get(
  File "C:\Users\clara\anaconda3\envs\tf_gpu\lib\site-packages\ray\_private\auto_init_hook.py", line 21, in auto_init_wrapper
    return fn(*args, **kwargs)
  File "C:\Users\clara\anaconda3\envs\tf_gpu\lib\site-packages\ray\_private\client_mode_hook.py", line 103, in wrapper
    return func(*args, **kwargs)
  File "C:\Users\clara\anaconda3\envs\tf_gpu\lib\site-packages\ray\_private\worker.py", line 2753, in get
    values, debugger_breakpoint = worker.get_objects(object_refs, timeout=timeout)
  File "C:\Users\clara\anaconda3\envs\tf_gpu\lib\site-packages\ray\_private\worker.py", line 904, in get_objects
    raise value.as_instanceof_cause()
ray.exceptions.RayTaskError(ClientAppException): [36mray::ClientAppActor.run()[39m (pid=17372, ip=127.0.0.1, actor_id=38dbbf05716928ec6fb350bf01000000, repr=<flwr.simulation.ray_transport.ray_actor.ClientAppActor object at 0x00000210E74B0A60>)
  File "C:\Users\clara\anaconda3\envs\tf_gpu\lib\site-packages\flwr\client\client_app.py", line 143, in __call__
    return self._call(message, context)
  File "C:\Users\clara\anaconda3\envs\tf_gpu\lib\site-packages\flwr\client\client_app.py", line 126, in ffn
    out_message = handle_legacy_message_from_msgtype(
  File "C:\Users\clara\anaconda3\envs\tf_gpu\lib\site-packages\flwr\client\message_handler\message_handler.py", line 129, in handle_legacy_message_from_msgtype
    fit_res = maybe_call_fit(
  File "C:\Users\clara\anaconda3\envs\tf_gpu\lib\site-packages\flwr\client\client.py", line 255, in maybe_call_fit
    return client.fit(fit_ins)
  File "C:\Users\clara\anaconda3\envs\tf_gpu\lib\site-packages\flwr\client\numpy_client.py", line 259, in _fit
    results = self.numpy_client.fit(parameters, ins.config)  # type: ignore
  File "C:\Users\clara\Desktop\TFG\Codigo TFG\3.FederatedTraining\client.py", line 27, in fit
    self.model.set_weights(parameters)
  File "C:\Users\clara\anaconda3\envs\tf_gpu\lib\site-packages\keras\src\layers\layer.py", line 696, in set_weights
    raise ValueError(
ValueError: You called `set_weights(weights)` on layer 'sequential_11' with a weight list of length 0, but the layer was expecting 8 weights.

The above exception was the direct cause of the following exception:

[36mray::ClientAppActor.run()[39m (pid=17372, ip=127.0.0.1, actor_id=38dbbf05716928ec6fb350bf01000000, repr=<flwr.simulation.ray_transport.ray_actor.ClientAppActor object at 0x00000210E74B0A60>)
  File "python\ray\_raylet.pyx", line 1856, in ray._raylet.execute_task
  File "python\ray\_raylet.pyx", line 1957, in ray._raylet.execute_task
  File "python\ray\_raylet.pyx", line 1862, in ray._raylet.execute_task
  File "python\ray\_raylet.pyx", line 1803, in ray._raylet.execute_task.function_executor
  File "C:\Users\clara\anaconda3\envs\tf_gpu\lib\site-packages\ray\_private\function_manager.py", line 696, in actor_method_executor
    return method(__ray_actor, *args, **kwargs)
  File "C:\Users\clara\anaconda3\envs\tf_gpu\lib\site-packages\ray\util\tracing\tracing_helper.py", line 467, in _resume_span
    return method(self, *_args, **_kwargs)
  File "C:\Users\clara\anaconda3\envs\tf_gpu\lib\site-packages\flwr\simulation\ray_transport\ray_actor.py", line 63, in run
    raise ClientAppException(str(ex)) from ex
flwr.client.client_app.ClientAppException: 
Exception ClientAppException occurred. Message: You called `set_weights(weights)` on layer 'sequential_11' with a weight list of length 0, but the layer was expecting 8 weights.

[2024-12-03 16:27:54,898][flwr][ERROR] - [36mray::ClientAppActor.run()[39m (pid=17372, ip=127.0.0.1, actor_id=38dbbf05716928ec6fb350bf01000000, repr=<flwr.simulation.ray_transport.ray_actor.ClientAppActor object at 0x00000210E74B0A60>)
  File "C:\Users\clara\anaconda3\envs\tf_gpu\lib\site-packages\flwr\client\client_app.py", line 143, in __call__
    return self._call(message, context)
  File "C:\Users\clara\anaconda3\envs\tf_gpu\lib\site-packages\flwr\client\client_app.py", line 126, in ffn
    out_message = handle_legacy_message_from_msgtype(
  File "C:\Users\clara\anaconda3\envs\tf_gpu\lib\site-packages\flwr\client\message_handler\message_handler.py", line 129, in handle_legacy_message_from_msgtype
    fit_res = maybe_call_fit(
  File "C:\Users\clara\anaconda3\envs\tf_gpu\lib\site-packages\flwr\client\client.py", line 255, in maybe_call_fit
    return client.fit(fit_ins)
  File "C:\Users\clara\anaconda3\envs\tf_gpu\lib\site-packages\flwr\client\numpy_client.py", line 259, in _fit
    results = self.numpy_client.fit(parameters, ins.config)  # type: ignore
  File "C:\Users\clara\Desktop\TFG\Codigo TFG\3.FederatedTraining\client.py", line 27, in fit
    self.model.set_weights(parameters)
  File "C:\Users\clara\anaconda3\envs\tf_gpu\lib\site-packages\keras\src\layers\layer.py", line 696, in set_weights
    raise ValueError(
ValueError: You called `set_weights(weights)` on layer 'sequential_11' with a weight list of length 0, but the layer was expecting 8 weights.

The above exception was the direct cause of the following exception:

[36mray::ClientAppActor.run()[39m (pid=17372, ip=127.0.0.1, actor_id=38dbbf05716928ec6fb350bf01000000, repr=<flwr.simulation.ray_transport.ray_actor.ClientAppActor object at 0x00000210E74B0A60>)
  File "python\ray\_raylet.pyx", line 1856, in ray._raylet.execute_task
  File "python\ray\_raylet.pyx", line 1957, in ray._raylet.execute_task
  File "python\ray\_raylet.pyx", line 1862, in ray._raylet.execute_task
  File "python\ray\_raylet.pyx", line 1803, in ray._raylet.execute_task.function_executor
  File "C:\Users\clara\anaconda3\envs\tf_gpu\lib\site-packages\ray\_private\function_manager.py", line 696, in actor_method_executor
    return method(__ray_actor, *args, **kwargs)
  File "C:\Users\clara\anaconda3\envs\tf_gpu\lib\site-packages\ray\util\tracing\tracing_helper.py", line 467, in _resume_span
    return method(self, *_args, **_kwargs)
  File "C:\Users\clara\anaconda3\envs\tf_gpu\lib\site-packages\flwr\simulation\ray_transport\ray_actor.py", line 63, in run
    raise ClientAppException(str(ex)) from ex
flwr.client.client_app.ClientAppException: 
Exception ClientAppException occurred. Message: You called `set_weights(weights)` on layer 'sequential_11' with a weight list of length 0, but the layer was expecting 8 weights.
[2024-12-03 16:27:56,660][flwr][ERROR] - Traceback (most recent call last):
  File "C:\Users\clara\anaconda3\envs\tf_gpu\lib\site-packages\flwr\simulation\ray_transport\ray_client_proxy.py", line 94, in _submit_job
    out_mssg, updated_context = self.actor_pool.get_client_result(
  File "C:\Users\clara\anaconda3\envs\tf_gpu\lib\site-packages\flwr\simulation\ray_transport\ray_actor.py", line 398, in get_client_result
    return self._fetch_future_result(cid)
  File "C:\Users\clara\anaconda3\envs\tf_gpu\lib\site-packages\flwr\simulation\ray_transport\ray_actor.py", line 279, in _fetch_future_result
    res_cid, out_mssg, updated_context = ray.get(
  File "C:\Users\clara\anaconda3\envs\tf_gpu\lib\site-packages\ray\_private\auto_init_hook.py", line 21, in auto_init_wrapper
    return fn(*args, **kwargs)
  File "C:\Users\clara\anaconda3\envs\tf_gpu\lib\site-packages\ray\_private\client_mode_hook.py", line 103, in wrapper
    return func(*args, **kwargs)
  File "C:\Users\clara\anaconda3\envs\tf_gpu\lib\site-packages\ray\_private\worker.py", line 2753, in get
    values, debugger_breakpoint = worker.get_objects(object_refs, timeout=timeout)
  File "C:\Users\clara\anaconda3\envs\tf_gpu\lib\site-packages\ray\_private\worker.py", line 904, in get_objects
    raise value.as_instanceof_cause()
ray.exceptions.RayTaskError(ClientAppException): [36mray::ClientAppActor.run()[39m (pid=20408, ip=127.0.0.1, actor_id=e8f6c7b4b011b565c443b57701000000, repr=<flwr.simulation.ray_transport.ray_actor.ClientAppActor object at 0x0000015A5B8A28E0>)
  File "C:\Users\clara\anaconda3\envs\tf_gpu\lib\site-packages\flwr\client\client_app.py", line 143, in __call__
    return self._call(message, context)
  File "C:\Users\clara\anaconda3\envs\tf_gpu\lib\site-packages\flwr\client\client_app.py", line 126, in ffn
    out_message = handle_legacy_message_from_msgtype(
  File "C:\Users\clara\anaconda3\envs\tf_gpu\lib\site-packages\flwr\client\message_handler\message_handler.py", line 129, in handle_legacy_message_from_msgtype
    fit_res = maybe_call_fit(
  File "C:\Users\clara\anaconda3\envs\tf_gpu\lib\site-packages\flwr\client\client.py", line 255, in maybe_call_fit
    return client.fit(fit_ins)
  File "C:\Users\clara\anaconda3\envs\tf_gpu\lib\site-packages\flwr\client\numpy_client.py", line 259, in _fit
    results = self.numpy_client.fit(parameters, ins.config)  # type: ignore
  File "C:\Users\clara\Desktop\TFG\Codigo TFG\3.FederatedTraining\client.py", line 27, in fit
    self.model.set_weights(parameters)
  File "C:\Users\clara\anaconda3\envs\tf_gpu\lib\site-packages\keras\src\layers\layer.py", line 696, in set_weights
    raise ValueError(
ValueError: You called `set_weights(weights)` on layer 'sequential_13' with a weight list of length 0, but the layer was expecting 8 weights.

The above exception was the direct cause of the following exception:

[36mray::ClientAppActor.run()[39m (pid=20408, ip=127.0.0.1, actor_id=e8f6c7b4b011b565c443b57701000000, repr=<flwr.simulation.ray_transport.ray_actor.ClientAppActor object at 0x0000015A5B8A28E0>)
  File "python\ray\_raylet.pyx", line 1856, in ray._raylet.execute_task
  File "python\ray\_raylet.pyx", line 1957, in ray._raylet.execute_task
  File "python\ray\_raylet.pyx", line 1862, in ray._raylet.execute_task
  File "python\ray\_raylet.pyx", line 1803, in ray._raylet.execute_task.function_executor
  File "C:\Users\clara\anaconda3\envs\tf_gpu\lib\site-packages\ray\_private\function_manager.py", line 696, in actor_method_executor
    return method(__ray_actor, *args, **kwargs)
  File "C:\Users\clara\anaconda3\envs\tf_gpu\lib\site-packages\ray\util\tracing\tracing_helper.py", line 467, in _resume_span
    return method(self, *_args, **_kwargs)
  File "C:\Users\clara\anaconda3\envs\tf_gpu\lib\site-packages\flwr\simulation\ray_transport\ray_actor.py", line 63, in run
    raise ClientAppException(str(ex)) from ex
flwr.client.client_app.ClientAppException: 
Exception ClientAppException occurred. Message: You called `set_weights(weights)` on layer 'sequential_13' with a weight list of length 0, but the layer was expecting 8 weights.

[2024-12-03 16:27:56,670][flwr][ERROR] - [36mray::ClientAppActor.run()[39m (pid=20408, ip=127.0.0.1, actor_id=e8f6c7b4b011b565c443b57701000000, repr=<flwr.simulation.ray_transport.ray_actor.ClientAppActor object at 0x0000015A5B8A28E0>)
  File "C:\Users\clara\anaconda3\envs\tf_gpu\lib\site-packages\flwr\client\client_app.py", line 143, in __call__
    return self._call(message, context)
  File "C:\Users\clara\anaconda3\envs\tf_gpu\lib\site-packages\flwr\client\client_app.py", line 126, in ffn
    out_message = handle_legacy_message_from_msgtype(
  File "C:\Users\clara\anaconda3\envs\tf_gpu\lib\site-packages\flwr\client\message_handler\message_handler.py", line 129, in handle_legacy_message_from_msgtype
    fit_res = maybe_call_fit(
  File "C:\Users\clara\anaconda3\envs\tf_gpu\lib\site-packages\flwr\client\client.py", line 255, in maybe_call_fit
    return client.fit(fit_ins)
  File "C:\Users\clara\anaconda3\envs\tf_gpu\lib\site-packages\flwr\client\numpy_client.py", line 259, in _fit
    results = self.numpy_client.fit(parameters, ins.config)  # type: ignore
  File "C:\Users\clara\Desktop\TFG\Codigo TFG\3.FederatedTraining\client.py", line 27, in fit
    self.model.set_weights(parameters)
  File "C:\Users\clara\anaconda3\envs\tf_gpu\lib\site-packages\keras\src\layers\layer.py", line 696, in set_weights
    raise ValueError(
ValueError: You called `set_weights(weights)` on layer 'sequential_13' with a weight list of length 0, but the layer was expecting 8 weights.

The above exception was the direct cause of the following exception:

[36mray::ClientAppActor.run()[39m (pid=20408, ip=127.0.0.1, actor_id=e8f6c7b4b011b565c443b57701000000, repr=<flwr.simulation.ray_transport.ray_actor.ClientAppActor object at 0x0000015A5B8A28E0>)
  File "python\ray\_raylet.pyx", line 1856, in ray._raylet.execute_task
  File "python\ray\_raylet.pyx", line 1957, in ray._raylet.execute_task
  File "python\ray\_raylet.pyx", line 1862, in ray._raylet.execute_task
  File "python\ray\_raylet.pyx", line 1803, in ray._raylet.execute_task.function_executor
  File "C:\Users\clara\anaconda3\envs\tf_gpu\lib\site-packages\ray\_private\function_manager.py", line 696, in actor_method_executor
    return method(__ray_actor, *args, **kwargs)
  File "C:\Users\clara\anaconda3\envs\tf_gpu\lib\site-packages\ray\util\tracing\tracing_helper.py", line 467, in _resume_span
    return method(self, *_args, **_kwargs)
  File "C:\Users\clara\anaconda3\envs\tf_gpu\lib\site-packages\flwr\simulation\ray_transport\ray_actor.py", line 63, in run
    raise ClientAppException(str(ex)) from ex
flwr.client.client_app.ClientAppException: 
Exception ClientAppException occurred. Message: You called `set_weights(weights)` on layer 'sequential_13' with a weight list of length 0, but the layer was expecting 8 weights.
[2024-12-03 16:27:59,446][flwr][ERROR] - Traceback (most recent call last):
  File "C:\Users\clara\anaconda3\envs\tf_gpu\lib\site-packages\flwr\simulation\ray_transport\ray_client_proxy.py", line 94, in _submit_job
    out_mssg, updated_context = self.actor_pool.get_client_result(
  File "C:\Users\clara\anaconda3\envs\tf_gpu\lib\site-packages\flwr\simulation\ray_transport\ray_actor.py", line 398, in get_client_result
    return self._fetch_future_result(cid)
  File "C:\Users\clara\anaconda3\envs\tf_gpu\lib\site-packages\flwr\simulation\ray_transport\ray_actor.py", line 279, in _fetch_future_result
    res_cid, out_mssg, updated_context = ray.get(
  File "C:\Users\clara\anaconda3\envs\tf_gpu\lib\site-packages\ray\_private\auto_init_hook.py", line 21, in auto_init_wrapper
    return fn(*args, **kwargs)
  File "C:\Users\clara\anaconda3\envs\tf_gpu\lib\site-packages\ray\_private\client_mode_hook.py", line 103, in wrapper
    return func(*args, **kwargs)
  File "C:\Users\clara\anaconda3\envs\tf_gpu\lib\site-packages\ray\_private\worker.py", line 2753, in get
    values, debugger_breakpoint = worker.get_objects(object_refs, timeout=timeout)
  File "C:\Users\clara\anaconda3\envs\tf_gpu\lib\site-packages\ray\_private\worker.py", line 904, in get_objects
    raise value.as_instanceof_cause()
ray.exceptions.RayTaskError(ClientAppException): [36mray::ClientAppActor.run()[39m (pid=17372, ip=127.0.0.1, actor_id=38dbbf05716928ec6fb350bf01000000, repr=<flwr.simulation.ray_transport.ray_actor.ClientAppActor object at 0x00000210E74B0A60>)
  File "C:\Users\clara\anaconda3\envs\tf_gpu\lib\site-packages\flwr\client\client_app.py", line 143, in __call__
    return self._call(message, context)
  File "C:\Users\clara\anaconda3\envs\tf_gpu\lib\site-packages\flwr\client\client_app.py", line 126, in ffn
    out_message = handle_legacy_message_from_msgtype(
  File "C:\Users\clara\anaconda3\envs\tf_gpu\lib\site-packages\flwr\client\message_handler\message_handler.py", line 129, in handle_legacy_message_from_msgtype
    fit_res = maybe_call_fit(
  File "C:\Users\clara\anaconda3\envs\tf_gpu\lib\site-packages\flwr\client\client.py", line 255, in maybe_call_fit
    return client.fit(fit_ins)
  File "C:\Users\clara\anaconda3\envs\tf_gpu\lib\site-packages\flwr\client\numpy_client.py", line 259, in _fit
    results = self.numpy_client.fit(parameters, ins.config)  # type: ignore
  File "C:\Users\clara\Desktop\TFG\Codigo TFG\3.FederatedTraining\client.py", line 27, in fit
    self.model.set_weights(parameters)
  File "C:\Users\clara\anaconda3\envs\tf_gpu\lib\site-packages\keras\src\layers\layer.py", line 696, in set_weights
    raise ValueError(
ValueError: You called `set_weights(weights)` on layer 'sequential_12' with a weight list of length 0, but the layer was expecting 8 weights.

The above exception was the direct cause of the following exception:

[36mray::ClientAppActor.run()[39m (pid=17372, ip=127.0.0.1, actor_id=38dbbf05716928ec6fb350bf01000000, repr=<flwr.simulation.ray_transport.ray_actor.ClientAppActor object at 0x00000210E74B0A60>)
  File "python\ray\_raylet.pyx", line 1856, in ray._raylet.execute_task
  File "python\ray\_raylet.pyx", line 1957, in ray._raylet.execute_task
  File "python\ray\_raylet.pyx", line 1862, in ray._raylet.execute_task
  File "python\ray\_raylet.pyx", line 1803, in ray._raylet.execute_task.function_executor
  File "C:\Users\clara\anaconda3\envs\tf_gpu\lib\site-packages\ray\_private\function_manager.py", line 696, in actor_method_executor
    return method(__ray_actor, *args, **kwargs)
  File "C:\Users\clara\anaconda3\envs\tf_gpu\lib\site-packages\ray\util\tracing\tracing_helper.py", line 467, in _resume_span
    return method(self, *_args, **_kwargs)
  File "C:\Users\clara\anaconda3\envs\tf_gpu\lib\site-packages\flwr\simulation\ray_transport\ray_actor.py", line 63, in run
    raise ClientAppException(str(ex)) from ex
flwr.client.client_app.ClientAppException: 
Exception ClientAppException occurred. Message: You called `set_weights(weights)` on layer 'sequential_12' with a weight list of length 0, but the layer was expecting 8 weights.

[2024-12-03 16:27:59,454][flwr][ERROR] - [36mray::ClientAppActor.run()[39m (pid=17372, ip=127.0.0.1, actor_id=38dbbf05716928ec6fb350bf01000000, repr=<flwr.simulation.ray_transport.ray_actor.ClientAppActor object at 0x00000210E74B0A60>)
  File "C:\Users\clara\anaconda3\envs\tf_gpu\lib\site-packages\flwr\client\client_app.py", line 143, in __call__
    return self._call(message, context)
  File "C:\Users\clara\anaconda3\envs\tf_gpu\lib\site-packages\flwr\client\client_app.py", line 126, in ffn
    out_message = handle_legacy_message_from_msgtype(
  File "C:\Users\clara\anaconda3\envs\tf_gpu\lib\site-packages\flwr\client\message_handler\message_handler.py", line 129, in handle_legacy_message_from_msgtype
    fit_res = maybe_call_fit(
  File "C:\Users\clara\anaconda3\envs\tf_gpu\lib\site-packages\flwr\client\client.py", line 255, in maybe_call_fit
    return client.fit(fit_ins)
  File "C:\Users\clara\anaconda3\envs\tf_gpu\lib\site-packages\flwr\client\numpy_client.py", line 259, in _fit
    results = self.numpy_client.fit(parameters, ins.config)  # type: ignore
  File "C:\Users\clara\Desktop\TFG\Codigo TFG\3.FederatedTraining\client.py", line 27, in fit
    self.model.set_weights(parameters)
  File "C:\Users\clara\anaconda3\envs\tf_gpu\lib\site-packages\keras\src\layers\layer.py", line 696, in set_weights
    raise ValueError(
ValueError: You called `set_weights(weights)` on layer 'sequential_12' with a weight list of length 0, but the layer was expecting 8 weights.

The above exception was the direct cause of the following exception:

[36mray::ClientAppActor.run()[39m (pid=17372, ip=127.0.0.1, actor_id=38dbbf05716928ec6fb350bf01000000, repr=<flwr.simulation.ray_transport.ray_actor.ClientAppActor object at 0x00000210E74B0A60>)
  File "python\ray\_raylet.pyx", line 1856, in ray._raylet.execute_task
  File "python\ray\_raylet.pyx", line 1957, in ray._raylet.execute_task
  File "python\ray\_raylet.pyx", line 1862, in ray._raylet.execute_task
  File "python\ray\_raylet.pyx", line 1803, in ray._raylet.execute_task.function_executor
  File "C:\Users\clara\anaconda3\envs\tf_gpu\lib\site-packages\ray\_private\function_manager.py", line 696, in actor_method_executor
    return method(__ray_actor, *args, **kwargs)
  File "C:\Users\clara\anaconda3\envs\tf_gpu\lib\site-packages\ray\util\tracing\tracing_helper.py", line 467, in _resume_span
    return method(self, *_args, **_kwargs)
  File "C:\Users\clara\anaconda3\envs\tf_gpu\lib\site-packages\flwr\simulation\ray_transport\ray_actor.py", line 63, in run
    raise ClientAppException(str(ex)) from ex
flwr.client.client_app.ClientAppException: 
Exception ClientAppException occurred. Message: You called `set_weights(weights)` on layer 'sequential_12' with a weight list of length 0, but the layer was expecting 8 weights.
