[2024-12-03 23:19:41,476][flwr][WARNING] - DEPRECATED FEATURE: flwr.simulation.start_simulation() is deprecated.
	Instead, use the `flwr run` CLI command to start a local simulation in your Flower app, as shown for example below:

		$ flwr new  # Create a new Flower app from a template

		$ flwr run  # Run the Flower app in Simulation Mode

	Using `start_simulation()` is deprecated.

            This is a deprecated feature. It will be removed
            entirely in future versions of Flower.
        
[2024-12-03 23:19:41,479][flwr][INFO] - Starting Flower simulation, config: num_rounds=10, no round_timeout
[2024-12-03 23:19:52,334][flwr][INFO] - Flower VCE: Ray initialized with resources: {'accelerator_type:G': 1.0, 'node:__internal_head__': 1.0, 'CPU': 8.0, 'object_store_memory': 1864291123.0, 'node:127.0.0.1': 1.0, 'memory': 3728582247.0, 'GPU': 1.0}
[2024-12-03 23:19:52,486][flwr][INFO] - Optimize your simulation with Flower VCE: https://flower.ai/docs/framework/how-to-run-simulations.html
[2024-12-03 23:19:52,487][flwr][INFO] - Flower VCE: Resources for each Virtual Client: {'num_cpus': 2, 'num_gpus': 0.5}
[2024-12-03 23:19:52,511][flwr][INFO] - Flower VCE: Creating VirtualClientEngineActorPool with 2 actors
[2024-12-03 23:19:52,512][flwr][INFO] - [INIT]
[2024-12-03 23:19:52,513][flwr][INFO] - Requesting initial parameters from one random client
[2024-12-03 23:20:03,855][flwr][WARNING] - Failed to receive initial parameters from the client. Empty initial parameters will be used.
[2024-12-03 23:20:03,856][flwr][INFO] - Starting evaluation of initial global parameters
[2024-12-03 23:20:16,226][flwr][INFO] - initial parameters (loss, other metrics): 0.14217747747898102, {'mae': 0.3352893590927124}
[2024-12-03 23:20:16,227][flwr][INFO] - 
[2024-12-03 23:20:16,228][flwr][INFO] - [ROUND 1]
[2024-12-03 23:20:16,229][flwr][INFO] - configure_fit: strategy sampled 1 clients (out of 1)
[2024-12-03 23:20:18,627][flwr][ERROR] - Traceback (most recent call last):
  File "C:\Users\clara\anaconda3\envs\tf_gpu\lib\site-packages\flwr\simulation\ray_transport\ray_client_proxy.py", line 94, in _submit_job
    out_mssg, updated_context = self.actor_pool.get_client_result(
  File "C:\Users\clara\anaconda3\envs\tf_gpu\lib\site-packages\flwr\simulation\ray_transport\ray_actor.py", line 398, in get_client_result
    return self._fetch_future_result(cid)
  File "C:\Users\clara\anaconda3\envs\tf_gpu\lib\site-packages\flwr\simulation\ray_transport\ray_actor.py", line 279, in _fetch_future_result
    res_cid, out_mssg, updated_context = ray.get(
  File "C:\Users\clara\anaconda3\envs\tf_gpu\lib\site-packages\ray\_private\auto_init_hook.py", line 21, in auto_init_wrapper
    return fn(*args, **kwargs)
  File "C:\Users\clara\anaconda3\envs\tf_gpu\lib\site-packages\ray\_private\client_mode_hook.py", line 103, in wrapper
    return func(*args, **kwargs)
  File "C:\Users\clara\anaconda3\envs\tf_gpu\lib\site-packages\ray\_private\worker.py", line 2753, in get
    values, debugger_breakpoint = worker.get_objects(object_refs, timeout=timeout)
  File "C:\Users\clara\anaconda3\envs\tf_gpu\lib\site-packages\ray\_private\worker.py", line 904, in get_objects
    raise value.as_instanceof_cause()
ray.exceptions.RayTaskError(ClientAppException): [36mray::ClientAppActor.run()[39m (pid=1976, ip=127.0.0.1, actor_id=6b7804ce62ccde3aea0880a701000000, repr=<flwr.simulation.ray_transport.ray_actor.ClientAppActor object at 0x0000020CD7FC1A30>)
  File "C:\Users\clara\anaconda3\envs\tf_gpu\lib\site-packages\flwr\client\client_app.py", line 143, in __call__
    return self._call(message, context)
  File "C:\Users\clara\anaconda3\envs\tf_gpu\lib\site-packages\flwr\client\client_app.py", line 126, in ffn
    out_message = handle_legacy_message_from_msgtype(
  File "C:\Users\clara\anaconda3\envs\tf_gpu\lib\site-packages\flwr\client\message_handler\message_handler.py", line 129, in handle_legacy_message_from_msgtype
    fit_res = maybe_call_fit(
  File "C:\Users\clara\anaconda3\envs\tf_gpu\lib\site-packages\flwr\client\client.py", line 255, in maybe_call_fit
    return client.fit(fit_ins)
  File "C:\Users\clara\anaconda3\envs\tf_gpu\lib\site-packages\flwr\client\numpy_client.py", line 259, in _fit
    results = self.numpy_client.fit(parameters, ins.config)  # type: ignore
  File "C:\Users\clara\Desktop\TFG\Codigo TFG\3.FederatedTraining\client.py", line 27, in fit
    self.model.set_weights(parameters)
  File "C:\Users\clara\anaconda3\envs\tf_gpu\lib\site-packages\keras\src\layers\layer.py", line 696, in set_weights
    raise ValueError(
ValueError: You called `set_weights(weights)` on layer 'sequential_1' with a weight list of length 0, but the layer was expecting 8 weights.

The above exception was the direct cause of the following exception:

[36mray::ClientAppActor.run()[39m (pid=1976, ip=127.0.0.1, actor_id=6b7804ce62ccde3aea0880a701000000, repr=<flwr.simulation.ray_transport.ray_actor.ClientAppActor object at 0x0000020CD7FC1A30>)
  File "python\ray\_raylet.pyx", line 1856, in ray._raylet.execute_task
  File "python\ray\_raylet.pyx", line 1957, in ray._raylet.execute_task
  File "python\ray\_raylet.pyx", line 1862, in ray._raylet.execute_task
  File "python\ray\_raylet.pyx", line 1803, in ray._raylet.execute_task.function_executor
  File "C:\Users\clara\anaconda3\envs\tf_gpu\lib\site-packages\ray\_private\function_manager.py", line 696, in actor_method_executor
    return method(__ray_actor, *args, **kwargs)
  File "C:\Users\clara\anaconda3\envs\tf_gpu\lib\site-packages\ray\util\tracing\tracing_helper.py", line 467, in _resume_span
    return method(self, *_args, **_kwargs)
  File "C:\Users\clara\anaconda3\envs\tf_gpu\lib\site-packages\flwr\simulation\ray_transport\ray_actor.py", line 63, in run
    raise ClientAppException(str(ex)) from ex
flwr.client.client_app.ClientAppException: 
Exception ClientAppException occurred. Message: You called `set_weights(weights)` on layer 'sequential_1' with a weight list of length 0, but the layer was expecting 8 weights.

[2024-12-03 23:20:18,644][flwr][ERROR] - [36mray::ClientAppActor.run()[39m (pid=1976, ip=127.0.0.1, actor_id=6b7804ce62ccde3aea0880a701000000, repr=<flwr.simulation.ray_transport.ray_actor.ClientAppActor object at 0x0000020CD7FC1A30>)
  File "C:\Users\clara\anaconda3\envs\tf_gpu\lib\site-packages\flwr\client\client_app.py", line 143, in __call__
    return self._call(message, context)
  File "C:\Users\clara\anaconda3\envs\tf_gpu\lib\site-packages\flwr\client\client_app.py", line 126, in ffn
    out_message = handle_legacy_message_from_msgtype(
  File "C:\Users\clara\anaconda3\envs\tf_gpu\lib\site-packages\flwr\client\message_handler\message_handler.py", line 129, in handle_legacy_message_from_msgtype
    fit_res = maybe_call_fit(
  File "C:\Users\clara\anaconda3\envs\tf_gpu\lib\site-packages\flwr\client\client.py", line 255, in maybe_call_fit
    return client.fit(fit_ins)
  File "C:\Users\clara\anaconda3\envs\tf_gpu\lib\site-packages\flwr\client\numpy_client.py", line 259, in _fit
    results = self.numpy_client.fit(parameters, ins.config)  # type: ignore
  File "C:\Users\clara\Desktop\TFG\Codigo TFG\3.FederatedTraining\client.py", line 27, in fit
    self.model.set_weights(parameters)
  File "C:\Users\clara\anaconda3\envs\tf_gpu\lib\site-packages\keras\src\layers\layer.py", line 696, in set_weights
    raise ValueError(
ValueError: You called `set_weights(weights)` on layer 'sequential_1' with a weight list of length 0, but the layer was expecting 8 weights.

The above exception was the direct cause of the following exception:

[36mray::ClientAppActor.run()[39m (pid=1976, ip=127.0.0.1, actor_id=6b7804ce62ccde3aea0880a701000000, repr=<flwr.simulation.ray_transport.ray_actor.ClientAppActor object at 0x0000020CD7FC1A30>)
  File "python\ray\_raylet.pyx", line 1856, in ray._raylet.execute_task
  File "python\ray\_raylet.pyx", line 1957, in ray._raylet.execute_task
  File "python\ray\_raylet.pyx", line 1862, in ray._raylet.execute_task
  File "python\ray\_raylet.pyx", line 1803, in ray._raylet.execute_task.function_executor
  File "C:\Users\clara\anaconda3\envs\tf_gpu\lib\site-packages\ray\_private\function_manager.py", line 696, in actor_method_executor
    return method(__ray_actor, *args, **kwargs)
  File "C:\Users\clara\anaconda3\envs\tf_gpu\lib\site-packages\ray\util\tracing\tracing_helper.py", line 467, in _resume_span
    return method(self, *_args, **_kwargs)
  File "C:\Users\clara\anaconda3\envs\tf_gpu\lib\site-packages\flwr\simulation\ray_transport\ray_actor.py", line 63, in run
    raise ClientAppException(str(ex)) from ex
flwr.client.client_app.ClientAppException: 
Exception ClientAppException occurred. Message: You called `set_weights(weights)` on layer 'sequential_1' with a weight list of length 0, but the layer was expecting 8 weights.
[2024-12-03 23:20:18,655][flwr][INFO] - aggregate_fit: received 0 results and 1 failures
